Workbook

Sheet GDK
A1: =HEX2DEC(MID(C1,3,99)) -> 32 | B1: GDK_KEY_space | C1: 0x020 | D1: =HEX2DEC(MID(C1,3,99)) -> 32 | E1: 65288 | F1: =DEC2HEX(E1) -> FF08
A2: =HEX2DEC(MID(C2,3,99)) -> 33 | B2: GDK_KEY_exclam | C2: 0x021 | D2: =HEX2DEC(MID(C2,3,99)) -> 33 | E2: 39 | F2: =DEC2HEX(E2) -> 27
A3: =HEX2DEC(MID(C3,3,99)) -> 34 | B3: GDK_KEY_quotedbl | C3: 0x022 | D3: =HEX2DEC(MID(C3,3,99)) -> 34 | E3: 65361 | F3: =DEC2HEX(E3) -> FF51
A4: =HEX2DEC(MID(C4,3,99)) -> 35 | B4: GDK_KEY_numbersign | C4: 0x023 | D4: =HEX2DEC(MID(C4,3,99)) -> 35 | E4: 65505 | F4: =DEC2HEX(E4) -> FFE1 | G4: =MATCH(E4,D:D,0) -> 1358 | H4: {=INDEX(B:B,G4)} -> GDK_KEY_Shift_L
A5: =HEX2DEC(MID(C5,3,99)) -> 36 | B5: GDK_KEY_dollar | C5: 0x024 | D5: =HEX2DEC(MID(C5,3,99)) -> 36 | E5: 65506 | F5: =DEC2HEX(E5) -> FFE2 | G5: =MATCH(E5,D:D,0) -> 1359 | H5: {=INDEX(B:B,G5)} -> GDK_KEY_Shift_R
A6: =HEX2DEC(MID(C6,3,99)) -> 37 | B6: GDK_KEY_percent | C6: 0x025 | D6: =HEX2DEC(MID(C6,3,99)) -> 37 | E6: 65507 | F6: =DEC2HEX(E6) -> FFE3 | G6: =MATCH(E6,D:D,0) -> 1360 | H6: {=INDEX(B:B,G6)} -> GDK_KEY_Control_L
A7: =HEX2DEC(MID(C7,3,99)) -> 38 | B7: GDK_KEY_ampersand | C7: 0x026 | D7: =HEX2DEC(MID(C7,3,99)) -> 38 | E7: 65514 | F7: =DEC2HEX(E7) -> FFEA | G7: =MATCH(E7,D:D,0) -> 1367 | H7: {=INDEX(B:B,G7)} -> GDK_KEY_Alt_R
A8: =HEX2DEC(MID(C8,3,99)) -> 39 | B8: GDK_KEY_apostrophe | C8: 0x027 | D8: =HEX2DEC(MID(C8,3,99)) -> 39 | E8: 92 | F8: =DEC2HEX(E8) -> 5C | G8: =MATCH(E8,D:D,0) -> 62 | H8: {=INDEX(B:B,G8)} -> GDK_KEY_backslash
A9: =HEX2DEC(MID(C9,3,99)) -> 39 | B9: GDK_KEY_quoteright | C9: 0x027 | D9: =HEX2DEC(MID(C9,3,99)) -> 39 | E9: 65364 | F9: =DEC2HEX(E9) -> FF54 | G9: =MATCH(E9,D:D,0) -> 1234 | H9: {=INDEX(B:B,G9)} -> GDK_KEY_Down
A10: =HEX2DEC(MID(C10,3,99)) -> 40 | B10: GDK_KEY_parenleft | C10: 0x028 | D10: =HEX2DEC(MID(C10,3,99)) -> 40 | E10: 65513 | F10: =DEC2HEX(E10) -> FFE9 | G10: =MATCH(E10,D:D,0) -> 1366 | H10: {=INDEX(B:B,G10)} -> GDK_KEY_Alt_L
A11: =HEX2DEC(MID(C11,3,99)) -> 41 | B11: GDK_KEY_parenright | C11: 0x029 | D11: =HEX2DEC(MID(C11,3,99)) -> 41
A12: =HEX2DEC(MID(C12,3,99)) -> 42 | B12: GDK_KEY_asterisk | C12: 0x02a | D12: =HEX2DEC(MID(C12,3,99)) -> 42
A13: =HEX2DEC(MID(C13,3,99)) -> 43 | B13: GDK_KEY_plus | C13: 0x02b | D13: =HEX2DEC(MID(C13,3,99)) -> 43
A14: =HEX2DEC(MID(C14,3,99)) -> 44 | B14: GDK_KEY_comma | C14: 0x02c | D14: =HEX2DEC(MID(C14,3,99)) -> 44
A15: =HEX2DEC(MID(C15,3,99)) -> 45 | B15: GDK_KEY_minus | C15: 0x02d | D15: =HEX2DEC(MID(C15,3,99)) -> 45
A16: =HEX2DEC(MID(C16,3,99)) -> 46 | B16: GDK_KEY_period | C16: 0x02e | D16: =HEX2DEC(MID(C16,3,99)) -> 46
A17: =HEX2DEC(MID(C17,3,99)) -> 47 | B17: GDK_KEY_slash | C17: 0x02f | D17: =HEX2DEC(MID(C17,3,99)) -> 47
A18: =HEX2DEC(MID(C18,3,99)) -> 48 | B18: GDK_KEY_0 | C18: 0x030 | D18: =HEX2DEC(MID(C18,3,99)) -> 48
A19: =HEX2DEC(MID(C19,3,99)) -> 49 | B19: GDK_KEY_1 | C19: 0x031 | D19: =HEX2DEC(MID(C19,3,99)) -> 49
A20: =HEX2DEC(MID(C20,3,99)) -> 50 | B20: GDK_KEY_2 | C20: 0x032 | D20: =HEX2DEC(MID(C20,3,99)) -> 50
A21: =HEX2DEC(MID(C21,3,99)) -> 51 | B21: GDK_KEY_3 | C21: 0x033 | D21: =HEX2DEC(MID(C21,3,99)) -> 51
A22: =HEX2DEC(MID(C22,3,99)) -> 52 | B22: GDK_KEY_4 | C22: 0x034 | D22: =HEX2DEC(MID(C22,3,99)) -> 52
... A2278: =HEX2DEC(MID(C2278,3,99)) -> 269025206 | B2278: GDK_KEY_AudioPreset | C2278: 0x1008ffb6 | D2278: =HEX2DEC(MID(C2278,3,99)) -> 269025206

Sheet 2024-08-30
A1: 97 | B1: =VLOOKUP(A1,GDK!A:B,2,0) -> GDK_KEY_a | D1: =B1&REPT(" ",20-LEN(B1))&"/* "&IF(A1<256,_xlfn.UNICHAR(A1)," ")&" "&A1&REPT(" ",5-LEN(A1))&" */" -> GDK_KEY_a /* a 97 */
A2: 118 | B2: =VLOOKUP(A2,GDK!A:B,2,0) -> GDK_KEY_v | D2: =B2&REPT(" ",20-LEN(B2))&"/* "&IF(A2<256,_xlfn.UNICHAR(A2)," ")&" "&A2&REPT(" ",5-LEN(A2))&" */" -> GDK_KEY_v /* v 118 */
A3: 113 | B3: =VLOOKUP(A3,GDK!A:B,2,0) -> GDK_KEY_q | D3: =B3&REPT(" ",20-LEN(B3))&"/* "&IF(A3<256,_xlfn.UNICHAR(A3)," ")&" "&A3&REPT(" ",5-LEN(A3))&" */" -> GDK_KEY_q /* q 113 */
A4: 111 | B4: =VLOOKUP(A4,GDK!A:B,2,0) -> GDK_KEY_o | D4: =B4&REPT(" ",20-LEN(B4))&"/* "&IF(A4<256,_xlfn.UNICHAR(A4)," ")&" "&A4&REPT(" ",5-LEN(A4))&" */" -> GDK_KEY_o /* o 111 */
A5: 108 | B5: =VLOOKUP(A5,GDK!A:B,2,0) -> GDK_KEY_l | D5: =B5&REPT(" ",20-LEN(B5))&"/* "&IF(A5<256,_xlfn.UNICHAR(A5)," ")&" "&A5&REPT(" ",5-LEN(A5))&" */" -> GDK_KEY_l /* l 108 */
A6: 120 | B6: =VLOOKUP(A6,GDK!A:B,2,0) -> GDK_KEY_x | D6: =B6&REPT(" ",20-LEN(B6))&"/* "&IF(A6<256,_xlfn.UNICHAR(A6)," ")&" "&A6&REPT(" ",5-LEN(A6))&" */" -> GDK_KEY_x /* x 120 */
A7: 109 | B7: =VLOOKUP(A7,GDK!A:B,2,0) -> GDK_KEY_m | D7: =B7&REPT(" ",20-LEN(B7))&"/* "&IF(A7<256,_xlfn.UNICHAR(A7)," ")&" "&A7&REPT(" ",5-LEN(A7))&" */" -> GDK_KEY_m /* m 109 */
A8: 114 | B8: =VLOOKUP(A8,GDK!A:B,2,0) -> GDK_KEY_r | D8: =B8&REPT(" ",20-LEN(B8))&"/* "&IF(A8<256,_xlfn.UNICHAR(A8)," ")&" "&A8&REPT(" ",5-LEN(A8))&" */" -> GDK_KEY_r /* r 114 */
A9: 100 | B9: =VLOOKUP(A9,GDK!A:B,2,0) -> GDK_KEY_d | D9: =B9&REPT(" ",20-LEN(B9))&"/* "&IF(A9<256,_xlfn.UNICHAR(A9)," ")&" "&A9&REPT(" ",5-LEN(A9))&" */" -> GDK_KEY_d /* d 100 */
A10: 115 | B10: =VLOOKUP(A10,GDK!A:B,2,0) -> GDK_KEY_s | D10: =B10&REPT(" ",20-LEN(B10))&"/* "&IF(A10<256,_xlfn.UNICHAR(A10)," ")&" "&A10&REPT(" ",5-LEN(A10))&" */" -> GDK_KEY_s /* s 115 */
A11: 99 | B11: =VLOOKUP(A11,GDK!A:B,2,0) -> GDK_KEY_c | D11: =B11&REPT(" ",20-LEN(B11))&"/* "&IF(A11<256,_xlfn.UNICHAR(A11)," ")&" "&A11&REPT(" ",5-LEN(A11))&" */" -> GDK_KEY_c /* c 99 */
A12: 116 | B12: =VLOOKUP(A12,GDK!A:B,2,0) -> GDK_KEY_t | D12: =B12&REPT(" ",20-LEN(B12))&"/* "&IF(A12<256,_xlfn.UNICHAR(A12)," ")&" "&A12&REPT(" ",5-LEN(A12))&" */" -> GDK_KEY_t /* t 116 */
... A108: 36 | B108: =VLOOKUP(A108,GDK!A:B,2,0) -> GDK_KEY_dollar | D108: =B108&REPT(" ",20-LEN(B108))&"/* "&IF(A108<256,_xlfn.UNICHAR(A108)," ")&" "&A108&REPT(" ",5-LEN(A108))&" */" -> GDK_KEY_dollar /* $ 36 */

Sheet 2024-09-01
A1: { .item | B1: ITM_0 | E1: GDK_KEY_0 | F1: =VLOOKUP(E1,GDK!B:D,3,0) -> 48
A2: { .item | B2: ITM_0 | E2: GDK_KEY_KP_0 | F2: =VLOOKUP(E2,GDK!B:D,3,0) -> 65456
A3: { .item | B3: ITM_1 | E3: GDK_KEY_1 | F3: =VLOOKUP(E3,GDK!B:D,3,0) -> 49
A4: { .item | B4: ITM_1 | E4: GDK_KEY_KP_1 | F4: =VLOOKUP(E4,GDK!B:D,3,0) -> 65457
A5: { .item | B5: ITM_2 | E5: GDK_KEY_2 | F5: =VLOOKUP(E5,GDK!B:D,3,0) -> 50
A6: { .item | B6: ITM_2 | E6: GDK_KEY_KP_2 | F6: =VLOOKUP(E6,GDK!B:D,3,0) -> 65458
A7: { .item | B7: ITM_3 | E7: GDK_KEY_3 | F7: =VLOOKUP(E7,GDK!B:D,3,0) -> 51
A8: { .item | B8: ITM_3 | E8: GDK_KEY_KP_3 | F8: =VLOOKUP(E8,GDK!B:D,3,0) -> 65459
A9: { .item | B9: ITM_4 | E9: GDK_KEY_4 | F9: =VLOOKUP(E9,GDK!B:D,3,0) -> 52
A10: { .item | B10: ITM_4 | E10: GDK_KEY_KP_4 | F10: =VLOOKUP(E10,GDK!B:D,3,0) -> 65460
A11: { .item | B11: ITM_5 | E11: GDK_KEY_5 | F11: =VLOOKUP(E11,GDK!B:D,3,0) -> 53
A12: { .item | B12: ITM_5 | E12: GDK_KEY_KP_5 | F12: =VLOOKUP(E12,GDK!B:D,3,0) -> 65461
... A21: { .item | B21: ITM_A | E21: GDK_KEY_A | F21: =VLOOKUP(E21,GDK!B:D,3,0) -> 65
A22: { .item | B22: ITM_B | E22: GDK_KEY_B | F22: =VLOOKUP(E22,GDK!B:D,3,0) -> 66 | G22: =F22-F21 -> 1
A23: { .item | B23: ITM_C | E23: GDK_KEY_C | F23: =VLOOKUP(E23,GDK!B:D,3,0) -> 67 | G23: =F23-F22 -> 1
A24: { .item | B24: ITM_D | E24: GDK_KEY_D | F24: =VLOOKUP(E24,GDK!B:D,3,0) -> 68 | G24: =F24-F23 -> 1
A25: { .item | B25: ITM_E | E25: GDK_KEY_E | F25: =VLOOKUP(E25,GDK!B:D,3,0) -> 69 | G25: =F25-F24 -> 1
A26: { .item | B26: ITM_F | E26: GDK_KEY_F | F26: =VLOOKUP(E26,GDK!B:D,3,0) -> 70 | G26: =F26-F25 -> 1
A27: { .item | B27: ITM_G | E27: GDK_KEY_G | F27: =VLOOKUP(E27,GDK!B:D,3,0) -> 71 | G27: =F27-F26 -> 1
A28: { .item | B28: ITM_H | E28: GDK_KEY_H | F28: =VLOOKUP(E28,GDK!B:D,3,0) -> 72 | G28: =F28-F27 -> 1
A29: { .item | B29: ITM_I | E29: GDK_KEY_I | F29: =VLOOKUP(E29,GDK!B:D,3,0) -> 73 | G29: =F29-F28 -> 1
A30: { .item | B30: ITM_J | E30: GDK_KEY_J | F30: =VLOOKUP(E30,GDK!B:D,3,0) -> 74 | G30: =F30-F29 -> 1
A31: { .item | B31: ITM_K | E31: GDK_KEY_K | F31: =VLOOKUP(E31,GDK!B:D,3,0) -> 75 | G31: =F31-F30 -> 1
A32: { .item | B32: ITM_L | E32: GDK_KEY_L | F32: =VLOOKUP(E32,GDK!B:D,3,0) -> 76 | G32: =F32-F31 -> 1
A33: { .item | B33: ITM_M | E33: GDK_KEY_M | F33: =VLOOKUP(E33,GDK!B:D,3,0) -> 77 | G33: =F33-F32 -> 1
... A157: { .item | B157: ITM_E_ACUTE | E157: GDK_KEY_Eacute | F157: =VLOOKUP(E157,GDK!B:D,3,0) -> 201 | G157: =F157-F156 -> -737
A158: // #define ITM_E_BREVE 681 | F158: =VLOOKUP(E158,GDK!B:D,3,0) -> #N/A | G158: =F158-F157 -> #N/A
A159: { .item | B159: ITM_E_GRAVE | E159: GDK_KEY_Egrave | F159: =VLOOKUP(E159,GDK!B:D,3,0) -> 200 | G159: =F159-F158 -> #N/A
A160: { .item | B160: ITM_E_DIARESIS | E160: GDK_KEY_Ediaeresis | F160: =VLOOKUP(E160,GDK!B:D,3,0) -> 203 | G160: =F160-F159 -> 3
A161: { .item | B161: ITM_E_CIRC | E161: GDK_KEY_Ecircumflex | F161: =VLOOKUP(E161,GDK!B:D,3,0) -> 202 | G161: =F161-F160 -> -1
A162: { .item | B162: ITM_E_OGONEK | E162: GDK_KEY_Eogonek | F162: =VLOOKUP(E162,GDK!B:D,3,0) -> 458 | G162: =F162-F161 -> 256
A163: { .item | B163: ITM_G_BREVE | E163: GDK_KEY_Gbreve | F163: =VLOOKUP(E163,GDK!B:D,3,0) -> 683 | G163: =F163-F162 -> 225
A164: { .item | B164: ITM_I_MACRON | E164: GDK_KEY_Imacron | F164: =VLOOKUP(E164,GDK!B:D,3,0) -> 975 | G164: =F164-F163 -> 292
A165: { .item | B165: ITM_I_ACUTE | E165: GDK_KEY_Iacute | F165: =VLOOKUP(E165,GDK!B:D,3,0) -> 205 | G165: =F165-F164 -> -770
A166: { .item | B166: ITM_I_BREVE | E166: GDK_KEY_Ibreve | F166: =VLOOKUP(E166,GDK!B:D,3,0) -> 16777516 | G166: =F166-F165 -> 16777311
A167: { .item | B167: ITM_I_GRAVE | E167: GDK_KEY_Igrave | F167: =VLOOKUP(E167,GDK!B:D,3,0) -> 204 | G167: =F167-F166 -> -16777312
A168: { .item | B168: ITM_I_DIARESIS | E168: GDK_KEY_Idiaeresis | F168: =VLOOKUP(E168,GDK!B:D,3,0) -> 207 | G168: =F168-F167 -> 3
A169: { .item | B169: ITM_I_CIRC | E169: GDK_KEY_Icircumflex | F169: =VLOOKUP(E169,GDK!B:D,3,0) -> 206 | G169: =F169-F168 -> -1
A170: { .item | B170: ITM_I_OGONEK | E170: GDK_KEY_Iogonek | F170: =VLOOKUP(E170,GDK!B:D,3,0) -> 967 | G170: =F170-F169 -> 761
A171: // #define ITM_I_DOT 694 | F171: =VLOOKUP(E171,GDK!B:D,3,0) -> #N/A | G171: =F171-F170 -> #N/A
...
