Workbook
Name items: Lookups!$C:$C
Name keylabelaim: Lookups!$E:$F
Name label: MAIN!$AA:$AK
Name labelitem: Lookups!$B:$C
Name layout: MAIN!$A$1

Sheet MAIN
A1: C47 | X1: Layout | Y1: Row | Z1: Column | AA1: Index | AB1: Primary | AC1: F-shift | AD1: G-shift | AF1: Alpha | AH1: f-Alpha | AI1: g-Alpha | AJ1: TAM | AM1: primary | AN1: fShifted | AO1: gShifted | AP1: keyLblAim | AQ1: primaryAim | AR1: fShiftedAim | AS1: gShiftedAim | AT1: primaryTam | AX1: primary | AY1: fShifted | AZ1: gShifted | BA1: keyLblAim | BB1: primaryAim | BC1: fShiftedAim | BD1: gShiftedAim | BE1: primaryTam
V2: IN CODE | W2: DROPLIST | AA2: 1 | AB2: 2 | AC2: 3 | AD2: 4 | AF2: 5
C3: =VLOOKUP(LEFT(C53,LEN(layout)+3),label,RIGHT(C53,1)+1,0) -> F1 | G3: =VLOOKUP(LEFT(G53,LEN(layout)+3),label,RIGHT(G53,1)+1,0) -> F2 | J3: =VLOOKUP(LEFT(J53,LEN(layout)+3),label,RIGHT(J53,1)+1,0) -> F3 | M3: =VLOOKUP(LEFT(M53,LEN(layout)+3),label,RIGHT(M53,1)+1,0) -> F4 | P3: =VLOOKUP(LEFT(P53,LEN(layout)+3),label,RIGHT(P53,1)+1,0) -> F4 | S3: =VLOOKUP(LEFT(S53,LEN(layout)+3),label,RIGHT(S53,1)+1,0) -> F6 | W3: =X48 -> C47
V4: From WP code | W4: =X93 -> WP43
W5: =X138 -> E47
W6: =X183 -> V47
V7: kbd_std_N43 | W7: =X228 -> N47
C8: =VLOOKUP(LEFT(C58,LEN(layout)+3),label,RIGHT(C58,1)+1,0) -> ->I | D8: =VLOOKUP(LEFT(D58,LEN(layout)+3),label,RIGHT(D58,1)+1,0) -> a b/c | G8: =VLOOKUP(LEFT(G58,LEN(layout)+3),label,RIGHT(G58,1)+1,0) -> y^x | H8: =VLOOKUP(LEFT(H58,LEN(layout)+3),label,RIGHT(H58,1)+1,0) -> # | J8: =VLOOKUP(LEFT(J58,LEN(layout)+3),label,RIGHT(J58,1)+1,0) -> x^2 | K8: =VLOOKUP(LEFT(K58,LEN(layout)+3),label,RIGHT(K58,1)+1,0) -> .ms | M8: =VLOOKUP(LEFT(M58,LEN(layout)+3),label,RIGHT(M58,1)+1,0) -> 10^x | N8: =VLOOKUP(LEFT(N58,LEN(layout)+3),label,RIGHT(N58,1)+1,0) -> .d | P8: =VLOOKUP(LEFT(P58,LEN(layout)+3),label,RIGHT(P58,1)+1,0) -> e^x | Q8: =VLOOKUP(LEFT(Q58,LEN(layout)+3),label,RIGHT(Q58,1)+1,0) -> LBL | S8: =VLOOKUP(LEFT(S58,LEN(layout)+3),label,RIGHT(S58,1)+1,0) -> [ alpha ] | T8: =VLOOKUP(LEFT(T58,LEN(layout)+3),label,RIGHT(T58,1)+1,0) -> GTO | V8: kbd_std_D47 | W8: =X273 -> D47
C9: =VLOOKUP(LEFT(C59,LEN(layout)+3),label,RIGHT(C59,1)+1,0) -> Sigma+ | E9: =SUBSTITUTE(VLOOKUP(LEFT(E59,LEN(layout)+3),label,RIGHT(E59,1)+2,0),0,"") -> A | G9: =VLOOKUP(LEFT(G59,LEN(layout)+3),label,RIGHT(G59,1)+1,0) -> 1/x | I9: =SUBSTITUTE(VLOOKUP(LEFT(I59,LEN(layout)+3),label,RIGHT(I59,1)+2,0),0,"") -> B | J9: =VLOOKUP(LEFT(J59,LEN(layout)+3),label,RIGHT(J59,1)+1,0) -> √x | L9: =SUBSTITUTE(VLOOKUP(LEFT(L59,LEN(layout)+3),label,RIGHT(L59,1)+2,0),0,"") -> C | M9: =VLOOKUP(LEFT(M59,LEN(layout)+3),label,RIGHT(M59,1)+1,0) -> LOG | O9: =SUBSTITUTE(VLOOKUP(LEFT(O59,LEN(layout)+3),label,RIGHT(O59,1)+2,0),0,"") -> D | P9: =VLOOKUP(LEFT(P59,LEN(layout)+3),label,RIGHT(P59,1)+1,0) -> LN | R9: =SUBSTITUTE(VLOOKUP(LEFT(R59,LEN(layout)+3),label,RIGHT(R59,1)+2,0),0,"") -> E | S9: =VLOOKUP(LEFT(S59,LEN(layout)+3),label,RIGHT(S59,1)+1,0) -> XEQ | U9: =SUBSTITUTE(VLOOKUP(LEFT(U59,LEN(layout)+3),label,RIGHT(U59,1)+2,0),0,"") -> F | W9: DM42
W10: S47
W11: R47
C12: =VLOOKUP(LEFT(C58,LEN(layout)+3),label,RIGHT(C58,1)+6,0) -> a | D12: =VLOOKUP(LEFT(D58,LEN(layout)+3),label,RIGHT(D58,1)+6,0) -> Sigma | E12: =VLOOKUP(LEFT(E59,LEN(layout)+3),label,RIGHT(E59,1)+6,0) -> Reg A | G12: =VLOOKUP(LEFT(G58,LEN(layout)+3),label,RIGHT(G58,1)+6,0) -> b | H12: =VLOOKUP(LEFT(H58,LEN(layout)+3),label,RIGHT(H58,1)+6,0) -> ^ | I12: =VLOOKUP(LEFT(I59,LEN(layout)+3),label,RIGHT(I59,1)+6,0) -> Reg B | J12: =VLOOKUP(LEFT(J58,LEN(layout)+3),label,RIGHT(J58,1)+6,0) -> c | K12: =VLOOKUP(LEFT(K58,LEN(layout)+3),label,RIGHT(K58,1)+6,0) -> √ | L12: =VLOOKUP(LEFT(L59,LEN(layout)+3),label,RIGHT(L59,1)+6,0) -> Reg C | M12: =VLOOKUP(LEFT(M58,LEN(layout)+3),label,RIGHT(M58,1)+6,0) -> d | N12: =VLOOKUP(LEFT(N58,LEN(layout)+3),label,RIGHT(N58,1)+6,0) -> LOG | O12: =VLOOKUP(LEFT(O59,LEN(layout)+3),label,RIGHT(O59,1)+6,0) -> Reg D | P12: =VLOOKUP(LEFT(P58,LEN(layout)+3),label,RIGHT(P58,1)+6,0) -> e | Q12: =VLOOKUP(LEFT(Q58,LEN(layout)+3),label,RIGHT(Q58,1)+6,0) -> LN | R12: =VLOOKUP(LEFT(R59,LEN(layout)+3),label,RIGHT(R59,1)+6,0) -> Reg E | S12: =VLOOKUP(LEFT(S58,LEN(layout)+3),label,RIGHT(S58,1)+6,0) -> f | T12: =VLOOKUP(LEFT(T58,LEN(layout)+3),label,RIGHT(T58,1)+6,0) -> alpha | U12: =VLOOKUP(LEFT(U59,LEN(layout)+3),label,RIGHT(U59,1)+6,0) -> [TAMALPHA] | W12: R47bkfg
W13: R47fgbk
C14: =VLOOKUP(LEFT(C64,LEN(layout)+3),label,RIGHT(C64,1)+1,0) -> |x| | D14: =VLOOKUP(LEFT(D64,LEN(layout)+3),label,RIGHT(D64,1)+1,0) -> angle | G14: =VLOOKUP(LEFT(G64,LEN(layout)+3),label,RIGHT(G64,1)+1,0) -> % | H14: =VLOOKUP(LEFT(H64,LEN(layout)+3),label,RIGHT(H64,1)+1,0) -> Delta % | J14: =VLOOKUP(LEFT(J64,LEN(layout)+3),label,RIGHT(J64,1)+1,0) -> pi | K14: =VLOOKUP(LEFT(K64,LEN(layout)+3),label,RIGHT(K64,1)+1,0) -> x√y | M14: =VLOOKUP(LEFT(M64,LEN(layout)+3),label,RIGHT(M64,1)+1,0) -> ASIN | N14: =VLOOKUP(LEFT(N64,LEN(layout)+3),label,RIGHT(N64,1)+1,0) -> op_i | P14: =VLOOKUP(LEFT(P64,LEN(layout)+3),label,RIGHT(P64,1)+1,0) -> ACOS | Q14: =VLOOKUP(LEFT(Q64,LEN(layout)+3),label,RIGHT(Q64,1)+1,0) -> ->R | S14: =VLOOKUP(LEFT(S64,LEN(layout)+3),label,RIGHT(S64,1)+1,0) -> ATAN | T14: =VLOOKUP(LEFT(T64,LEN(layout)+3),label,RIGHT(T64,1)+1,0) -> ->P | W14: R47fg_g
C15: =VLOOKUP(LEFT(C65,LEN(layout)+3),label,RIGHT(C65,1)+1,0) -> STO | E15: =SUBSTITUTE(VLOOKUP(LEFT(E65,LEN(layout)+3),label,RIGHT(E65,1)+2,0),0,"") -> G | G15: =VLOOKUP(LEFT(G65,LEN(layout)+3),label,RIGHT(G65,1)+1,0) -> RCL | I15: =SUBSTITUTE(VLOOKUP(LEFT(I65,LEN(layout)+3),label,RIGHT(I65,1)+2,0),0,"") -> H | J15: =VLOOKUP(LEFT(J65,LEN(layout)+3),label,RIGHT(J65,1)+1,0) -> RDN | L15: =SUBSTITUTE(VLOOKUP(LEFT(L65,LEN(layout)+3),label,RIGHT(L65,1)+2,0),0,"") -> I | M15: =VLOOKUP(LEFT(M65,LEN(layout)+3),label,RIGHT(M65,1)+1,0) -> SIN | O15: =SUBSTITUTE(VLOOKUP(LEFT(O65,LEN(layout)+3),label,RIGHT(O65,1)+2,0),0,"") -> J | P15: =VLOOKUP(LEFT(P65,LEN(layout)+3),label,RIGHT(P65,1)+1,0) -> COS | R15: =SUBSTITUTE(VLOOKUP(LEFT(R65,LEN(layout)+3),label,RIGHT(R65,1)+2,0),0,"") -> K | S15: =VLOOKUP(LEFT(S65,LEN(layout)+3),label,RIGHT(S65,1)+1,0) -> TAN | U15: =SUBSTITUTE(VLOOKUP(LEFT(U65,LEN(layout)+3),label,RIGHT(U65,1)+2,0),0,"") -> L
C18: =VLOOKUP(LEFT(C64,LEN(layout)+3),label,RIGHT(C64,1)+6,0) -> g | D18: =VLOOKUP(LEFT(D64,LEN(layout)+3),label,RIGHT(D64,1)+6,0) -> | | E18: =VLOOKUP(LEFT(E65,LEN(layout)+3),label,RIGHT(E65,1)+6,0) -> Reg G | G18: =VLOOKUP(LEFT(G64,LEN(layout)+3),label,RIGHT(G64,1)+6,0) -> h | H18: =VLOOKUP(LEFT(H64,LEN(layout)+3),label,RIGHT(H64,1)+6,0) -> Delta | I18: =VLOOKUP(LEFT(I65,LEN(layout)+3),label,RIGHT(I65,1)+6,0) -> Reg H | J18: =VLOOKUP(LEFT(J64,LEN(layout)+3),label,RIGHT(J64,1)+6,0) -> i | K18: =VLOOKUP(LEFT(K64,LEN(layout)+3),label,RIGHT(K64,1)+6,0) -> pi | L18: =VLOOKUP(LEFT(L65,LEN(layout)+3),label,RIGHT(L65,1)+6,0) -> Reg I | M18: =VLOOKUP(LEFT(M64,LEN(layout)+3),label,RIGHT(M64,1)+6,0) -> j | N18: =VLOOKUP(LEFT(N64,LEN(layout)+3),label,RIGHT(N64,1)+6,0) -> SIN | O18: =VLOOKUP(LEFT(O65,LEN(layout)+3),label,RIGHT(O65,1)+6,0) -> Reg J | P18: =VLOOKUP(LEFT(P64,LEN(layout)+3),label,RIGHT(P64,1)+6,0) -> k | Q18: =VLOOKUP(LEFT(Q64,LEN(layout)+3),label,RIGHT(Q64,1)+6,0) -> COS | R18: =VLOOKUP(LEFT(R65,LEN(layout)+3),label,RIGHT(R65,1)+6,0) -> Reg K | S18: =VLOOKUP(LEFT(S64,LEN(layout)+3),label,RIGHT(S64,1)+6,0) -> l | T18: =VLOOKUP(LEFT(T64,LEN(layout)+3),label,RIGHT(T64,1)+6,0) -> TAN | U18: =VLOOKUP(LEFT(U65,LEN(layout)+3),label,RIGHT(U65,1)+6,0) -> Reg L
C20: =VLOOKUP(LEFT(C70,LEN(layout)+3),label,RIGHT(C70,1)+1,0) -> COMPLEX | F20: =VLOOKUP(LEFT(F70,LEN(layout)+3),label,RIGHT(F70,1)+1,0) -> [ CPX ] | J20: =VLOOKUP(LEFT(J70,LEN(layout)+3),label,RIGHT(J70,1)+1,0) -> LASTx | K20: =VLOOKUP(LEFT(K70,LEN(layout)+3),label,RIGHT(K70,1)+1,0) -> [ STK ] | M20: =VLOOKUP(LEFT(M70,LEN(layout)+3),label,RIGHT(M70,1)+1,0) -> [ MODE ] | N20: =VLOOKUP(LEFT(N70,LEN(layout)+3),label,RIGHT(N70,1)+1,0) -> [ TRG ] | P20: =VLOOKUP(LEFT(P70,LEN(layout)+3),label,RIGHT(P70,1)+1,0) -> [ DISP ] | Q20: =VLOOKUP(LEFT(Q70,LEN(layout)+3),label,RIGHT(Q70,1)+1,0) -> [ EXP ] | S20: =VLOOKUP(LEFT(S70,LEN(layout)+3),label,RIGHT(S70,1)+1,0) -> Undo | T20: =VLOOKUP(LEFT(T70,LEN(layout)+3),label,RIGHT(T70,1)+1,0) -> [ CLR ] | AB20: C 4 3 | AC20: DELETED
C21: =VLOOKUP(LEFT(C71,LEN(layout)+3),label,RIGHT(C71,1)+1,0) -> ENTER | I21: =SUBSTITUTE(VLOOKUP(LEFT(I71,LEN(layout)+3),label,RIGHT(I71,1)+2,0),0,"") -> ENTER | J21: =VLOOKUP(LEFT(J71,LEN(layout)+3),label,RIGHT(J71,1)+1,0) -> x <> y | L21: =SUBSTITUTE(VLOOKUP(LEFT(L71,LEN(layout)+3),label,RIGHT(L71,1)+2,0),0,"") -> M | M21: =VLOOKUP(LEFT(M71,LEN(layout)+3),label,RIGHT(M71,1)+1,0) -> CHS | O21: =SUBSTITUTE(VLOOKUP(LEFT(O71,LEN(layout)+3),label,RIGHT(O71,1)+2,0),0,"") -> N | P21: =VLOOKUP(LEFT(P71,LEN(layout)+3),label,RIGHT(P71,1)+1,0) -> EEX | R21: =SUBSTITUTE(VLOOKUP(LEFT(R71,LEN(layout)+3),label,RIGHT(R71,1)+2,0),0,"") -> O | S21: =VLOOKUP(LEFT(S71,LEN(layout)+3),label,RIGHT(S71,1)+1,0) -> <= | U21: =SUBSTITUTE(VLOOKUP(LEFT(U71,LEN(layout)+3),label,RIGHT(U71,1)+2,0),0,"") -> <=
C24: =VLOOKUP(LEFT(C70,LEN(layout)+3),label,RIGHT(C70,1)+6,0) -> X.SWAP | F24: =VLOOKUP(LEFT(F70,LEN(layout)+3),label,RIGHT(F70,1)+6,0) -> a.PARSE | I24: =VLOOKUP(LEFT(I71,LEN(layout)+3),label,RIGHT(I71,1)+6,0) -> ENTER | J24: =VLOOKUP(LEFT(J70,LEN(layout)+3),label,RIGHT(J70,1)+6,0) -> m | K24: =VLOOKUP(LEFT(K70,LEN(layout)+3),label,RIGHT(K70,1)+6,0) -> <> | L24: =VLOOKUP(LEFT(L71,LEN(layout)+3),label,RIGHT(L71,1)+6,0) -> Reg M | M24: =VLOOKUP(LEFT(M70,LEN(layout)+3),label,RIGHT(M70,1)+6,0) -> n | N24: =VLOOKUP(LEFT(N70,LEN(layout)+3),label,RIGHT(N70,1)+6,0) -> +/- | O24: =VLOOKUP(LEFT(O71,LEN(layout)+3),label,RIGHT(O71,1)+6,0) -> Reg N | P24: =VLOOKUP(LEFT(P70,LEN(layout)+3),label,RIGHT(P70,1)+6,0) -> o | Q24: =VLOOKUP(LEFT(Q70,LEN(layout)+3),label,RIGHT(Q70,1)+6,0) -> <E> | R24: =VLOOKUP(LEFT(R71,LEN(layout)+3),label,RIGHT(R71,1)+6,0) -> Reg O | S24: =VLOOKUP(LEFT(S70,LEN(layout)+3),label,RIGHT(S70,1)+6,0) -> CLA | T24: =VLOOKUP(LEFT(T70,LEN(layout)+3),label,RIGHT(T70,1)+6,0) -> CLA | U24: =VLOOKUP(LEFT(U71,LEN(layout)+3),label,RIGHT(U71,1)+6,0) -> <=
C26: =VLOOKUP(LEFT(C76,LEN(layout)+3),label,RIGHT(C76,1)+1,0) -> Scroll Up | D26: =VLOOKUP(LEFT(D76,LEN(layout)+3),label,RIGHT(D76,1)+1,0) -> REGS | F26: =VLOOKUP(LEFT(F76,LEN(layout)+3),label,RIGHT(F76,1)+1,0) -> [ EQN ] | H26: =VLOOKUP(LEFT(H76,LEN(layout)+3),label,RIGHT(H76,1)+1,0) -> [ HOME ] | J26: =VLOOKUP(LEFT(J76,LEN(layout)+3),label,RIGHT(J76,1)+1,0) -> [ ADV ] | L26: =VLOOKUP(LEFT(L76,LEN(layout)+3),label,RIGHT(L76,1)+1,0) -> [ FIN ] | N26: =VLOOKUP(LEFT(N76,LEN(layout)+3),label,RIGHT(N76,1)+1,0) -> [ MATX ] | P26: =VLOOKUP(LEFT(P76,LEN(layout)+3),label,RIGHT(P76,1)+1,0) -> [ X.FN ] | R26: =VLOOKUP(LEFT(R76,LEN(layout)+3),label,RIGHT(R76,1)+1,0) -> [ STAT ] | T26: =VLOOKUP(LEFT(T76,LEN(layout)+3),label,RIGHT(T76,1)+1,0) -> [ PLOT ]
C27: =VLOOKUP(LEFT(C77,LEN(layout)+3),label,RIGHT(C77,1)+1,0) -> Up | E27: =SUBSTITUTE(VLOOKUP(LEFT(E77,LEN(layout)+3),label,RIGHT(E77,1)+2,0),0,"") -> <-HOME | F27: =VLOOKUP(LEFT(F77,LEN(layout)+3),label,RIGHT(F77,1)+1,0) -> 7 | I27: =SUBSTITUTE(VLOOKUP(LEFT(I77,LEN(layout)+3),label,RIGHT(I77,1)+2,0),0,"") -> P | J27: =VLOOKUP(LEFT(J77,LEN(layout)+3),label,RIGHT(J77,1)+1,0) -> 8 | M27: =SUBSTITUTE(VLOOKUP(LEFT(M77,LEN(layout)+3),label,RIGHT(M77,1)+2,0),0,"") -> Q | N27: =VLOOKUP(LEFT(N77,LEN(layout)+3),label,RIGHT(N77,1)+1,0) -> 9 | Q27: =SUBSTITUTE(VLOOKUP(LEFT(Q77,LEN(layout)+3),label,RIGHT(Q77,1)+2,0),0,"") -> R | R27: =VLOOKUP(LEFT(R77,LEN(layout)+3),label,RIGHT(R77,1)+1,0) -> ÷ | U27: =SUBSTITUTE(VLOOKUP(LEFT(U77,LEN(layout)+3),label,RIGHT(U77,1)+2,0),0,"") -> S
C30: =VLOOKUP(LEFT(C76,LEN(layout)+3),label,RIGHT(C76,1)+6,0) -> CASE UP | D30: =VLOOKUP(LEFT(D76,LEN(layout)+3),label,RIGHT(D76,1)+6,0) -> Super | E30: =VLOOKUP(LEFT(E77,LEN(layout)+3),label,RIGHT(E77,1)+6,0) -> Up | F30: =VLOOKUP(LEFT(F76,LEN(layout)+3),label,RIGHT(F76,1)+6,0) -> p | H30: =VLOOKUP(LEFT(H76,LEN(layout)+3),label,RIGHT(H76,1)+6,0) -> 7 | I30: =VLOOKUP(LEFT(I77,LEN(layout)+3),label,RIGHT(I77,1)+6,0) -> 7 | J30: =VLOOKUP(LEFT(J76,LEN(layout)+3),label,RIGHT(J76,1)+6,0) -> q | L30: =VLOOKUP(LEFT(L76,LEN(layout)+3),label,RIGHT(L76,1)+6,0) -> 8 | M30: =VLOOKUP(LEFT(M77,LEN(layout)+3),label,RIGHT(M77,1)+6,0) -> 8 | N30: =VLOOKUP(LEFT(N76,LEN(layout)+3),label,RIGHT(N76,1)+6,0) -> r | P30: =VLOOKUP(LEFT(P76,LEN(layout)+3),label,RIGHT(P76,1)+6,0) -> 9 | Q30: =VLOOKUP(LEFT(Q77,LEN(layout)+3),label,RIGHT(Q77,1)+6,0) -> 9 | R30: =VLOOKUP(LEFT(R76,LEN(layout)+3),label,RIGHT(R76,1)+6,0) -> s | T30: =VLOOKUP(LEFT(T76,LEN(layout)+3),label,RIGHT(T76,1)+6,0) -> ÷ | U30: =VLOOKUP(LEFT(U77,LEN(layout)+3),label,RIGHT(U77,1)+6,0) -> ÷
C32: =VLOOKUP(LEFT(C82,LEN(layout)+3),label,RIGHT(C82,1)+1,0) -> Scroll Dn | D32: =VLOOKUP(LEFT(D82,LEN(layout)+3),label,RIGHT(D82,1)+1,0) -> FLGS | F32: =VLOOKUP(LEFT(F82,LEN(layout)+3),label,RIGHT(F82,1)+1,0) -> [ BASE ] | H32: =VLOOKUP(LEFT(H82,LEN(layout)+3),label,RIGHT(H82,1)+1,0) -> [ BITS ] | J32: =VLOOKUP(LEFT(J82,LEN(layout)+3),label,RIGHT(J82,1)+1,0) -> [ CONV ] | L32: =VLOOKUP(LEFT(L82,LEN(layout)+3),label,RIGHT(L82,1)+1,0) -> [ CLK ] | N32: =VLOOKUP(LEFT(N82,LEN(layout)+3),label,RIGHT(N82,1)+1,0) -> [ FLAG ] | P32: =VLOOKUP(LEFT(P82,LEN(layout)+3),label,RIGHT(P82,1)+1,0) -> [ REAL ] | R32: =VLOOKUP(LEFT(R82,LEN(layout)+3),label,RIGHT(R82,1)+1,0) -> [ PROB ] | T32: =VLOOKUP(LEFT(T82,LEN(layout)+3),label,RIGHT(T82,1)+1,0) -> [ INTS ]
C33: =VLOOKUP(LEFT(C83,LEN(layout)+3),label,RIGHT(C83,1)+1,0) -> Dn | E33: =SUBSTITUTE(VLOOKUP(LEFT(E83,LEN(layout)+3),label,RIGHT(E83,1)+2,0),0,"") -> END-> | F33: =VLOOKUP(LEFT(F83,LEN(layout)+3),label,RIGHT(F83,1)+1,0) -> 4 | I33: =SUBSTITUTE(VLOOKUP(LEFT(I83,LEN(layout)+3),label,RIGHT(I83,1)+2,0),0,"") -> T | J33: =VLOOKUP(LEFT(J83,LEN(layout)+3),label,RIGHT(J83,1)+1,0) -> 5 | M33: =SUBSTITUTE(VLOOKUP(LEFT(M83,LEN(layout)+3),label,RIGHT(M83,1)+2,0),0,"") -> U | N33: =VLOOKUP(LEFT(N83,LEN(layout)+3),label,RIGHT(N83,1)+1,0) -> 6 | Q33: =SUBSTITUTE(VLOOKUP(LEFT(Q83,LEN(layout)+3),label,RIGHT(Q83,1)+2,0),0,"") -> V | R33: =VLOOKUP(LEFT(R83,LEN(layout)+3),label,RIGHT(R83,1)+1,0) -> ✕ | U33: =SUBSTITUTE(VLOOKUP(LEFT(U83,LEN(layout)+3),label,RIGHT(U83,1)+2,0),0,"") -> W
C36: =VLOOKUP(LEFT(C82,LEN(layout)+3),label,RIGHT(C82,1)+6,0) -> CASE DN | D36: =VLOOKUP(LEFT(D82,LEN(layout)+3),label,RIGHT(D82,1)+6,0) -> Sub | E36: =VLOOKUP(LEFT(E83,LEN(layout)+3),label,RIGHT(E83,1)+6,0) -> Dn | F36: =VLOOKUP(LEFT(F82,LEN(layout)+3),label,RIGHT(F82,1)+6,0) -> t | H36: =VLOOKUP(LEFT(H82,LEN(layout)+3),label,RIGHT(H82,1)+6,0) -> 4 | I36: =VLOOKUP(LEFT(I83,LEN(layout)+3),label,RIGHT(I83,1)+6,0) -> 4 | J36: =VLOOKUP(LEFT(J82,LEN(layout)+3),label,RIGHT(J82,1)+6,0) -> u | L36: =VLOOKUP(LEFT(L82,LEN(layout)+3),label,RIGHT(L82,1)+6,0) -> 5 | M36: =VLOOKUP(LEFT(M83,LEN(layout)+3),label,RIGHT(M83,1)+6,0) -> 5 | N36: =VLOOKUP(LEFT(N82,LEN(layout)+3),label,RIGHT(N82,1)+6,0) -> v | P36: =VLOOKUP(LEFT(P82,LEN(layout)+3),label,RIGHT(P82,1)+6,0) -> 6 | Q36: =VLOOKUP(LEFT(Q83,LEN(layout)+3),label,RIGHT(Q83,1)+6,0) -> 6 | R36: =VLOOKUP(LEFT(R82,LEN(layout)+3),label,RIGHT(R82,1)+6,0) -> w | T36: =VLOOKUP(LEFT(T82,LEN(layout)+3),label,RIGHT(T82,1)+6,0) -> ✕ | U36: =VLOOKUP(LEFT(U83,LEN(layout)+3),label,RIGHT(U83,1)+6,0) -> ✕
C38: =VLOOKUP(LEFT(C88,LEN(layout)+3),label,RIGHT(C88,1)+1,0) | D38: =VLOOKUP(LEFT(D88,LEN(layout)+3),label,RIGHT(D88,1)+1,0) | F38: =VLOOKUP(LEFT(F88,LEN(layout)+3),label,RIGHT(F88,1)+1,0) -> ASN | H38: =VLOOKUP(LEFT(H88,LEN(layout)+3),label,RIGHT(H88,1)+1,0) -> [ KEYS ] | J38: =VLOOKUP(LEFT(J88,LEN(layout)+3),label,RIGHT(J88,1)+1,0) -> USER | L38: =VLOOKUP(LEFT(L88,LEN(layout)+3),label,RIGHT(L88,1)+1,0) -> [ a.FN ] | N38: =VLOOKUP(LEFT(N88,LEN(layout)+3),label,RIGHT(N88,1)+1,0) -> [ P.FN ] | P38: =VLOOKUP(LEFT(P88,LEN(layout)+3),label,RIGHT(P88,1)+1,0) -> [ LOOP ] | R38: =VLOOKUP(LEFT(R88,LEN(layout)+3),label,RIGHT(R88,1)+1,0) -> [ PRINT ] | T38: =VLOOKUP(LEFT(T88,LEN(layout)+3),label,RIGHT(T88,1)+1,0) -> [ I/O ]
C39: =VLOOKUP(LEFT(C89,LEN(layout)+3),label,RIGHT(C89,1)+1,0) -> f/g | E39: =SUBSTITUTE(VLOOKUP(LEFT(E89,LEN(layout)+3),label,RIGHT(E89,1)+2,0),0,"") -> f/g | F39: =VLOOKUP(LEFT(F89,LEN(layout)+3),label,RIGHT(F89,1)+1,0) -> 1 | I39: =SUBSTITUTE(VLOOKUP(LEFT(I89,LEN(layout)+3),label,RIGHT(I89,1)+2,0),0,"") -> X | J39: =VLOOKUP(LEFT(J89,LEN(layout)+3),label,RIGHT(J89,1)+1,0) -> 2 | M39: =SUBSTITUTE(VLOOKUP(LEFT(M89,LEN(layout)+3),label,RIGHT(M89,1)+2,0),0,"") -> Y | N39: =VLOOKUP(LEFT(N89,LEN(layout)+3),label,RIGHT(N89,1)+1,0) -> 3 | Q39: =SUBSTITUTE(VLOOKUP(LEFT(Q89,LEN(layout)+3),label,RIGHT(Q89,1)+2,0),0,"") -> Z | R39: =VLOOKUP(LEFT(R89,LEN(layout)+3),label,RIGHT(R89,1)+1,0) -> - | U39: =SUBSTITUTE(VLOOKUP(LEFT(U89,LEN(layout)+3),label,RIGHT(U89,1)+2,0),0,"") -> _
C42: =VLOOKUP(LEFT(C88,LEN(layout)+3),label,RIGHT(C88,1)+6,0) -> (FlipChar) | D42: =VLOOKUP(LEFT(D88,LEN(layout)+3),label,RIGHT(D88,1)+6,0) -> (Digit) | E42: =VLOOKUP(LEFT(E89,LEN(layout)+3),label,RIGHT(E89,1)+6,0) -> f/g | F42: =VLOOKUP(LEFT(F88,LEN(layout)+3),label,RIGHT(F88,1)+6,0) -> x | H42: =VLOOKUP(LEFT(H88,LEN(layout)+3),label,RIGHT(H88,1)+6,0) -> 1 | I42: =VLOOKUP(LEFT(I89,LEN(layout)+3),label,RIGHT(I89,1)+6,0) -> 1 | J42: =VLOOKUP(LEFT(J88,LEN(layout)+3),label,RIGHT(J88,1)+6,0) -> y | L42: =VLOOKUP(LEFT(L88,LEN(layout)+3),label,RIGHT(L88,1)+6,0) -> 2 | M42: =VLOOKUP(LEFT(M89,LEN(layout)+3),label,RIGHT(M89,1)+6,0) -> 2 | N42: =VLOOKUP(LEFT(N88,LEN(layout)+3),label,RIGHT(N88,1)+6,0) -> z | P42: =VLOOKUP(LEFT(P88,LEN(layout)+3),label,RIGHT(P88,1)+6,0) -> 3 | Q42: =VLOOKUP(LEFT(Q89,LEN(layout)+3),label,RIGHT(Q89,1)+6,0) -> 3 | R42: =VLOOKUP(LEFT(R88,LEN(layout)+3),label,RIGHT(R88,1)+6,0) -> <e> | T42: =VLOOKUP(LEFT(T88,LEN(layout)+3),label,RIGHT(T88,1)+6,0) -> - | U42: =VLOOKUP(LEFT(U89,LEN(layout)+3),label,RIGHT(U89,1)+6,0) -> -
C44: =VLOOKUP(LEFT(C94,LEN(layout)+3),label,RIGHT(C94,1)+1,0) -> OFF | D44: =VLOOKUP(LEFT(D94,LEN(layout)+3),label,RIGHT(D94,1)+1,0) -> SNAP | F44: =VLOOKUP(LEFT(F94,LEN(layout)+3),label,RIGHT(F94,1)+1,0) -> VIEW | H44: =VLOOKUP(LEFT(H94,LEN(layout)+3),label,RIGHT(H94,1)+1,0) -> STOPW | J44: =VLOOKUP(LEFT(J94,LEN(layout)+3),label,RIGHT(J94,1)+1,0) -> SHOW | L44: =VLOOKUP(LEFT(L94,LEN(layout)+3),label,RIGHT(L94,1)+1,0) -> [ INFO ] | N44: =VLOOKUP(LEFT(N94,LEN(layout)+3),label,RIGHT(N94,1)+1,0) -> PRGM | P44: =VLOOKUP(LEFT(P94,LEN(layout)+3),label,RIGHT(P94,1)+1,0) -> [ TEST ] | R44: =VLOOKUP(LEFT(R94,LEN(layout)+3),label,RIGHT(R94,1)+1,0) -> [ CAT ] | T44: =VLOOKUP(LEFT(T94,LEN(layout)+3),label,RIGHT(T94,1)+1,0) -> [ CNST ]
C45: =VLOOKUP(LEFT(C95,LEN(layout)+3),label,RIGHT(C95,1)+1,0) -> EXIT | E45: =SUBSTITUTE(VLOOKUP(LEFT(E95,LEN(layout)+3),label,RIGHT(E95,1)+2,0),0,"") -> EXIT | F45: =VLOOKUP(LEFT(F95,LEN(layout)+3),label,RIGHT(F95,1)+1,0) -> 0 | I45: =SUBSTITUTE(VLOOKUP(LEFT(I95,LEN(layout)+3),label,RIGHT(I95,1)+2,0),0,"") -> : | J45: =VLOOKUP(LEFT(J95,LEN(layout)+3),label,RIGHT(J95,1)+1,0) -> • | M45: =SUBSTITUTE(VLOOKUP(LEFT(M95,LEN(layout)+3),label,RIGHT(M95,1)+2,0),0,"") -> , | N45: =VLOOKUP(LEFT(N95,LEN(layout)+3),label,RIGHT(N95,1)+1,0) -> R/S | Q45: =SUBSTITUTE(VLOOKUP(LEFT(Q95,LEN(layout)+3),label,RIGHT(Q95,1)+2,0),0,"") -> ？ | R45: =VLOOKUP(LEFT(R95,LEN(layout)+3),label,RIGHT(R95,1)+1,0) -> + | U45: =SUBSTITUTE(VLOOKUP(LEFT(U95,LEN(layout)+3),label,RIGHT(U95,1)+2,0),0,"") -> spc
C48: =VLOOKUP(LEFT(C94,LEN(layout)+3),label,RIGHT(C94,1)+6,0) -> OFF | D48: =VLOOKUP(LEFT(D94,LEN(layout)+3),label,RIGHT(D94,1)+6,0) -> SNAP | E48: =VLOOKUP(LEFT(E95,LEN(layout)+3),label,RIGHT(E95,1)+6,0) -> EXIT | F48: =VLOOKUP(LEFT(F94,LEN(layout)+3),label,RIGHT(F94,1)+6,0) -> ; | H48: =VLOOKUP(LEFT(H94,LEN(layout)+3),label,RIGHT(H94,1)+6,0) -> 0 | I48: =VLOOKUP(LEFT(I95,LEN(layout)+3),label,RIGHT(I95,1)+6,0) -> 0 | J48: =VLOOKUP(LEFT(J94,LEN(layout)+3),label,RIGHT(J94,1)+6,0) -> # | L48: =VLOOKUP(LEFT(L94,LEN(layout)+3),label,RIGHT(L94,1)+6,0) -> . | M48: =VLOOKUP(LEFT(M95,LEN(layout)+3),label,RIGHT(M95,1)+6,0) -> . | N48: =VLOOKUP(LEFT(N94,LEN(layout)+3),label,RIGHT(N94,1)+6,0) -> ! | P48: =VLOOKUP(LEFT(P94,LEN(layout)+3),label,RIGHT(P94,1)+6,0) -> / | Q48: =VLOOKUP(LEFT(Q95,LEN(layout)+3),label,RIGHT(Q95,1)+6,0) | R48: =VLOOKUP(LEFT(R94,LEN(layout)+3),label,RIGHT(R94,1)+6,0) -> = | T48: =VLOOKUP(LEFT(T94,LEN(layout)+3),label,RIGHT(T94,1)+6,0) -> + | U48: =VLOOKUP(LEFT(U95,LEN(layout)+3),label,RIGHT(U95,1)+6,0) -> + | W48: NEW | X48: C47 | Y48: 1 | Z48: 1 | AA48: =X48&"."&Y48&Z48 -> C47.11 | AB48: F1
X49: =X48 -> C47 | Y49: 1 | Z49: 2 | AA49: =X49&"."&Y49&Z49 -> C47.12 | AB49: F2
C50: =2/10 -> 0.2 | D50: =3/10 -> 0.3 | E50: =4/10 -> 0.4 | G50: =2/10 -> 0.2 | H50: =3/10 -> 0.3 | I50: =4/10 -> 0.4 | J50: =2/10 -> 0.2 | K50: =3/10 -> 0.3 | L50: =4/10 -> 0.4 | M50: =2/10 -> 0.2 | N50: =3/10 -> 0.3 | O50: =4/10 -> 0.4 | P50: =2/10 -> 0.2 | Q50: =3/10 -> 0.3 | R50: =4/10 -> 0.4 | S50: =2/10 -> 0.2 | T50: =3/10 -> 0.3 | U50: =4/10 -> 0.4 | X50: =X49 -> C47 | Y50: 1 | Z50: 3 | AA50: =X50&"."&Y50&Z50 -> C47.13 | AB50: F3 | AM50: DOCUMENTATION | AX50: CODE GENERATION | AY50: not be be edited manually | BI50: ="// "&X50&" Layout from Layout_template_automation template: Do not change manually" -> // C47 Layout from Layout_template_automation template: Do not change manually
C51: 1 | D51: 1 | E51: 1 | G51: 2 | H51: 2 | I51: 2 | J51: 3 | K51: 3 | L51: 3 | M51: 4 | N51: 4 | O51: 4 | P51: 5 | Q51: 5 | R51: 5 | S51: 6 | T51: 6 | U51: 6 | X51: =X50 -> C47 | Y51: 1 | Z51: 4 | AA51: =X51&"."&Y51&Z51 -> C47.14 | AB51: F4 | BI51: //This variable is to store in flash memory
B52: 10 | X52: =X51 -> C47 | Y52: 1 | Z52: 5 | AA52: =X52&"."&Y52&Z52 -> C47.15 | AB52: F4 | AL52: =X52 -> C47 | AM52: Lookup label items | AP52: Double lookup F:G | AQ52: lookup label items | AR52: manual input | AS52: manual input | AT52: manual input | BI52: ="TO_QSPI const calcKey_t kbd_std_C47[37] = { //C47 Layout, in the default position without suffix, kbd_std" -> TO_QSPI const calcKey_t kbd_std_C47[37] = { //C47 Layout, in the default position without suffix, kbd_std
A53: 0.1 | B53: 10 | C53: =layout&"."&$B55+C51+$A53 -> C47.11,1 | G53: =layout&"."&$B55+G51+$A53 -> C47.12,1 | J53: =layout&"."&$B55+J51+$A53 -> C47.13,1 | M53: =layout&"."&$B55+M51+$A53 -> C47.14,1 | P53: =layout&"."&$B55+P51+$A53 -> C47.15,1 | S53: =layout&"."&$B55+S51+$A53 -> C47.16,1 | X53: =X52 -> C47 | Y53: 1 | Z53: 6 | AA53: =X53&"."&Y53&Z53 -> C47.16 | AB53: F6 | BI53: //keyID, primary, fShifted, gShifted, keyLblAim, primaryAim, fShiftedAim, gShiftedAim, primaryTam | BL53: HelperA | BM53: HelperB
A54: 0.1 | B54: 10 | X54: =X53 -> C47 | Y54: 2 | Z54: 1 | AA54: =X54&"."&Y54&Z54 -> C47.21 | AB54: Sigma+ | AC54: ->I | AD54: a b/c | AF54: A | AG54: =AF54=AH54 -> TRUE | AH54: =INDEX(labelitem,MATCH(AR54,items,0),1) -> a | AI54: =INDEX(labelitem,MATCH(AS54,items,0),1) -> Sigma | AJ54: =INDEX(labelitem,MATCH(AT54,items,0),1) -> Reg A | AL54: ="{"&Y54*10+Z54 -> {21 | AM54: =VLOOKUP(AB54,labelitem,2,0) -> ITM_SIGMAPLUS | AN54: =VLOOKUP(AC54,labelitem,2,0) -> ITM_RI | AO54: =VLOOKUP(AD54,labelitem,2,0) -> ITM_TGLFRT | AP54: =IF(NOT(ISNA(MATCH(AM54,Lookups!E:E,))),VLOOKUP(AM54,Lookups!E:F,2,0), IF(NOT(ISNA(MATCH(AN54,Lookups!E:E,))),VLOOKUP(AN54,Lookups!E:F,2,0), IF(NOT(ISNA(MATCH(AO54,Lookups!E:E,))),VLOOKUP(AO54,Lookups!E:F,2,0),"ITM_NULL"))) -> ITM_NULL | AQ54: =VLOOKUP(AF54,labelitem,2,0) -> ITM_A | AR54: ITM_a.lo | AS54: ITM_SIGMA | AT54: ITM_REG_A | AW54: =AL54 -> {21 | AX54: {=SUBSTITUTE(SUBSTITUTE(_xlfn.SWITCH(AM54, "ITM_T_HOME", "ITM_UP1", "ITM_T_END", "ITM_DOWN1", "DOCU_CHR_sub", "ITM_DOWN_ARROW", "DOCU_CHR_super", "ITM_UP_ARROW", "MNU_TAMALPHA", "ITM_alpha", "DOCU_CHR_caseFLIP", "ITM_NULL", "DOCU_CHR_numSET", "ITM_NULL", "DOCU_ITM_RADIX", "ITM_PERIOD", AM54), ".lo", ),"MNU_", "-MNU_")} -> ITM_SIGMAPLUS | AY54: {=SUBSTITUTE(SUBSTITUTE(_xlfn.SWITCH(AN54, "ITM_T_HOME", "ITM_UP1", "ITM_T_END", "ITM_DOWN1", "DOCU_CHR_sub", "ITM_DOWN_ARROW", "DOCU_CHR_super", "ITM_UP_ARROW", "MNU_TAMALPHA", "ITM_alpha", "DOCU_CHR_caseFLIP", "ITM_NULL", "DOCU_CHR_numSET", "ITM_NULL", "DOCU_ITM_RADIX", "ITM_PERIOD", AN54), ".lo", ),"MNU_", "-MNU_")} -> ITM_RI | AZ54: {=SUBSTITUTE(SUBSTITUTE(_xlfn.SWITCH(AO54, "ITM_T_HOME", "ITM_UP1", "ITM_T_END", "ITM_DOWN1", "DOCU_CHR_sub", "ITM_DOWN_ARROW", "DOCU_CHR_super", "ITM_UP_ARROW", "MNU_TAMALPHA", "ITM_alpha", "DOCU_CHR_caseFLIP", "ITM_NULL", "DOCU_CHR_numSET", "ITM_NULL", "DOCU_ITM_RADIX", "ITM_PERIOD", AO54), ".lo", ),"MNU_", "-MNU_")} -> ITM_TGLFRT | BA54: {=SUBSTITUTE(SUBSTITUTE(_xlfn.SWITCH(AP54, "ITM_T_HOME", "ITM_UP1", "ITM_T_END", "ITM_DOWN1", "DOCU_CHR_sub", "ITM_DOWN_ARROW", "DOCU_CHR_super", "ITM_UP_ARROW", "MNU_TAMALPHA", "ITM_alpha", "DOCU_CHR_caseFLIP", "ITM_NULL", "DOCU_CHR_numSET", "ITM_NULL", "DOCU_ITM_RADIX", "ITM_PERIOD", AP54), ".lo", ),"MNU_", "-MNU_")} -> ITM_NULL | BB54: {=SUBSTITUTE(SUBSTITUTE(_xlfn.SWITCH(AQ54, "ITM_T_HOME", "ITM_UP1", "ITM_T_END", "ITM_DOWN1", "DOCU_CHR_sub", "ITM_DOWN_ARROW", "DOCU_CHR_super", "ITM_UP_ARROW", "MNU_TAMALPHA", "ITM_alpha", "DOCU_CHR_caseFLIP", "ITM_NULL", "DOCU_CHR_numSET", "ITM_NULL", "DOCU_ITM_RADIX", "ITM_PERIOD", AQ54), ".lo", ),"MNU_", "-MNU_")} -> ITM_A | BC54: {=SUBSTITUTE(SUBSTITUTE(_xlfn.SWITCH(AR54, "ITM_T_HOME", "ITM_UP1", "ITM_T_END", "ITM_DOWN1", "DOCU_CHR_sub", "ITM_DOWN_ARROW", "DOCU_CHR_super", "ITM_UP_ARROW", "MNU_TAMALPHA", "ITM_alpha", "DOCU_CHR_caseFLIP", "ITM_NULL", "DOCU_CHR_numSET", "ITM_NULL", "DOCU_ITM_RADIX", "ITM_PERIOD", AR54), ".lo", ),"MNU_", "-MNU_")} -> ITM_a | BD54: {=SUBSTITUTE(SUBSTITUTE(_xlfn.SWITCH(AS54, "ITM_T_HOME", "ITM_UP1", "ITM_T_END", "ITM_DOWN1", "DOCU_CHR_sub", "ITM_DOWN_ARROW", "DOCU_CHR_super", "ITM_UP_ARROW", "MNU_TAMALPHA", "ITM_alpha", "DOCU_CHR_caseFLIP", "ITM_NULL", "DOCU_CHR_numSET", "ITM_NULL", "DOCU_ITM_RADIX", "ITM_PERIOD", AS54), ".lo", ),"MNU_", "-MNU_")} -> ITM_SIGMA | BE54: {=SUBSTITUTE(SUBSTITUTE(_xlfn.SWITCH(AT54, "ITM_T_HOME", "ITM_UP1", "ITM_T_END", "ITM_DOWN1", "DOCU_CHR_sub", "ITM_DOWN_ARROW", "DOCU_CHR_super", "ITM_UP_ARROW", "MNU_TAMALPHA", "ITM_alpha", "DOCU_CHR_caseFLIP", "ITM_NULL", "DOCU_CHR_numSET", "ITM_NULL", "DOCU_ITM_RADIX", "ITM_PERIOD", AT54), ".lo", ),"MNU_", "-MNU_")} -> ITM_REG_A | BH54: 20 | BI54: =" "&AW54&", "&REPT(" ",$BH$54-LEN(AW54))& AX54&", "&REPT(" ",$BH$54-LEN(AX54))& AY54&", "&REPT(" ",$BH$54-LEN(AY54))& AZ54&", "&REPT(" ",$BH$54-LEN(AZ54))& BA54&", "&REPT(" ",$BH$54-LEN(BA54))& BB54&", "&REPT(" ",$BH$54-LEN(BB54))& BC54&", "&REPT(" ",$BH$54-LEN(BC54))& BD54&", "&REPT(" ",$BH$54-LEN(BD54))& BE54&REPT(" ",$BH$54-LEN(BE54))& "}," -> {21, ITM_SIGMAPLUS, ITM_RI, ITM_TGLFRT, ITM_NULL, ITM_A, ITM_a, ITM_SIGMA, ITM_REG_A }, | BL54: =SUBSTITUTE(AR54,".lo","") -> ITM_a | BM54: =SUBSTITUTE(AS54,".lo","") -> ITM_SIGMA
A55: 0.1 | B55: 10 | X55: =X54 -> C47 | Y55: 2 | Z55: 2 | AA55: =X55&"."&Y55&Z55 -> C47.22 | AB55: 1/x | AC55: y^x | AD55: # | AF55: B | AG55: =AF55=AH55 -> TRUE | AH55: =INDEX(labelitem,MATCH(AR55,items,0),1) -> b | AI55: =INDEX(labelitem,MATCH(AS55,items,0),1) -> ^ | AJ55: =INDEX(labelitem,MATCH(AT55,items,0),1) -> Reg B | AL55: ="{"&Y55*10+Z55 -> {22 | AM55: =VLOOKUP(AB55,labelitem,2,0) -> ITM_1ONX | AN55: =VLOOKUP(AC55,labelitem,2,0) -> ITM_YX | AO55: =VLOOKUP(AD55,labelitem,2,0) -> ITM_HASH_JM | AP55: =IF(NOT(ISNA(MATCH(AM55,Lookups!E:E,))),VLOOKUP(AM55,Lookups!E:F,2,0), IF(NOT(ISNA(MATCH(AN55,Lookups!E:E,))),VLOOKUP(AN55,Lookups!E:F,2,0), IF(NOT(ISNA(MATCH(AO55,Lookups!E:E,))),VLOOKUP(AO55,Lookups!E:F,2,0),"ITM_NULL"))) -> ITM_NUMBER_SIGN | AQ55: =VLOOKUP(AF55,labelitem,2,0) -> ITM_B | AR55: ITM_b.lo | AS55: ITM_CIRCUMFLEX | AT55: ITM_REG_B | AW55: =AL55 -> {22 | AX55: {=SUBSTITUTE(SUBSTITUTE(_xlfn.SWITCH(AM55, "ITM_T_HOME", "ITM_UP1", "ITM_T_END", "ITM_DOWN1", "DOCU_CHR_sub", "ITM_DOWN_ARROW", "DOCU_CHR_super", "ITM_UP_ARROW", "MNU_TAMALPHA", "ITM_alpha", "DOCU_CHR_caseFLIP", "ITM_NULL", "DOCU_CHR_numSET", "ITM_NULL", "DOCU_ITM_RADIX", "ITM_PERIOD", AM55), ".lo", ),"MNU_", "-MNU_")} -> ITM_1ONX | AY55: {=SUBSTITUTE(SUBSTITUTE(_xlfn.SWITCH(AN55, "ITM_T_HOME", "ITM_UP1", "ITM_T_END", "ITM_DOWN1", "DOCU_CHR_sub", "ITM_DOWN_ARROW", "DOCU_CHR_super", "ITM_UP_ARROW", "MNU_TAMALPHA", "ITM_alpha", "DOCU_CHR_caseFLIP", "ITM_NULL", "DOCU_CHR_numSET", "ITM_NULL", "DOCU_ITM_RADIX", "ITM_PERIOD", AN55), ".lo", ),"MNU_", "-MNU_")} -> ITM_YX | AZ55: {=SUBSTITUTE(SUBSTITUTE(_xlfn.SWITCH(AO55, "ITM_T_HOME", "ITM_UP1", "ITM_T_END", "ITM_DOWN1", "DOCU_CHR_sub", "ITM_DOWN_ARROW", "DOCU_CHR_super", "ITM_UP_ARROW", "MNU_TAMALPHA", "ITM_alpha", "DOCU_CHR_caseFLIP", "ITM_NULL", "DOCU_CHR_numSET", "ITM_NULL", "DOCU_ITM_RADIX", "ITM_PERIOD", AO55), ".lo", ),"MNU_", "-MNU_")} -> ITM_HASH_JM | BA55: {=SUBSTITUTE(SUBSTITUTE(_xlfn.SWITCH(AP55, "ITM_T_HOME", "ITM_UP1", "ITM_T_END", "ITM_DOWN1", "DOCU_CHR_sub", "ITM_DOWN_ARROW", "DOCU_CHR_super", "ITM_UP_ARROW", "MNU_TAMALPHA", "ITM_alpha", "DOCU_CHR_caseFLIP", "ITM_NULL", "DOCU_CHR_numSET", "ITM_NULL", "DOCU_ITM_RADIX", "ITM_PERIOD", AP55), ".lo", ),"MNU_", "-MNU_")} -> ITM_NUMBER_SIGN | BB55: {=SUBSTITUTE(SUBSTITUTE(_xlfn.SWITCH(AQ55, "ITM_T_HOME", "ITM_UP1", "ITM_T_END", "ITM_DOWN1", "DOCU_CHR_sub", "ITM_DOWN_ARROW", "DOCU_CHR_super", "ITM_UP_ARROW", "MNU_TAMALPHA", "ITM_alpha", "DOCU_CHR_caseFLIP", "ITM_NULL", "DOCU_CHR_numSET", "ITM_NULL", "DOCU_ITM_RADIX", "ITM_PERIOD", AQ55), ".lo", ),"MNU_", "-MNU_")} -> ITM_B | BC55: {=SUBSTITUTE(SUBSTITUTE(_xlfn.SWITCH(AR55, "ITM_T_HOME", "ITM_UP1", "ITM_T_END", "ITM_DOWN1", "DOCU_CHR_sub", "ITM_DOWN_ARROW", "DOCU_CHR_super", "ITM_UP_ARROW", "MNU_TAMALPHA", "ITM_alpha", "DOCU_CHR_caseFLIP", "ITM_NULL", "DOCU_CHR_numSET", "ITM_NULL", "DOCU_ITM_RADIX", "ITM_PERIOD", AR55), ".lo", ),"MNU_", "-MNU_")} -> ITM_b | BD55: {=SUBSTITUTE(SUBSTITUTE(_xlfn.SWITCH(AS55, "ITM_T_HOME", "ITM_UP1", "ITM_T_END", "ITM_DOWN1", "DOCU_CHR_sub", "ITM_DOWN_ARROW", "DOCU_CHR_super", "ITM_UP_ARROW", "MNU_TAMALPHA", "ITM_alpha", "DOCU_CHR_caseFLIP", "ITM_NULL", "DOCU_CHR_numSET", "ITM_NULL", "DOCU_ITM_RADIX", "ITM_PERIOD", AS55), ".lo", ),"MNU_", "-MNU_")} -> ITM_CIRCUMFLEX | BE55: {=SUBSTITUTE(SUBSTITUTE(_xlfn.SWITCH(AT55, "ITM_T_HOME", "ITM_UP1", "ITM_T_END", "ITM_DOWN1", "DOCU_CHR_sub", "ITM_DOWN_ARROW", "DOCU_CHR_super", "ITM_UP_ARROW", "MNU_TAMALPHA", "ITM_alpha", "DOCU_CHR_caseFLIP", "ITM_NULL", "DOCU_CHR_numSET", "ITM_NULL", "DOCU_ITM_RADIX", "ITM_PERIOD", AT55), ".lo", ),"MNU_", "-MNU_")} -> ITM_REG_B | BI55: =" "&AW55&", "&REPT(" ",$BH$54-LEN(AW55))& AX55&", "&REPT(" ",$BH$54-LEN(AX55))& AY55&", "&REPT(" ",$BH$54-LEN(AY55))& AZ55&", "&REPT(" ",$BH$54-LEN(AZ55))& BA55&", "&REPT(" ",$BH$54-LEN(BA55))& BB55&", "&REPT(" ",$BH$54-LEN(BB55))& BC55&", "&REPT(" ",$BH$54-LEN(BC55))& BD55&", "&REPT(" ",$BH$54-LEN(BD55))& BE55&REPT(" ",$BH$54-LEN(BE55))& "}," -> {22, ITM_1ONX, ITM_YX, ITM_HASH_JM, ITM_NUMBER_SIGN, ITM_B, ITM_b, ITM_CIRCUMFLEX, ITM_REG_B }, | BL55: =SUBSTITUTE(AR55,".lo","") -> ITM_b | BM55: =SUBSTITUTE(AS55,".lo","") -> ITM_CIRCUMFLEX
C56: =2/10 -> 0.2 | D56: =3/10 -> 0.3 | E56: =4/10 -> 0.4 | G56: =2/10 -> 0.2 | H56: =3/10 -> 0.3 | I56: =4/10 -> 0.4 | J56: =2/10 -> 0.2 | K56: =3/10 -> 0.3 | L56: =4/10 -> 0.4 | M56: =2/10 -> 0.2 | N56: =3/10 -> 0.3 | O56: =4/10 -> 0.4 | P56: =2/10 -> 0.2 | Q56: =3/10 -> 0.3 | R56: =4/10 -> 0.4 | S56: =2/10 -> 0.2 | T56: =3/10 -> 0.3 | U56: =4/10 -> 0.4 | X56: =X55 -> C47 | Y56: 2 | Z56: 3 | AA56: =X56&"."&Y56&Z56 -> C47.23 | AB56: √x | AC56: x^2 | AD56: .ms | AF56: C | AG56: =AF56=AH56 -> TRUE | AH56: =INDEX(labelitem,MATCH(AR56,items,0),1) -> c | AI56: =INDEX(labelitem,MATCH(AS56,items,0),1) -> √ | AJ56: =INDEX(labelitem,MATCH(AT56,items,0),1) -> Reg C | AL56: ="{"&Y56*10+Z56 -> {23 | AM56: =VLOOKUP(AB56,labelitem,2,0) -> ITM_SQUAREROOTX | AN56: =VLOOKUP(AC56,labelitem,2,0) -> ITM_SQUARE | AO56: =VLOOKUP(AD56,labelitem,2,0) -> ITM_ms | AP56: =IF(NOT(ISNA(MATCH(AM56,Lookups!E:E,))),VLOOKUP(AM56,Lookups!E:F,2,0), IF(NOT(ISNA(MATCH(AN56,Lookups!E:E,))),VLOOKUP(AN56,Lookups!E:F,2,0), IF(NOT(ISNA(MATCH(AO56,Lookups!E:E,))),VLOOKUP(AO56,Lookups!E:F,2,0),"ITM_NULL"))) -> ITM_ROOT_SIGN | AQ56: =VLOOKUP(AF56,labelitem,2,0) -> ITM_C | AR56: ITM_c.lo | AS56: ITM_ROOT_SIGN | AT56: ITM_REG_C | AW56: =AL56 -> {23 | AX56: {=SUBSTITUTE(SUBSTITUTE(_xlfn.SWITCH(AM56, "ITM_T_HOME", "ITM_UP1", "ITM_T_END", "ITM_DOWN1", "DOCU_CHR_sub", "ITM_DOWN_ARROW", "DOCU_CHR_super", "ITM_UP_ARROW", "MNU_TAMALPHA", "ITM_alpha", "DOCU_CHR_caseFLIP", "ITM_NULL", "DOCU_CHR_numSET", "ITM_NULL", "DOCU_ITM_RADIX", "ITM_PERIOD", AM56), ".lo", ),"MNU_", "-MNU_")} -> ITM_SQUAREROOTX | AY56: {=SUBSTITUTE(SUBSTITUTE(_xlfn.SWITCH(AN56, "ITM_T_HOME", "ITM_UP1", "ITM_T_END", "ITM_DOWN1", "DOCU_CHR_sub", "ITM_DOWN_ARROW", "DOCU_CHR_super", "ITM_UP_ARROW", "MNU_TAMALPHA", "ITM_alpha", "DOCU_CHR_caseFLIP", "ITM_NULL", "DOCU_CHR_numSET", "ITM_NULL", "DOCU_ITM_RADIX", "ITM_PERIOD", AN56), ".lo", ),"MNU_", "-MNU_")} -> ITM_SQUARE | AZ56: {=SUBSTITUTE(SUBSTITUTE(_xlfn.SWITCH(AO56, "ITM_T_HOME", "ITM_UP1", "ITM_T_END", "ITM_DOWN1", "DOCU_CHR_sub", "ITM_DOWN_ARROW", "DOCU_CHR_super", "ITM_UP_ARROW", "MNU_TAMALPHA", "ITM_alpha", "DOCU_CHR_caseFLIP", "ITM_NULL", "DOCU_CHR_numSET", "ITM_NULL", "DOCU_ITM_RADIX", "ITM_PERIOD", AO56), ".lo", ),"MNU_", "-MNU_")} -> ITM_ms | BA56: {=SUBSTITUTE(SUBSTITUTE(_xlfn.SWITCH(AP56, "ITM_T_HOME", "ITM_UP1", "ITM_T_END", "ITM_DOWN1", "DOCU_CHR_sub", "ITM_DOWN_ARROW", "DOCU_CHR_super", "ITM_UP_ARROW", "MNU_TAMALPHA", "ITM_alpha", "DOCU_CHR_caseFLIP", "ITM_NULL", "DOCU_CHR_numSET", "ITM_NULL", "DOCU_ITM_RADIX", "ITM_PERIOD", AP56), ".lo", ),"MNU_", "-MNU_")} -> ITM_ROOT_SIGN | BB56: {=SUBSTITUTE(SUBSTITUTE(_xlfn.SWITCH(AQ56, "ITM_T_HOME", "ITM_UP1", "ITM_T_END", "ITM_DOWN1", "DOCU_CHR_sub", "ITM_DOWN_ARROW", "DOCU_CHR_super", "ITM_UP_ARROW", "MNU_TAMALPHA", "ITM_alpha", "DOCU_CHR_caseFLIP", "ITM_NULL", "DOCU_CHR_numSET", "ITM_NULL", "DOCU_ITM_RADIX", "ITM_PERIOD", AQ56), ".lo", ),"MNU_", "-MNU_")} -> ITM_C | BC56: {=SUBSTITUTE(SUBSTITUTE(_xlfn.SWITCH(AR56, "ITM_T_HOME", "ITM_UP1", "ITM_T_END", "ITM_DOWN1", "DOCU_CHR_sub", "ITM_DOWN_ARROW", "DOCU_CHR_super", "ITM_UP_ARROW", "MNU_TAMALPHA", "ITM_alpha", "DOCU_CHR_caseFLIP", "ITM_NULL", "DOCU_CHR_numSET", "ITM_NULL", "DOCU_ITM_RADIX", "ITM_PERIOD", AR56), ".lo", ),"MNU_", "-MNU_")} -> ITM_c | BD56: {=SUBSTITUTE(SUBSTITUTE(_xlfn.SWITCH(AS56, "ITM_T_HOME", "ITM_UP1", "ITM_T_END", "ITM_DOWN1", "DOCU_CHR_sub", "ITM_DOWN_ARROW", "DOCU_CHR_super", "ITM_UP_ARROW", "MNU_TAMALPHA", "ITM_alpha", "DOCU_CHR_caseFLIP", "ITM_NULL", "DOCU_CHR_numSET", "ITM_NULL", "DOCU_ITM_RADIX", "ITM_PERIOD", AS56), ".lo", ),"MNU_", "-MNU_")} -> ITM_ROOT_SIGN | BE56: {=SUBSTITUTE(SUBSTITUTE(_xlfn.SWITCH(AT56, "ITM_T_HOME", "ITM_UP1", "ITM_T_END", "ITM_DOWN1", "DOCU_CHR_sub", "ITM_DOWN_ARROW", "DOCU_CHR_super", "ITM_UP_ARROW", "MNU_TAMALPHA", "ITM_alpha", "DOCU_CHR_caseFLIP", "ITM_NULL", "DOCU_CHR_numSET", "ITM_NULL", "DOCU_ITM_RADIX", "ITM_PERIOD", AT56), ".lo", ),"MNU_", "-MNU_")} -> ITM_REG_C | BI56: =" "&AW56&", "&REPT(" ",$BH$54-LEN(AW56))& AX56&", "&REPT(" ",$BH$54-LEN(AX56))& AY56&", "&REPT(" ",$BH$54-LEN(AY56))& AZ56&", "&REPT(" ",$BH$54-LEN(AZ56))& BA56&", "&REPT(" ",$BH$54-LEN(BA56))& BB56&", "&REPT(" ",$BH$54-LEN(BB56))& BC56&", "&REPT(" ",$BH$54-LEN(BC56))& BD56&", "&REPT(" ",$BH$54-LEN(BD56))& BE56&REPT(" ",$BH$54-LEN(BE56))& "}," -> {23, ITM_SQUAREROOTX, ITM_SQUARE, ITM_ms, ITM_ROOT_SIGN, ITM_C, ITM_c, ITM_ROOT_SIGN, ITM_REG_C }, | BL56: =SUBSTITUTE(AR56,".lo","") -> ITM_c | BM56: =SUBSTITUTE(AS56,".lo","") -> ITM_ROOT_SIGN
C57: 1 | D57: 1 | E57: 1 | G57: 2 | H57: 2 | I57: 2 | J57: 3 | K57: 3 | L57: 3 | M57: 4 | N57: 4 | O57: 4 | P57: 5 | Q57: 5 | R57: 5 | S57: 6 | T57: 6 | U57: 6 | X57: =X56 -> C47 | Y57: 2 | Z57: 4 | AA57: =X57&"."&Y57&Z57 -> C47.24 | AB57: LOG | AC57: 10^x | AD57: .d | AF57: D | AG57: =AF57=AH57 -> TRUE | AH57: =INDEX(labelitem,MATCH(AR57,items,0),1) -> d | AI57: =INDEX(labelitem,MATCH(AS57,items,0),1) -> LOG | AJ57: =INDEX(labelitem,MATCH(AT57,items,0),1) -> Reg D | AL57: ="{"&Y57*10+Z57 -> {24 | AM57: =VLOOKUP(AB57,labelitem,2,0) -> ITM_LOG10 | AN57: =VLOOKUP(AC57,labelitem,2,0) -> ITM_10x | AO57: =VLOOKUP(AD57,labelitem,2,0) -> ITM_dotD | AP57: =IF(NOT(ISNA(MATCH(AM57,Lookups!E:E,))),VLOOKUP(AM57,Lookups!E:F,2,0), IF(NOT(ISNA(MATCH(AN57,Lookups!E:E,))),VLOOKUP(AN57,Lookups!E:F,2,0), IF(NOT(ISNA(MATCH(AO57,Lookups!E:E,))),VLOOKUP(AO57,Lookups!E:F,2,0),"ITM_NULL"))) -> ITM_NULL | AQ57: =VLOOKUP(AF57,labelitem,2,0) -> ITM_D | AR57: ITM_d.lo | AS57: ITM_LG_SIGN | AT57: ITM_REG_D | AW57: =AL57 -> {24 | AX57: {=SUBSTITUTE(SUBSTITUTE(_xlfn.SWITCH(AM57, "ITM_T_HOME", "ITM_UP1", "ITM_T_END", "ITM_DOWN1", "DOCU_CHR_sub", "ITM_DOWN_ARROW", "DOCU_CHR_super", "ITM_UP_ARROW", "MNU_TAMALPHA", "ITM_alpha", "DOCU_CHR_caseFLIP", "ITM_NULL", "DOCU_CHR_numSET", "ITM_NULL", "DOCU_ITM_RADIX", "ITM_PERIOD", AM57), ".lo", ),"MNU_", "-MNU_")} -> ITM_LOG10 | AY57: {=SUBSTITUTE(SUBSTITUTE(_xlfn.SWITCH(AN57, "ITM_T_HOME", "ITM_UP1", "ITM_T_END", "ITM_DOWN1", "DOCU_CHR_sub", "ITM_DOWN_ARROW", "DOCU_CHR_super", "ITM_UP_ARROW", "MNU_TAMALPHA", "ITM_alpha", "DOCU_CHR_caseFLIP", "ITM_NULL", "DOCU_CHR_numSET", "ITM_NULL", "DOCU_ITM_RADIX", "ITM_PERIOD", AN57), ".lo", ),"MNU_", "-MNU_")} -> ITM_10x | AZ57: {=SUBSTITUTE(SUBSTITUTE(_xlfn.SWITCH(AO57, "ITM_T_HOME", "ITM_UP1", "ITM_T_END", "ITM_DOWN1", "DOCU_CHR_sub", "ITM_DOWN_ARROW", "DOCU_CHR_super", "ITM_UP_ARROW", "MNU_TAMALPHA", "ITM_alpha", "DOCU_CHR_caseFLIP", "ITM_NULL", "DOCU_CHR_numSET", "ITM_NULL", "DOCU_ITM_RADIX", "ITM_PERIOD", AO57), ".lo", ),"MNU_", "-MNU_")} -> ITM_dotD | BA57: {=SUBSTITUTE(SUBSTITUTE(_xlfn.SWITCH(AP57, "ITM_T_HOME", "ITM_UP1", "ITM_T_END", "ITM_DOWN1", "DOCU_CHR_sub", "ITM_DOWN_ARROW", "DOCU_CHR_super", "ITM_UP_ARROW", "MNU_TAMALPHA", "ITM_alpha", "DOCU_CHR_caseFLIP", "ITM_NULL", "DOCU_CHR_numSET", "ITM_NULL", "DOCU_ITM_RADIX", "ITM_PERIOD", AP57), ".lo", ),"MNU_", "-MNU_")} -> ITM_NULL | BB57: {=SUBSTITUTE(SUBSTITUTE(_xlfn.SWITCH(AQ57, "ITM_T_HOME", "ITM_UP1", "ITM_T_END", "ITM_DOWN1", "DOCU_CHR_sub", "ITM_DOWN_ARROW", "DOCU_CHR_super", "ITM_UP_ARROW", "MNU_TAMALPHA", "ITM_alpha", "DOCU_CHR_caseFLIP", "ITM_NULL", "DOCU_CHR_numSET", "ITM_NULL", "DOCU_ITM_RADIX", "ITM_PERIOD", AQ57), ".lo", ),"MNU_", "-MNU_")} -> ITM_D | BC57: {=SUBSTITUTE(SUBSTITUTE(_xlfn.SWITCH(AR57, "ITM_T_HOME", "ITM_UP1", "ITM_T_END", "ITM_DOWN1", "DOCU_CHR_sub", "ITM_DOWN_ARROW", "DOCU_CHR_super", "ITM_UP_ARROW", "MNU_TAMALPHA", "ITM_alpha", "DOCU_CHR_caseFLIP", "ITM_NULL", "DOCU_CHR_numSET", "ITM_NULL", "DOCU_ITM_RADIX", "ITM_PERIOD", AR57), ".lo", ),"MNU_", "-MNU_")} -> ITM_d | BD57: {=SUBSTITUTE(SUBSTITUTE(_xlfn.SWITCH(AS57, "ITM_T_HOME", "ITM_UP1", "ITM_T_END", "ITM_DOWN1", "DOCU_CHR_sub", "ITM_DOWN_ARROW", "DOCU_CHR_super", "ITM_UP_ARROW", "MNU_TAMALPHA", "ITM_alpha", "DOCU_CHR_caseFLIP", "ITM_NULL", "DOCU_CHR_numSET", "ITM_NULL", "DOCU_ITM_RADIX", "ITM_PERIOD", AS57), ".lo", ),"MNU_", "-MNU_")} -> ITM_LG_SIGN | BE57: {=SUBSTITUTE(SUBSTITUTE(_xlfn.SWITCH(AT57, "ITM_T_HOME", "ITM_UP1", "ITM_T_END", "ITM_DOWN1", "DOCU_CHR_sub", "ITM_DOWN_ARROW", "DOCU_CHR_super", "ITM_UP_ARROW", "MNU_TAMALPHA", "ITM_alpha", "DOCU_CHR_caseFLIP", "ITM_NULL", "DOCU_CHR_numSET", "ITM_NULL", "DOCU_ITM_RADIX", "ITM_PERIOD", AT57), ".lo", ),"MNU_", "-MNU_")} -> ITM_REG_D | BI57: =" "&AW57&", "&REPT(" ",$BH$54-LEN(AW57))& AX57&", "&REPT(" ",$BH$54-LEN(AX57))& AY57&", "&REPT(" ",$BH$54-LEN(AY57))& AZ57&", "&REPT(" ",$BH$54-LEN(AZ57))& BA57&", "&REPT(" ",$BH$54-LEN(BA57))& BB57&", "&REPT(" ",$BH$54-LEN(BB57))& BC57&", "&REPT(" ",$BH$54-LEN(BC57))& BD57&", "&REPT(" ",$BH$54-LEN(BD57))& BE57&REPT(" ",$BH$54-LEN(BE57))& "}," -> {24, ITM_LOG10, ITM_10x, ITM_dotD, ITM_NULL, ITM_D, ITM_d, ITM_LG_SIGN, ITM_REG_D }, | BL57: =SUBSTITUTE(AR57,".lo","") -> ITM_d | BM57: =SUBSTITUTE(AS57,".lo","") -> ITM_LG_SIGN
...

Sheet Lookups
B1: Label | C1: Item | E1: keyLblAim lookups
B2: 0 | C2: ITM_0 | E2: ITM_SQUAREROOTX | F2: ITM_ROOT_SIGN
B3: 0 | C3: ITM_0 | E3: ITM_ENTER | F3: ITM_ENTER | H3: .lo | I3: ="" | J3: ="A1" -> A1 | K3: ="Substitute(" & J3 & "; """&H3&"""; """ & I3 &"""); " -> Substitute(A1; ".lo"; ""); | L3: formula | M3: =K4 -> Substitute(Substitute(A1; ".lo"; ""); "MNU_"; "-MNU_")
B4: 1 | C4: ITM_1 | E4: ITM_XexY | F4: ITM_ex | H4: MNU_ | I4: ="-MNU_" -> -MNU_ | K4: ="Substitute(" & K3& """"&H4&"""; """&I4&""")" -> Substitute(Substitute(A1; ".lo"; ""); "MNU_"; "-MNU_") | L4: value | M4: Substitute(Substitute(A1; ".lo"; ""); "MNU_"; "-MNU_")
B5: 1 | C5: ITM_1 | E5: ITM_CHS | F5: ITM_PLUS_MINUS
B6: 2 | C6: ITM_2 | E6: ITM_BACKSPACE | F6: ITM_BACKSPACE | G6: gShiftedAim -> | H6: ITM_SEMICOLON | I6: ITM_0 | J6: B2 | K6: ="Substitute(" & J6 & "; """&H6&"""; """ & I6 &""")" -> Substitute(B2; "ITM_SEMICOLON"; "ITM_0") | L6: formula | M6: =K6 -> Substitute(B2; "ITM_SEMICOLON"; "ITM_0")
B7: 2 | C7: ITM_2 | E7: ITM_UP1 | F7: ITM_UP1 | L7: value | M7: Substitute(B2; "ITM_SEMICOLON"; "ITM_0")
B8: 3 | C8: ITM_3 | E8: ITM_7 | F8: ITM_7
B9: 3 | C9: ITM_3 | E9: ITM_8 | F9: ITM_8 | H9: ITM_T_HOME | I9: ITM_UP1 | K9: =""""&H9&"""; """&I9&"""" -> "ITM_T_HOME"; "ITM_UP1" | L9: formula | M9: =_xlfn.TEXTJOIN("; ",TRUE,K9:K17) -> "ITM_T_HOME"; "ITM_UP1"; "ITM_T_END"; "ITM_DOWN1"; "DOCU_CHR_sub"; "ITM_DOWN_ARROW"; "DOCU_CHR_super"; "ITM_UP_ARROW"; "MNU_TAMALPHA"; "ITM_alpha"; "DOCU_CHR_caseFLIP"; "ITM_NULL"; "DOCU_CHR_numSET"; "ITM_NULL"; "DOCU_ITM_RADIX"; "ITM_PERIOD"; "ITM_SEMICOLON"; "ITM_0"
B10: 3√y | C10: ITM_CUBEROOT | E10: ITM_9 | F10: ITM_9 | H10: ITM_T_END | I10: ITM_DOWN1 | K10: =""""&H10&"""; """&I10&"""" -> "ITM_T_END"; "ITM_DOWN1" | L10: value | M10: "ITM_T_HOME"; "ITM_UP1"; "ITM_T_END"; "ITM_DOWN1"; "DOCU_CHR_sub"; "ITM_DOWN_ARROW"; "DOCU_CHR_super"; "ITM_UP_ARROW"; "DOCU_ITM_AIM_TAM"; "ITM_alpha"; "DOCU_CHR_caseFLIP"; "ITM_NULL"; "DOCU_CHR_numSET"; "ITM_NULL"; "DOCU_ITM_RADIX"; "ITM_PERIOD"; "ITM_SEMICOLON"; "ITM_0"; an33
B11: 3rty | C11: ITM_CUBEROOT | E11: ITM_DIV | F11: ITM_OBELUS | H11: DOCU_CHR_sub | I11: ITM_DOWN_ARROW | K11: =""""&H11&"""; """&I11&"""" -> "DOCU_CHR_sub"; "ITM_DOWN_ARROW"
B12: 4 | C12: ITM_4 | E12: ITM_DOWN1 | F12: ITM_DOWN1 | H12: DOCU_CHR_super | I12: ITM_UP_ARROW | K12: =""""&H12&"""; """&I12&"""" -> "DOCU_CHR_super"; "ITM_UP_ARROW"
B13: 4 | C13: ITM_4 | E13: ITM_4 | F13: ITM_4 | H13: MNU_TAMALPHA | I13: ITM_alpha | K13: =""""&H13&"""; """&I13&"""" -> "MNU_TAMALPHA"; "ITM_alpha"
B14: 5 | C14: ITM_5 | E14: ITM_5 | F14: ITM_5 | H14: DOCU_CHR_caseFLIP | I14: ITM_NULL | K14: =""""&H14&"""; """&I14&"""" -> "DOCU_CHR_caseFLIP"; "ITM_NULL"
B15: 5 | C15: ITM_5 | E15: ITM_6 | F15: ITM_6 | H15: DOCU_CHR_numSET | I15: ITM_NULL | K15: =""""&H15&"""; """&I15&"""" -> "DOCU_CHR_numSET"; "ITM_NULL"
B16: 6 | C16: ITM_6 | E16: ITM_MULT | F16: ITM_CROSS | H16: DOCU_ITM_RADIX | I16: ITM_PERIOD | K16: =""""&H16&"""; """&I16&"""" -> "DOCU_ITM_RADIX"; "ITM_PERIOD"
B17: 6 | C17: ITM_6 | E17: KEY_fg | F17: KEY_fg | H17: ITM_SEMICOLON | I17: ITM_0 | K17: =""""&H17&"""; """&I17&"""" -> "ITM_SEMICOLON"; "ITM_0"
B18: 7 | C18: ITM_7 | E18: ITM_1 | F18: ITM_1
B19: 7 | C19: ITM_7 | E19: ITM_2 | F19: ITM_2
B20: 8 | C20: ITM_8 | E20: ITM_3 | F20: ITM_3
B21: 8 | C21: ITM_8 | E21: ITM_SUB | F21: ITM_MINUS
B22: 9 | C22: ITM_9 | E22: ITM_EXIT1 | F22: ITM_EXIT1
B23: 9 | C23: ITM_9 | E23: ITM_0 | F23: ITM_0
B24: =" " | C24: ITM_NULL | E24: ITM_PERIOD | F24: ITM_PERIOD
E25: ITM_ADD | F25: ITM_PLUS
B26: [ TRG ] | C26: MNU_TRG_C47 | E26: ITM_HASH_JM | F26: ITM_NUMBER_SIGN
B27: f | C27: ITM_SHIFTf | E27: ITM_SHIFTf | F27: ITM_SHIFTf
B28: g | C28: ITM_SHIFTg | E28: ITM_SHIFTg | F28: ITM_SHIFTg
B29: _ | C29: ITM_UNDERSCORE | E29: DOCU_ITM_RADIX | F29: ITM_PERIOD
B30: - | C30: ITM_SUB
B31: - | C31: ITM_MINUS
B32: ->I | C32: ITM_RI
B33: ->P | C33: ITM_toPOL2
B34: ->R | C34: ITM_toREC2
B35: , | C35: ITM_COMMA
B36: ; | C36: ITM_SEMICOLON
B37: : | C37: ITM_COLON
B38: ？ | C38: ITM_QUESTION_MARK
B39: • | C39: DOCU_ITM_RADIX
B40: . | C40: ITM_PERIOD
...

Sheet Revisions
B3: 44925 | C3: COPIED D47 FROM DR5 TO THIS SHEET
C4: RENAMED JM4 SHEET TO DR5J
B8: 44795 | C8: Removed nonexistent layouts
C9: Inserted V47
C10: corrections
B12: 45170 | C12: Changes by Jaco:
B13: v | C13: Restored the last line of code in each section being different, in blue
B14: v | C14: Restored theAdded " " before each line of code to be compatible
B15: v | C15: In the target code, in the text editor, changed C47, C43, fAim back to "0" in the code, due to complex ideosyncrasies in the simulator labelling. Not fixing it now.
B16: xx | C16: (in the other layouts this has not been changed - it is todo)
B18: v | C18: Added WP43 adapted code for C47, to spreadsheet as text
B19: v | C19: Swapped DM42 CLX and UNDO back (added Sigma- to the Lookup table)
B21: v | C21: Errors on the V47: See the red marked cells in MAIN tab.
B22: v | C22: =MAIN!AJ198 | D22: Errors in V47. I forced this one NULL: | G22: =MAIN!AT198 -> ITM_NULL
B23: v | C23: =MAIN!AI199 -> COS
B24: v | C24: =MAIN!AI200 -> TAN
B27: 45171 | C27: Changes by Jaco
C28: Deleted Sheet1
C29: Added EXIT to E47 AIM primary
C30: Cleared "Checked OK" column as all is checked at this point
