Workbook

Sheet SOURCE
A1: -1
A3: 0 | B3: 0 | C3: / { itemToBeCoded | D3: NOPARAM | E3: "" | F3: "0000" | G3: 0 | H3: 0 | I3: CAT_NONE | J3: SLS_UNCHANGED | K3: US_UNCHANGED | L3: EIM_DISABLED | M3: PTP_NONE | N3: Filter | O3: // ITM_NULL | P3: ITM_NULL | S3: CAT<>NAME | T3: XEQM LOOKUP | U3: CATEGORY | W3: Function items using different letters
A4: =IF(B4=INT(B4),ROW(),"") | B4: =IF(AND(MID(C4,2,1)<>"/",MID(C4,1,1)="/"),INT(B3)+1,B3+0.01) -> 0.01 | T4: =IF(ISNA(VLOOKUP(P4,'NEW XEQM.c'!D:D,1,0)),"--",VLOOKUP(P4,'NEW XEQM.c'!D:G,3,0)) -> -- | W4: =SUBSTITUTE(IF(AND(T4="--",FIND("STD",E4),FIND("fn",C4)>0,FIND("ITM_",P4),I4="CAT_FNCT"),E4,""),"""","") -> #VALUE!
A5: =IF(B5=INT(B5),ROW(),"") | B5: =IF(AND(MID(C5,2,1)<>"/",MID(C5,1,1)="/"),INT(B4)+1,B4+0.01) -> 0.02 | C5: // Items from 1 to 127 are 1 byte OP codes | P5: =C5 -> // Items from 1 to 127 are 1 byte OP codes | T5: =IF(ISNA(VLOOKUP(P5,'NEW XEQM.c'!D:D,1,0)),"--",VLOOKUP(P5,'NEW XEQM.c'!D:G,3,0)) -> -- | W5: =SUBSTITUTE(IF(AND(T5="--",FIND("STD",E5),FIND("fn",C5)>0,FIND("ITM_",P5),I5="CAT_FNCT"),E5,""),"""","") -> #VALUE!
A6: =IF(B6=INT(B6),ROW(),"") -> 6 | B6: =IF(AND(MID(C6,2,1)<>"/",MID(C6,1,1)="/"),INT(B5)+1,B5+0.01) -> 1 | C6: / { fnNop | D6: TM_LABEL | E6: "LBL" | F6: "LBL" | G6: 0 | H6: 99 | I6: CAT_FNCT | J6: SLS_ENABLED | K6: US_ENABLED | L6: EIM_DISABLED | M6: PTP_DECLARE_LABEL | P6: ITM_LBL | S6: =IF(E6=F6,"","NOT EQUAL") | T6: =IF(ISNA(VLOOKUP(P6,'NEW XEQM.c'!D:D,1,0)),"--",VLOOKUP(P6,'NEW XEQM.c'!D:G,3,0)) -> -- | W6: =SUBSTITUTE(IF(AND(T6="--",FIND("STD",E6),FIND("fn",C6)>0,FIND("ITM_",P6),I6="CAT_FNCT"),E6,""),"""","") -> #VALUE!
A7: =IF(B7=INT(B7),ROW(),"") -> 7 | B7: =IF(AND(MID(C7,2,1)<>"/",MID(C7,1,1)="/"),INT(B6)+1,B6+0.01) -> 2 | C7: / { fnGoto | D7: TM_LABEL | E7: "GTO" | F7: "GTO" | G7: 0 | H7: 99 | I7: CAT_FNCT | J7: SLS_ENABLED | K7: US_ENABLED | L7: EIM_DISABLED | M7: PTP_LABEL | P7: ITM_GTO | S7: =IF(E7=F7,"","NOT EQUAL") | T7: =IF(ISNA(VLOOKUP(P7,'NEW XEQM.c'!D:D,1,0)),"--",VLOOKUP(P7,'NEW XEQM.c'!D:G,3,0)) -> -- | W7: =SUBSTITUTE(IF(AND(T7="--",FIND("STD",E7),FIND("fn",C7)>0,FIND("ITM_",P7),I7="CAT_FNCT"),E7,""),"""","") -> #VALUE!
A8: =IF(B8=INT(B8),ROW(),"") -> 8 | B8: =IF(AND(MID(C8,2,1)<>"/",MID(C8,1,1)="/"),INT(B7)+1,B7+0.01) -> 3 | C8: / { fnExecute | D8: TM_LABEL | E8: "XEQ" | F8: "XEQ" | G8: 0 | H8: 99 | I8: CAT_FNCT | J8: SLS_ENABLED | K8: US_ENABLED | L8: EIM_DISABLED | M8: PTP_LABEL | P8: ITM_XEQ | S8: =IF(E8=F8,"","NOT EQUAL") | T8: =IF(ISNA(VLOOKUP(P8,'NEW XEQM.c'!D:D,1,0)),"--",VLOOKUP(P8,'NEW XEQM.c'!D:G,3,0)) -> -- | W8: =SUBSTITUTE(IF(AND(T8="--",FIND("STD",E8),FIND("fn",C8)>0,FIND("ITM_",P8),I8="CAT_FNCT"),E8,""),"""","") -> #VALUE!
A9: =IF(B9=INT(B9),ROW(),"") -> 9 | B9: =IF(AND(MID(C9,2,1)<>"/",MID(C9,1,1)="/"),INT(B8)+1,B8+0.01) -> 4 | C9: / { fnReturn | D9: 0 | E9: "RTN" | F9: "RTN" | G9: 0 | H9: 0 | I9: CAT_FNCT | J9: SLS_UNCHANGED | K9: US_UNCHANGED | L9: EIM_DISABLED | M9: PTP_NONE | P9: ITM_RTN | S9: =IF(E9=F9,"","NOT EQUAL") | T9: =IF(ISNA(VLOOKUP(P9,'NEW XEQM.c'!D:D,1,0)),"--",VLOOKUP(P9,'NEW XEQM.c'!D:G,3,0)) -> -- | W9: =SUBSTITUTE(IF(AND(T9="--",FIND("STD",E9),FIND("fn",C9)>0,FIND("ITM_",P9),I9="CAT_FNCT"),E9,""),"""","") -> #VALUE!
A10: =IF(B10=INT(B10),ROW(),"") -> 10 | B10: =IF(AND(MID(C10,2,1)<>"/",MID(C10,1,1)="/"),INT(B9)+1,B9+0.01) -> 5 | C10: / { fnIse | D10: TM_REGISTER | E10: "ISE" | F10: "ISE" | G10: 0 | H10: 99 | I10: CAT_FNCT | J10: SLS_ENABLED | K10: US_ENABLED | L10: EIM_DISABLED | M10: PTP_REGISTER | P10: ITM_ISE | S10: =IF(E10=F10,"","NOT EQUAL") | T10: =IF(ISNA(VLOOKUP(P10,'NEW XEQM.c'!D:D,1,0)),"--",VLOOKUP(P10,'NEW XEQM.c'!D:G,3,0)) -> -- | W10: =SUBSTITUTE(IF(AND(T10="--",FIND("STD",E10),FIND("fn",C10)>0,FIND("ITM_",P10),I10="CAT_FNCT"),E10,""),"""","") -> #VALUE!
A11: =IF(B11=INT(B11),ROW(),"") -> 11 | B11: =IF(AND(MID(C11,2,1)<>"/",MID(C11,1,1)="/"),INT(B10)+1,B10+0.01) -> 6 | C11: / { fnIsg | D11: TM_REGISTER | E11: "ISG" | F11: "ISG" | G11: 0 | H11: 99 | I11: CAT_FNCT | J11: SLS_ENABLED | K11: US_ENABLED | L11: EIM_DISABLED | M11: PTP_REGISTER | P11: ITM_ISG | S11: =IF(E11=F11,"","NOT EQUAL") | T11: =IF(ISNA(VLOOKUP(P11,'NEW XEQM.c'!D:D,1,0)),"--",VLOOKUP(P11,'NEW XEQM.c'!D:G,3,0)) -> -- | W11: =SUBSTITUTE(IF(AND(T11="--",FIND("STD",E11),FIND("fn",C11)>0,FIND("ITM_",P11),I11="CAT_FNCT"),E11,""),"""","") -> #VALUE!
A12: =IF(B12=INT(B12),ROW(),"") -> 12 | B12: =IF(AND(MID(C12,2,1)<>"/",MID(C12,1,1)="/"),INT(B11)+1,B11+0.01) -> 7 | C12: / { fnIsz | D12: TM_REGISTER | E12: "ISZ" | F12: "ISZ" | G12: 0 | H12: 99 | I12: CAT_FNCT | J12: SLS_ENABLED | K12: US_ENABLED | L12: EIM_DISABLED | M12: PTP_REGISTER | P12: ITM_ISZ | S12: =IF(E12=F12,"","NOT EQUAL") | T12: =IF(ISNA(VLOOKUP(P12,'NEW XEQM.c'!D:D,1,0)),"--",VLOOKUP(P12,'NEW XEQM.c'!D:G,3,0)) -> -- | W12: =SUBSTITUTE(IF(AND(T12="--",FIND("STD",E12),FIND("fn",C12)>0,FIND("ITM_",P12),I12="CAT_FNCT"),E12,""),"""","") -> #VALUE!
A13: =IF(B13=INT(B13),ROW(),"") -> 13 | B13: =IF(AND(MID(C13,2,1)<>"/",MID(C13,1,1)="/"),INT(B12)+1,B12+0.01) -> 8 | C13: / { fnDse | D13: TM_REGISTER | E13: "DSE" | F13: "DSE" | G13: 0 | H13: 99 | I13: CAT_FNCT | J13: SLS_ENABLED | K13: US_ENABLED | L13: EIM_DISABLED | M13: PTP_REGISTER | P13: ITM_DSE | S13: =IF(E13=F13,"","NOT EQUAL") | T13: =IF(ISNA(VLOOKUP(P13,'NEW XEQM.c'!D:D,1,0)),"--",VLOOKUP(P13,'NEW XEQM.c'!D:G,3,0)) -> -- | W13: =SUBSTITUTE(IF(AND(T13="--",FIND("STD",E13),FIND("fn",C13)>0,FIND("ITM_",P13),I13="CAT_FNCT"),E13,""),"""","") -> #VALUE!
A14: =IF(B14=INT(B14),ROW(),"") -> 14 | B14: =IF(AND(MID(C14,2,1)<>"/",MID(C14,1,1)="/"),INT(B13)+1,B13+0.01) -> 9 | C14: / { fnDsl | D14: TM_REGISTER | E14: "DSL" | F14: "DSL" | G14: 0 | H14: 99 | I14: CAT_FNCT | J14: SLS_ENABLED | K14: US_ENABLED | L14: EIM_DISABLED | M14: PTP_REGISTER | P14: ITM_DSL | S14: =IF(E14=F14,"","NOT EQUAL") | T14: =IF(ISNA(VLOOKUP(P14,'NEW XEQM.c'!D:D,1,0)),"--",VLOOKUP(P14,'NEW XEQM.c'!D:G,3,0)) -> -- | W14: =SUBSTITUTE(IF(AND(T14="--",FIND("STD",E14),FIND("fn",C14)>0,FIND("ITM_",P14),I14="CAT_FNCT"),E14,""),"""","") -> #VALUE!
A15: =IF(B15=INT(B15),ROW(),"") -> 15 | B15: =IF(AND(MID(C15,2,1)<>"/",MID(C15,1,1)="/"),INT(B14)+1,B14+0.01) -> 10 | C15: / { fnDsz | D15: TM_REGISTER | E15: "DSZ" | F15: "DSZ" | G15: 0 | H15: 99 | I15: CAT_FNCT | J15: SLS_ENABLED | K15: US_ENABLED | L15: EIM_DISABLED | M15: PTP_REGISTER | P15: ITM_DSZ | S15: =IF(E15=F15,"","NOT EQUAL") | T15: =IF(ISNA(VLOOKUP(P15,'NEW XEQM.c'!D:D,1,0)),"--",VLOOKUP(P15,'NEW XEQM.c'!D:G,3,0)) -> -- | W15: =SUBSTITUTE(IF(AND(T15="--",FIND("STD",E15),FIND("fn",C15)>0,FIND("ITM_",P15),I15="CAT_FNCT"),E15,""),"""","") -> #VALUE!
A16: =IF(B16=INT(B16),ROW(),"") -> 16 | B16: =IF(AND(MID(C16,2,1)<>"/",MID(C16,1,1)="/"),INT(B15)+1,B15+0.01) -> 11 | C16: / { fnXEqualsTo | D16: TM_CMP | E16: "x= ?" | F16: "x= ?" | G16: 0 | H16: 99 | I16: CAT_FNCT | J16: SLS_ENABLED | K16: US_UNCHANGED | L16: EIM_DISABLED | M16: PTP_COMPARE | P16: ITM_XEQU | S16: =IF(E16=F16,"","NOT EQUAL") | T16: =IF(ISNA(VLOOKUP(P16,'NEW XEQM.c'!D:D,1,0)),"--",VLOOKUP(P16,'NEW XEQM.c'!D:G,3,0)) -> -- | W16: =SUBSTITUTE(IF(AND(T16="--",FIND("STD",E16),FIND("fn",C16)>0,FIND("ITM_",P16),I16="CAT_FNCT"),E16,""),"""","") -> #VALUE!
A17: =IF(B17=INT(B17),ROW(),"") -> 17 | B17: =IF(AND(MID(C17,2,1)<>"/",MID(C17,1,1)="/"),INT(B16)+1,B16+0.01) -> 12 | C17: / { fnXNotEqual | D17: TM_CMP | E17: "x" STD_NOT_EQUAL " ?" | F17: "x" STD_NOT_EQUAL " ?" | G17: 0 | H17: 99 | I17: CAT_FNCT | J17: SLS_ENABLED | K17: US_UNCHANGED | L17: EIM_DISABLED | M17: PTP_COMPARE | P17: ITM_XNE | S17: =IF(E17=F17,"","NOT EQUAL") | T17: =IF(ISNA(VLOOKUP(P17,'NEW XEQM.c'!D:D,1,0)),"--",VLOOKUP(P17,'NEW XEQM.c'!D:G,3,0)) -> -- | W17: =SUBSTITUTE(IF(AND(T17="--",FIND("STD",E17),FIND("fn",C17)>0,FIND("ITM_",P17),I17="CAT_FNCT"),E17,""),"""","") -> x STD_NOT_EQUAL ?
... A30: =IF(B30=INT(B30),ROW(),"") -> 30 | B30: =IF(AND(MID(C30,2,1)<>"/",MID(C30,1,1)="/"),INT(B29)+1,B29+0.01) -> 25 | C30: / { fnCheckInteger | D30: CHECK_INTEGER | E30: "INT?" | F30: "INT?" | G30: 0 | H30: 0 | I30: CAT_FNCT | J30: SLS_ENABLED | K30: US_UNCHANGED | L30: EIM_DISABLED | M30: PTP_NONE | P30: ITM_INT | S30: =IF(E30=F30,"","NOT EQUAL") | T30: =IF(ISNA(VLOOKUP(P30,'NEW XEQM.c'!D:D,1,0)),"--",VLOOKUP(P30,'NEW XEQM.c'!D:G,3,0)) -> -- | W30: =SUBSTITUTE(IF(AND(T30="--",FIND("STD",E30),FIND("fn",C30)>0,FIND("ITM_",P30),I30="CAT_FNCT"),E30,""),"""","") -> #VALUE!
A31: =IF(B31=INT(B31),ROW(),"") -> 31 | B31: =IF(AND(MID(C31,2,1)<>"/",MID(C31,1,1)="/"),INT(B30)+1,B30+0.01) -> 26 | C31: / { fnCheckValue | D31: CHECK_VALUE_COMPLEX | E31: "CPX?" | F31: "CPX?" | G31: 0 | H31: 0 | I31: CAT_FNCT | J31: SLS_ENABLED | K31: US_UNCHANGED | L31: EIM_DISABLED | M31: PTP_NONE | P31: ITM_CPX | S31: =IF(E31=F31,"","NOT EQUAL") | T31: =IF(ISNA(VLOOKUP(P31,'NEW XEQM.c'!D:D,1,0)),"--",VLOOKUP(P31,'NEW XEQM.c'!D:G,3,0)) -> -- | U31: Complex | W31: =SUBSTITUTE(IF(AND(T31="--",FIND("STD",E31),FIND("fn",C31)>0,FIND("ITM_",P31),I31="CAT_FNCT"),E31,""),"""","") -> #VALUE!
A32: =IF(B32=INT(B32),ROW(),"") -> 32 | B32: =IF(AND(MID(C32,2,1)<>"/",MID(C32,1,1)="/"),INT(B31)+1,B31+0.01) -> 27 | C32: / { fnCheckValue | D32: CHECK_VALUE_MATRIX | E32: "MATR?" | F32: "MATR?" | G32: 0 | H32: 0 | I32: CAT_FNCT | J32: SLS_ENABLED | K32: US_UNCHANGED | L32: EIM_DISABLED | M32: PTP_NONE | P32: ITM_MATR | S32: =IF(E32=F32,"","NOT EQUAL") | T32: =IF(ISNA(VLOOKUP(P32,'NEW XEQM.c'!D:D,1,0)),"--",VLOOKUP(P32,'NEW XEQM.c'!D:G,3,0)) -> -- | W32: =SUBSTITUTE(IF(AND(T32="--",FIND("STD",E32),FIND("fn",C32)>0,FIND("ITM_",P32),I32="CAT_FNCT"),E32,""),"""","") -> #VALUE!
A33: =IF(B33=INT(B33),ROW(),"") -> 33 | B33: =IF(AND(MID(C33,2,1)<>"/",MID(C33,1,1)="/"),INT(B32)+1,B32+0.01) -> 28 | C33: / { fnCheckValue | D33: CHECK_VALUE_NAN | E33: "NaN?" | F33: "NaN?" | G33: 0 | H33: 0 | I33: CAT_FNCT | J33: SLS_ENABLED | K33: US_UNCHANGED | L33: EIM_DISABLED | M33: PTP_NONE | P33: ITM_NAN | S33: =IF(E33=F33,"","NOT EQUAL") | T33: =IF(ISNA(VLOOKUP(P33,'NEW XEQM.c'!D:D,1,0)),"--",VLOOKUP(P33,'NEW XEQM.c'!D:G,3,0)) -> -- | W33: =SUBSTITUTE(IF(AND(T33="--",FIND("STD",E33),FIND("fn",C33)>0,FIND("ITM_",P33),I33="CAT_FNCT"),E33,""),"""","") -> #VALUE!
A34: =IF(B34=INT(B34),ROW(),"") -> 34 | B34: =IF(AND(MID(C34,2,1)<>"/",MID(C34,1,1)="/"),INT(B33)+1,B33+0.01) -> 29 | C34: / { fnCheckValue | D34: CHECK_VALUE_REAL | E34: "REAL?" | F34: "REAL?" | G34: 0 | H34: 0 | I34: CAT_FNCT | J34: SLS_ENABLED | K34: US_UNCHANGED | L34: EIM_DISABLED | M34: PTP_NONE | P34: ITM_REAL | S34: =IF(E34=F34,"","NOT EQUAL") | T34: =IF(ISNA(VLOOKUP(P34,'NEW XEQM.c'!D:D,1,0)),"--",VLOOKUP(P34,'NEW XEQM.c'!D:G,3,0)) -> -- | U34: INFO | W34: =SUBSTITUTE(IF(AND(T34="--",FIND("STD",E34),FIND("fn",C34)>0,FIND("ITM_",P34),I34="CAT_FNCT"),E34,""),"""","") -> #VALUE!
A35: =IF(B35=INT(B35),ROW(),"") -> 35 | B35: =IF(AND(MID(C35,2,1)<>"/",MID(C35,1,1)="/"),INT(B34)+1,B34+0.01) -> 30 | C35: / { fnCheckValue | D35: CHECK_VALUE_SPECIAL | E35: "SPEC?" | F35: "SPEC?" | G35: 0 | H35: 0 | I35: CAT_FNCT | J35: SLS_ENABLED | K35: US_UNCHANGED | L35: EIM_DISABLED | M35: PTP_NONE | P35: ITM_SPEC | S35: =IF(E35=F35,"","NOT EQUAL") | T35: =IF(ISNA(VLOOKUP(P35,'NEW XEQM.c'!D:D,1,0)),"--",VLOOKUP(P35,'NEW XEQM.c'!D:G,3,0)) -> -- | W35: =SUBSTITUTE(IF(AND(T35="--",FIND("STD",E35),FIND("fn",C35)>0,FIND("ITM_",P35),I35="CAT_FNCT"),E35,""),"""","") -> #VALUE!
A36: =IF(B36=INT(B36),ROW(),"") -> 36 | B36: =IF(AND(MID(C36,2,1)<>"/",MID(C36,1,1)="/"),INT(B35)+1,B35+0.01) -> 31 | C36: / { fnIsString | D36: NOPARAM | E36: "STRI?" | F36: "STRI?" | G36: 0 | H36: 0 | I36: CAT_FNCT | J36: SLS_ENABLED | K36: US_UNCHANGED | L36: EIM_DISABLED | M36: PTP_NONE | P36: ITM_STRI | S36: =IF(E36=F36,"","NOT EQUAL") | T36: =IF(ISNA(VLOOKUP(P36,'NEW XEQM.c'!D:D,1,0)),"--",VLOOKUP(P36,'NEW XEQM.c'!D:G,3,0)) -> -- | W36: =SUBSTITUTE(IF(AND(T36="--",FIND("STD",E36),FIND("fn",C36)>0,FIND("ITM_",P36),I36="CAT_FNCT"),E36,""),"""","") -> #VALUE!
A37: =IF(B37=INT(B37),ROW(),"") -> 37 | B37: =IF(AND(MID(C37,2,1)<>"/",MID(C37,1,1)="/"),INT(B36)+1,B36+0.01) -> 32 | C37: / { fnCheckValue | D37: CHECK_VALUE_INFINITY | E37: STD_PLUS_MINUS STD_INFINITY "?" | F37: STD_PLUS_MINUS STD_INFINITY "?" | G37: 0 | H37: 0 | I37: CAT_FNCT | J37: SLS_ENABLED | K37: US_ENABLED | L37: EIM_DISABLED | M37: PTP_NONE | P37: ITM_PMINFINITY | S37: =IF(E37=F37,"","NOT EQUAL") | T37: =IF(ISNA(VLOOKUP(P37,'NEW XEQM.c'!D:D,1,0)),"--",VLOOKUP(P37,'NEW XEQM.c'!D:G,3,0)) -> -- | W37: =SUBSTITUTE(IF(AND(T37="--",FIND("STD",E37),FIND("fn",C37)>0,FIND("ITM_",P37),I37="CAT_FNCT"),E37,""),"""","") -> STD_PLUS_MINUS STD_INFINITY ?
A38: =IF(B38=INT(B38),ROW(),"") -> 38 | B38: =IF(AND(MID(C38,2,1)<>"/",MID(C38,1,1)="/"),INT(B37)+1,B37+0.01) -> 33 | C38: / { fnIsPrime | D38: NOPARAM | E38: "PRIME?" | F38: "PRIME?" | G38: 0 | H38: 0 | I38: CAT_FNCT | J38: SLS_ENABLED | K38: US_UNCHANGED | L38: EIM_DISABLED | M38: PTP_NONE | P38: ITM_PRIME | S38: =IF(E38=F38,"","NOT EQUAL") | T38: =IF(ISNA(VLOOKUP(P38,'NEW XEQM.c'!D:D,1,0)),"--",VLOOKUP(P38,'NEW XEQM.c'!D:G,3,0)) -> PRIME? | U38: Math | W38: =SUBSTITUTE(IF(AND(T38="--",FIND("STD",E38),FIND("fn",C38)>0,FIND("ITM_",P38),I38="CAT_FNCT"),E38,""),"""","") -> #VALUE!
A39: =IF(B39=INT(B39),ROW(),"") -> 39 | B39: =IF(AND(MID(C39,2,1)<>"/",MID(C39,1,1)="/"),INT(B38)+1,B38+0.01) -> 34 | C39: / { fnIsTopRoutine | D39: NOPARAM | E39: "TOP?" | F39: "TOP?" | G39: 0 | H39: 0 | I39: CAT_FNCT | J39: SLS_UNCHANGED | K39: US_UNCHANGED | L39: EIM_DISABLED | M39: PTP_NONE | P39: ITM_TOP | S39: =IF(E39=F39,"","NOT EQUAL") | T39: =IF(ISNA(VLOOKUP(P39,'NEW XEQM.c'!D:D,1,0)),"--",VLOOKUP(P39,'NEW XEQM.c'!D:G,3,0)) -> -- | W39: =SUBSTITUTE(IF(AND(T39="--",FIND("STD",E39),FIND("fn",C39)>0,FIND("ITM_",P39),I39="CAT_FNCT"),E39,""),"""","") -> #VALUE!
A40: =IF(B40=INT(B40),ROW(),"") -> 40 | B40: =IF(AND(MID(C40,2,1)<>"/",MID(C40,1,1)="/"),INT(B39)+1,B39+0.01) -> 35 | C40: / { fnKeyEnter | D40: NOPARAM/*#JM#*/ | E40: "ENTER" STD_UP_ARROW | F40: "ENTER" STD_UP_ARROW | G40: 0 | H40: 0 | I40: CAT_FNCT | J40: SLS_UNCHANGED | K40: US_ENABLED | L40: EIM_DISABLED | M40: PTP_NONE | P40: ITM_ENTER | S40: =IF(E40=F40,"","NOT EQUAL") | T40: =IF(ISNA(VLOOKUP(P40,'NEW XEQM.c'!D:D,1,0)),"--",VLOOKUP(P40,'NEW XEQM.c'!D:G,3,0)) -> ENTER | U40: STACK | W40: =SUBSTITUTE(IF(AND(T40="--",FIND("STD",E40),FIND("fn",C40)>0,FIND("ITM_",P40),I40="CAT_FNCT"),E40,""),"""","")
A41: =IF(B41=INT(B41),ROW(),"") -> 41 | B41: =IF(AND(MID(C41,2,1)<>"/",MID(C41,1,1)="/"),INT(B40)+1,B40+0.01) -> 36 | C41: / { fnSwapXY | D41: NOPARAM | E41: "x" STD_RIGHT_OVER_LEFT_ARROW "y" | F41: "x" STD_RIGHT_OVER_LEFT_ARROW "y" | G41: 0 | H41: 0 | I41: CAT_FNCT | J41: SLS_ENABLED | K41: US_ENABL_XEQ | L41: EIM_DISABLED | M41: PTP_NONE | P41: ITM_XexY | S41: =IF(E41=F41,"","NOT EQUAL") | T41: =IF(ISNA(VLOOKUP(P41,'NEW XEQM.c'!D:D,1,0)),"--",VLOOKUP(P41,'NEW XEQM.c'!D:G,3,0)) -> X<>Y | U41: STACK | W41: =SUBSTITUTE(IF(AND(T41="--",FIND("STD",E41),FIND("fn",C41)>0,FIND("ITM_",P41),I41="CAT_FNCT"),E41,""),"""","")
A42: =IF(B42=INT(B42),ROW(),"") -> 42 | B42: =IF(AND(MID(C42,2,1)<>"/",MID(C42,1,1)="/"),INT(B41)+1,B41+0.01) -> 37 | C42: / { fnDrop | D42: NOPARAM | E42: "DROPx" | F42: "DROPx" | G42: 0 | H42: 0 | I42: CAT_FNCT | J42: SLS_ENABLED | K42: US_ENABLED | L42: EIM_DISABLED | M42: PTP_NONE | P42: ITM_DROP | S42: =IF(E42=F42,"","NOT EQUAL") | T42: =IF(ISNA(VLOOKUP(P42,'NEW XEQM.c'!D:D,1,0)),"--",VLOOKUP(P42,'NEW XEQM.c'!D:G,3,0)) -> DROP | U42: STACK | W42: =SUBSTITUTE(IF(AND(T42="--",FIND("STD",E42),FIND("fn",C42)>0,FIND("ITM_",P42),I42="CAT_FNCT"),E42,""),"""","") -> #VALUE!
A43: =IF(B43=INT(B43),ROW(),"") -> 43 | B43: =IF(AND(MID(C43,2,1)<>"/",MID(C43,1,1)="/"),INT(B42)+1,B42+0.01) -> 38 | C43: / { fnPause | D43: TM_VALUE | E43: "PAUSE" | F43: "PAUSE" | G43: 0 | H43: 99 | I43: CAT_FNCT | J43: SLS_UNCHANGED | K43: US_UNCHANGED | L43: EIM_DISABLED | M43: PTP_NUMBER_8 | P43: ITM_PAUSE | S43: =IF(E43=F43,"","NOT EQUAL") | T43: =IF(ISNA(VLOOKUP(P43,'NEW XEQM.c'!D:D,1,0)),"--",VLOOKUP(P43,'NEW XEQM.c'!D:G,3,0)) -> -- | W43: =SUBSTITUTE(IF(AND(T43="--",FIND("STD",E43),FIND("fn",C43)>0,FIND("ITM_",P43),I43="CAT_FNCT"),E43,""),"""","") -> #VALUE!
A44: =IF(B44=INT(B44),ROW(),"") -> 44 | B44: =IF(AND(MID(C44,2,1)<>"/",MID(C44,1,1)="/"),INT(B43)+1,B43+0.01) -> 39 | C44: / { fnRollUp | D44: NOPARAM | E44: "R" STD_UP_ARROW | F44: "R" STD_UP_ARROW | G44: 0 | H44: 0 | I44: CAT_FNCT | J44: SLS_ENABLED | K44: US_ENABL_XEQ | L44: EIM_DISABLED | M44: PTP_NONE | P44: ITM_Rup | S44: =IF(E44=F44,"","NOT EQUAL") | T44: =IF(ISNA(VLOOKUP(P44,'NEW XEQM.c'!D:D,1,0)),"--",VLOOKUP(P44,'NEW XEQM.c'!D:G,3,0)) -> -- | W44: =SUBSTITUTE(IF(AND(T44="--",FIND("STD",E44),FIND("fn",C44)>0,FIND("ITM_",P44),I44="CAT_FNCT"),E44,""),"""","") -> R STD_UP_ARROW
A45: =IF(B45=INT(B45),ROW(),"") -> 45 | B45: =IF(AND(MID(C45,2,1)<>"/",MID(C45,1,1)="/"),INT(B44)+1,B44+0.01) -> 40 | C45: / { fnRollDown | D45: NOPARAM | E45: "R" STD_DOWN_ARROW | F45: "R" STD_DOWN_ARROW | G45: 0 | H45: 0 | I45: CAT_FNCT | J45: SLS_ENABLED | K45: US_ENABL_XEQ | L45: EIM_DISABLED | M45: PTP_NONE | P45: ITM_Rdown | S45: =IF(E45=F45,"","NOT EQUAL") | T45: =IF(ISNA(VLOOKUP(P45,'NEW XEQM.c'!D:D,1,0)),"--",VLOOKUP(P45,'NEW XEQM.c'!D:G,3,0)) -> -- | W45: =SUBSTITUTE(IF(AND(T45="--",FIND("STD",E45),FIND("fn",C45)>0,FIND("ITM_",P45),I45="CAT_FNCT"),E45,""),"""","") -> R STD_DOWN_ARROW
A46: =IF(B46=INT(B46),ROW(),"") -> 46 | B46: =IF(AND(MID(C46,2,1)<>"/",MID(C46,1,1)="/"),INT(B45)+1,B45+0.01) -> 41 | C46: / { fnClX | D46: NOPARAM | E46: "CLX" | F46: "CLX" | G46: 0 | H46: 0 | I46: CAT_FNCT | J46: SLS_DISABLED | K46: US_ENABL_XEQ | L46: EIM_DISABLED | M46: PTP_NONE | P46: ITM_CLX | S46: =IF(E46=F46,"","NOT EQUAL") | T46: =IF(ISNA(VLOOKUP(P46,'NEW XEQM.c'!D:D,1,0)),"--",VLOOKUP(P46,'NEW XEQM.c'!D:G,3,0)) -> CLX | U46: Clear | W46: =SUBSTITUTE(IF(AND(T46="--",FIND("STD",E46),FIND("fn",C46)>0,FIND("ITM_",P46),I46="CAT_FNCT"),E46,""),"""","") -> #VALUE!
A47: =IF(B47=INT(B47),ROW(),"") -> 47 | B47: =IF(AND(MID(C47,2,1)<>"/",MID(C47,1,1)="/"),INT(B46)+1,B46+0.01) -> 42 | C47: / { fnFillStack | D47: NOPARAM | E47: "FILL" | F47: "FILL" | G47: 0 | H47: 0 | I47: CAT_FNCT | J47: SLS_ENABLED | K47: US_ENABLED | L47: EIM_DISABLED | M47: PTP_NONE | P47: ITM_FILL | S47: =IF(E47=F47,"","NOT EQUAL") | T47: =IF(ISNA(VLOOKUP(P47,'NEW XEQM.c'!D:D,1,0)),"--",VLOOKUP(P47,'NEW XEQM.c'!D:G,3,0)) -> FILL | U47: STACK | W47: =SUBSTITUTE(IF(AND(T47="--",FIND("STD",E47),FIND("fn",C47)>0,FIND("ITM_",P47),I47="CAT_FNCT"),E47,""),"""","") -> #VALUE!
A48: =IF(B48=INT(B48),ROW(),"") -> 48 | B48: =IF(AND(MID(C48,2,1)<>"/",MID(C48,1,1)="/"),INT(B47)+1,B47+0.01) -> 43 | C48: / { fnInput | D48: TM_REGISTER | E48: "INPUT" | F48: "INPUT" | G48: 0 | H48: 99 | I48: CAT_FNCT | J48: SLS_ENABLED | K48: US_CANCEL | L48: EIM_DISABLED | M48: PTP_REGISTER | P48: ITM_INPUT | S48: =IF(E48=F48,"","NOT EQUAL") | T48: =IF(ISNA(VLOOKUP(P48,'NEW XEQM.c'!D:D,1,0)),"--",VLOOKUP(P48,'NEW XEQM.c'!D:G,3,0)) -> -- | W48: =SUBSTITUTE(IF(AND(T48="--",FIND("STD",E48),FIND("fn",C48)>0,FIND("ITM_",P48),I48="CAT_FNCT"),E48,""),"""","") -> #VALUE!
A49: =IF(B49=INT(B49),ROW(),"") -> 49 | B49: =IF(AND(MID(C49,2,1)<>"/",MID(C49,1,1)="/"),INT(B48)+1,B48+0.01) -> 44 | C49: / { fnStore | D49: TM_STORCL | E49: "STO" | F49: "STO" | G49: 0 | H49: 99 | I49: CAT_FNCT | J49: SLS_ENABLED | K49: US_ENABLED | L49: EIM_DISABLED | M49: PTP_REGISTER | P49: ITM_STO | S49: =IF(E49=F49,"","NOT EQUAL") | T49: =IF(ISNA(VLOOKUP(P49,'NEW XEQM.c'!D:D,1,0)),"--",VLOOKUP(P49,'NEW XEQM.c'!D:G,3,0)) -> STO | U49: STACK | W49: =SUBSTITUTE(IF(AND(T49="--",FIND("STD",E49),FIND("fn",C49)>0,FIND("ITM_",P49),I49="CAT_FNCT"),E49,""),"""","") -> #VALUE!
A50: =IF(B50=INT(B50),ROW(),"") -> 50 | B50: =IF(AND(MID(C50,2,1)<>"/",MID(C50,1,1)="/"),INT(B49)+1,B49+0.01) -> 45 | C50: / { fnStoreAdd | D50: NOPARAM | E50: "STO+" | F50: "STO+" | G50: 0 | H50: 99 | I50: CAT_FNCT | J50: SLS_ENABLED | K50: US_ENABLED | L50: EIM_DISABLED | M50: PTP_REGISTER | P50: ITM_STOADD | S50: =IF(E50=F50,"","NOT EQUAL") | T50: =IF(ISNA(VLOOKUP(P50,'NEW XEQM.c'!D:D,1,0)),"--",VLOOKUP(P50,'NEW XEQM.c'!D:G,3,0)) -> -- | U50: STACK | W50: =SUBSTITUTE(IF(AND(T50="--",FIND("STD",E50),FIND("fn",C50)>0,FIND("ITM_",P50),I50="CAT_FNCT"),E50,""),"""","") -> #VALUE!
A51: =IF(B51=INT(B51),ROW(),"") -> 51 | B51: =IF(AND(MID(C51,2,1)<>"/",MID(C51,1,1)="/"),INT(B50)+1,B50+0.01) -> 46 | C51: / { fnStoreSub | D51: NOPARAM | E51: "STO-" | F51: "STO-" | G51: 0 | H51: 99 | I51: CAT_FNCT | J51: SLS_ENABLED | K51: US_ENABLED | L51: EIM_DISABLED | M51: PTP_REGISTER | P51: ITM_STOSUB | S51: =IF(E51=F51,"","NOT EQUAL") | T51: =IF(ISNA(VLOOKUP(P51,'NEW XEQM.c'!D:D,1,0)),"--",VLOOKUP(P51,'NEW XEQM.c'!D:G,3,0)) -> -- | U51: STACK | W51: =SUBSTITUTE(IF(AND(T51="--",FIND("STD",E51),FIND("fn",C51)>0,FIND("ITM_",P51),I51="CAT_FNCT"),E51,""),"""","") -> #VALUE!
A52: =IF(B52=INT(B52),ROW(),"") -> 52 | B52: =IF(AND(MID(C52,2,1)<>"/",MID(C52,1,1)="/"),INT(B51)+1,B51+0.01) -> 47 | C52: / { fnStoreMult | D52: NOPARAM | E52: "STO" STD_CROSS | F52: "STO" STD_CROSS | G52: 0 | H52: 99 | I52: CAT_FNCT | J52: SLS_ENABLED | K52: US_ENABLED | L52: EIM_DISABLED | M52: PTP_REGISTER | P52: ITM_STOMULT | S52: =IF(E52=F52,"","NOT EQUAL") | T52: =IF(ISNA(VLOOKUP(P52,'NEW XEQM.c'!D:D,1,0)),"--",VLOOKUP(P52,'NEW XEQM.c'!D:G,3,0)) -> -- | U52: STACK | W52: =SUBSTITUTE(IF(AND(T52="--",FIND("STD",E52),FIND("fn",C52)>0,FIND("ITM_",P52),I52="CAT_FNCT"),E52,""),"""","") -> STO STD_CROSS
A53: =IF(B53=INT(B53),ROW(),"") -> 53 | B53: =IF(AND(MID(C53,2,1)<>"/",MID(C53,1,1)="/"),INT(B52)+1,B52+0.01) -> 48 | C53: / { fnStoreDiv | D53: NOPARAM | E53: "STO/" | F53: "STO/" | G53: 0 | H53: 99 | I53: CAT_FNCT | J53: SLS_ENABLED | K53: US_ENABLED | L53: EIM_DISABLED | M53: PTP_REGISTER | P53: ITM_STODIV | S53: =IF(E53=F53,"","NOT EQUAL") | T53: =IF(ISNA(VLOOKUP(P53,'NEW XEQM.c'!D:D,1,0)),"--",VLOOKUP(P53,'NEW XEQM.c'!D:G,3,0)) -> -- | U53: STACK | W53: =SUBSTITUTE(IF(AND(T53="--",FIND("STD",E53),FIND("fn",C53)>0,FIND("ITM_",P53),I53="CAT_FNCT"),E53,""),"""","") -> #VALUE!
...

Sheet EXPORT.C
A3: =IF(AND(OR(SOURCE!A3="",ISBLANK(SOURCE!A3)),SOURCE!B3>0),IF(ISBLANK(SOURCE!C3),"",SOURCE!C3), IF(SOURCE!B3<0,VLOOKUP(SOURCE!B3,lookups!A$1:B$25,2,0), IF(ISBLANK(SOURCE!B3), "", "/* "&TEXT(SOURCE!B3,"???0")&" *"& SOURCE!C3&", "& IF(lookups!$E$2-LEN(SOURCE!C3) >= 0, REPT(" ",lookups!$E$2-LEN(SOURCE!C3)), "")& SOURCE!D3&", "& IF(lookups!$F$2-LEN(SOURCE!D3) >= 0, REPT(" ",lookups!$F$2-LEN(SOURCE!D3)), "")& SOURCE!E3&", "& IF(lookups!$G$2-LEN(SOURCE!E3) >=0, REPT(" ",lookups!$G$2-LEN(SOURCE!E3)), "")& SOURCE!F3&", "& IF(lookups!$H$2-LEN(SOURCE!F3) >= 0, REPT(" ",lookups!$H$2-LEN(SOURCE!F3)+2), "")&"("& SUBSTITUTE(TEXT(SOURCE!G3,"??0")," ","")&" << TAM_MAX_BITS) |"& IF(lookups!$I$2-3 >= 0, REPT(" ",MAX(1,lookups!$I$2-5+4+1-1-LEN( IF(ISTEXT(SOURCE!H3),SOURCE!H3, SUBSTITUTE(SUBSTITUTE(TEXT(SOURCE!H3,"????0")," ","")," ","")) ))), "")& IF(ISTEXT(SOURCE!H3),SOURCE!H3, SUBSTITUTE(SUBSTITUTE(TEXT(SOURCE!H3,"????0")," ","")," ","")) &","& IF(lookups!$J$2-3 >= 0, REPT(" ",lookups!$J$2-3-5), "")& SOURCE!I3& " | "& IF(lookups!$K$2-LEN(SOURCE!I3) >= 0, REPT(" ",lookups!$K$2-LEN(SOURCE!I3)), "")& SOURCE!J3& IF(lookups!$L$2-LEN(SOURCE!J3) >= 0, REPT(" ",lookups!$L$2-LEN(SOURCE!J3)), "")& " | "& IF(lookups!$K$2-LEN(SOURCE!I3) >= 0, REPT(" ",lookups!$K$2-LEN(SOURCE!I3)), "")& SOURCE!K3& IF(lookups!$L$2-LEN(SOURCE!K3) >= 0, REPT(" ",lookups!$M$2-LEN(SOURCE!K3)), "")& " | "& SOURCE!L3& IF(lookups!$O$2-LEN(SOURCE!L3) >= 0, REPT(" ",lookups!$O$2-LEN(SOURCE!L3)), "")& " | "& SOURCE!M3& IF(lookups!$P$2-LEN(SOURCE!M3) >= 0, REPT(" ",lookups!$P$2-LEN(SOURCE!M3)), "")& "},"&IF(SOURCE!O3<>"",""&SOURCE!O3,"") ) ) ) -> /* 0 */ { itemToBeCoded, NOPARAM, "", "0000", (0 << TAM_MAX_BITS) | 0, CAT_NONE | SLS_UNCHANGED | US_UNCHANGED | EIM_DISABLED | PTP_NONE }, // ITM_NULL
A4: =IF(AND(OR(SOURCE!A4="",ISBLANK(SOURCE!A4)),SOURCE!B4>0),IF(ISBLANK(SOURCE!C4),"",SOURCE!C4), IF(SOURCE!B4<0,VLOOKUP(SOURCE!B4,lookups!A$1:B$25,2,0), IF(ISBLANK(SOURCE!B4), "", "/* "&TEXT(SOURCE!B4,"???0")&" *"& SOURCE!C4&", "& IF(lookups!$E$2-LEN(SOURCE!C4) >= 0, REPT(" ",lookups!$E$2-LEN(SOURCE!C4)), "")& SOURCE!D4&", "& IF(lookups!$F$2-LEN(SOURCE!D4) >= 0, REPT(" ",lookups!$F$2-LEN(SOURCE!D4)), "")& SOURCE!E4&", "& IF(lookups!$G$2-LEN(SOURCE!E4) >=0, REPT(" ",lookups!$G$2-LEN(SOURCE!E4)), "")& SOURCE!F4&", "& IF(lookups!$H$2-LEN(SOURCE!F4) >= 0, REPT(" ",lookups!$H$2-LEN(SOURCE!F4)+2), "")&"("& SUBSTITUTE(TEXT(SOURCE!G4,"??0")," ","")&" << TAM_MAX_BITS) |"& IF(lookups!$I$2-3 >= 0, REPT(" ",MAX(1,lookups!$I$2-5+4+1-1-LEN( IF(ISTEXT(SOURCE!H4),SOURCE!H4, SUBSTITUTE(SUBSTITUTE(TEXT(SOURCE!H4,"????0")," ","")," ","")) ))), "")& IF(ISTEXT(SOURCE!H4),SOURCE!H4, SUBSTITUTE(SUBSTITUTE(TEXT(SOURCE!H4,"????0")," ","")," ","")) &","& IF(lookups!$J$2-3 >= 0, REPT(" ",lookups!$J$2-3-5), "")& SOURCE!I4& " | "& IF(lookups!$K$2-LEN(SOURCE!I4) >= 0, REPT(" ",lookups!$K$2-LEN(SOURCE!I4)), "")& SOURCE!J4& IF(lookups!$L$2-LEN(SOURCE!J4) >= 0, REPT(" ",lookups!$L$2-LEN(SOURCE!J4)), "")& " | "& IF(lookups!$K$2-LEN(SOURCE!I4) >= 0, REPT(" ",lookups!$K$2-LEN(SOURCE!I4)), "")& SOURCE!K4& IF(lookups!$L$2-LEN(SOURCE!K4) >= 0, REPT(" ",lookups!$M$2-LEN(SOURCE!K4)), "")& " | "& SOURCE!L4& IF(lookups!$O$2-LEN(SOURCE!L4) >= 0, REPT(" ",lookups!$O$2-LEN(SOURCE!L4)), "")& " | "& SOURCE!M4& IF(lookups!$P$2-LEN(SOURCE!M4) >= 0, REPT(" ",lookups!$P$2-LEN(SOURCE!M4)), "")& "},"&IF(SOURCE!O4<>"",""&SOURCE!O4,"") ) ) )
A5: =IF(AND(OR(SOURCE!A5="",ISBLANK(SOURCE!A5)),SOURCE!B5>0),IF(ISBLANK(SOURCE!C5),"",SOURCE!C5), IF(SOURCE!B5<0,VLOOKUP(SOURCE!B5,lookups!A$1:B$25,2,0), IF(ISBLANK(SOURCE!B5), "", "/* "&TEXT(SOURCE!B5,"???0")&" *"& SOURCE!C5&", "& IF(lookups!$E$2-LEN(SOURCE!C5) >= 0, REPT(" ",lookups!$E$2-LEN(SOURCE!C5)), "")& SOURCE!D5&", "& IF(lookups!$F$2-LEN(SOURCE!D5) >= 0, REPT(" ",lookups!$F$2-LEN(SOURCE!D5)), "")& SOURCE!E5&", "& IF(lookups!$G$2-LEN(SOURCE!E5) >=0, REPT(" ",lookups!$G$2-LEN(SOURCE!E5)), "")& SOURCE!F5&", "& IF(lookups!$H$2-LEN(SOURCE!F5) >= 0, REPT(" ",lookups!$H$2-LEN(SOURCE!F5)+2), "")&"("& SUBSTITUTE(TEXT(SOURCE!G5,"??0")," ","")&" << TAM_MAX_BITS) |"& IF(lookups!$I$2-3 >= 0, REPT(" ",MAX(1,lookups!$I$2-5+4+1-1-LEN( IF(ISTEXT(SOURCE!H5),SOURCE!H5, SUBSTITUTE(SUBSTITUTE(TEXT(SOURCE!H5,"????0")," ","")," ","")) ))), "")& IF(ISTEXT(SOURCE!H5),SOURCE!H5, SUBSTITUTE(SUBSTITUTE(TEXT(SOURCE!H5,"????0")," ","")," ","")) &","& IF(lookups!$J$2-3 >= 0, REPT(" ",lookups!$J$2-3-5), "")& SOURCE!I5& " | "& IF(lookups!$K$2-LEN(SOURCE!I5) >= 0, REPT(" ",lookups!$K$2-LEN(SOURCE!I5)), "")& SOURCE!J5& IF(lookups!$L$2-LEN(SOURCE!J5) >= 0, REPT(" ",lookups!$L$2-LEN(SOURCE!J5)), "")& " | "& IF(lookups!$K$2-LEN(SOURCE!I5) >= 0, REPT(" ",lookups!$K$2-LEN(SOURCE!I5)), "")& SOURCE!K5& IF(lookups!$L$2-LEN(SOURCE!K5) >= 0, REPT(" ",lookups!$M$2-LEN(SOURCE!K5)), "")& " | "& SOURCE!L5& IF(lookups!$O$2-LEN(SOURCE!L5) >= 0, REPT(" ",lookups!$O$2-LEN(SOURCE!L5)), "")& " | "& SOURCE!M5& IF(lookups!$P$2-LEN(SOURCE!M5) >= 0, REPT(" ",lookups!$P$2-LEN(SOURCE!M5)), "")& "},"&IF(SOURCE!O5<>"",""&SOURCE!O5,"") ) ) ) -> // Items from 1 to 127 are 1 byte OP codes
A6: =IF(AND(OR(SOURCE!A6="",ISBLANK(SOURCE!A6)),SOURCE!B6>0),IF(ISBLANK(SOURCE!C6),"",SOURCE!C6), IF(SOURCE!B6<0,VLOOKUP(SOURCE!B6,lookups!A$1:B$25,2,0), IF(ISBLANK(SOURCE!B6), "", "/* "&TEXT(SOURCE!B6,"???0")&" *"& SOURCE!C6&", "& IF(lookups!$E$2-LEN(SOURCE!C6) >= 0, REPT(" ",lookups!$E$2-LEN(SOURCE!C6)), "")& SOURCE!D6&", "& IF(lookups!$F$2-LEN(SOURCE!D6) >= 0, REPT(" ",lookups!$F$2-LEN(SOURCE!D6)), "")& SOURCE!E6&", "& IF(lookups!$G$2-LEN(SOURCE!E6) >=0, REPT(" ",lookups!$G$2-LEN(SOURCE!E6)), "")& SOURCE!F6&", "& IF(lookups!$H$2-LEN(SOURCE!F6) >= 0, REPT(" ",lookups!$H$2-LEN(SOURCE!F6)+2), "")&"("& SUBSTITUTE(TEXT(SOURCE!G6,"??0")," ","")&" << TAM_MAX_BITS) |"& IF(lookups!$I$2-3 >= 0, REPT(" ",MAX(1,lookups!$I$2-5+4+1-1-LEN( IF(ISTEXT(SOURCE!H6),SOURCE!H6, SUBSTITUTE(SUBSTITUTE(TEXT(SOURCE!H6,"????0")," ","")," ","")) ))), "")& IF(ISTEXT(SOURCE!H6),SOURCE!H6, SUBSTITUTE(SUBSTITUTE(TEXT(SOURCE!H6,"????0")," ","")," ","")) &","& IF(lookups!$J$2-3 >= 0, REPT(" ",lookups!$J$2-3-5), "")& SOURCE!I6& " | "& IF(lookups!$K$2-LEN(SOURCE!I6) >= 0, REPT(" ",lookups!$K$2-LEN(SOURCE!I6)), "")& SOURCE!J6& IF(lookups!$L$2-LEN(SOURCE!J6) >= 0, REPT(" ",lookups!$L$2-LEN(SOURCE!J6)), "")& " | "& IF(lookups!$K$2-LEN(SOURCE!I6) >= 0, REPT(" ",lookups!$K$2-LEN(SOURCE!I6)), "")& SOURCE!K6& IF(lookups!$L$2-LEN(SOURCE!K6) >= 0, REPT(" ",lookups!$M$2-LEN(SOURCE!K6)), "")& " | "& SOURCE!L6& IF(lookups!$O$2-LEN(SOURCE!L6) >= 0, REPT(" ",lookups!$O$2-LEN(SOURCE!L6)), "")& " | "& SOURCE!M6& IF(lookups!$P$2-LEN(SOURCE!M6) >= 0, REPT(" ",lookups!$P$2-LEN(SOURCE!M6)), "")& "},"&IF(SOURCE!O6<>"",""&SOURCE!O6,"") ) ) ) -> /* 1 */ { fnNop, TM_LABEL, "LBL", "LBL", (0 << TAM_MAX_BITS) | 99, CAT_FNCT | SLS_ENABLED | US_ENABLED | EIM_DISABLED | PTP_DECLARE_LABEL},
A7: =IF(AND(OR(SOURCE!A7="",ISBLANK(SOURCE!A7)),SOURCE!B7>0),IF(ISBLANK(SOURCE!C7),"",SOURCE!C7), IF(SOURCE!B7<0,VLOOKUP(SOURCE!B7,lookups!A$1:B$25,2,0), IF(ISBLANK(SOURCE!B7), "", "/* "&TEXT(SOURCE!B7,"???0")&" *"& SOURCE!C7&", "& IF(lookups!$E$2-LEN(SOURCE!C7) >= 0, REPT(" ",lookups!$E$2-LEN(SOURCE!C7)), "")& SOURCE!D7&", "& IF(lookups!$F$2-LEN(SOURCE!D7) >= 0, REPT(" ",lookups!$F$2-LEN(SOURCE!D7)), "")& SOURCE!E7&", "& IF(lookups!$G$2-LEN(SOURCE!E7) >=0, REPT(" ",lookups!$G$2-LEN(SOURCE!E7)), "")& SOURCE!F7&", "& IF(lookups!$H$2-LEN(SOURCE!F7) >= 0, REPT(" ",lookups!$H$2-LEN(SOURCE!F7)+2), "")&"("& SUBSTITUTE(TEXT(SOURCE!G7,"??0")," ","")&" << TAM_MAX_BITS) |"& IF(lookups!$I$2-3 >= 0, REPT(" ",MAX(1,lookups!$I$2-5+4+1-1-LEN( IF(ISTEXT(SOURCE!H7),SOURCE!H7, SUBSTITUTE(SUBSTITUTE(TEXT(SOURCE!H7,"????0")," ","")," ","")) ))), "")& IF(ISTEXT(SOURCE!H7),SOURCE!H7, SUBSTITUTE(SUBSTITUTE(TEXT(SOURCE!H7,"????0")," ","")," ","")) &","& IF(lookups!$J$2-3 >= 0, REPT(" ",lookups!$J$2-3-5), "")& SOURCE!I7& " | "& IF(lookups!$K$2-LEN(SOURCE!I7) >= 0, REPT(" ",lookups!$K$2-LEN(SOURCE!I7)), "")& SOURCE!J7& IF(lookups!$L$2-LEN(SOURCE!J7) >= 0, REPT(" ",lookups!$L$2-LEN(SOURCE!J7)), "")& " | "& IF(lookups!$K$2-LEN(SOURCE!I7) >= 0, REPT(" ",lookups!$K$2-LEN(SOURCE!I7)), "")& SOURCE!K7& IF(lookups!$L$2-LEN(SOURCE!K7) >= 0, REPT(" ",lookups!$M$2-LEN(SOURCE!K7)), "")& " | "& SOURCE!L7& IF(lookups!$O$2-LEN(SOURCE!L7) >= 0, REPT(" ",lookups!$O$2-LEN(SOURCE!L7)), "")& " | "& SOURCE!M7& IF(lookups!$P$2-LEN(SOURCE!M7) >= 0, REPT(" ",lookups!$P$2-LEN(SOURCE!M7)), "")& "},"&IF(SOURCE!O7<>"",""&SOURCE!O7,"") ) ) ) -> /* 2 */ { fnGoto, TM_LABEL, "GTO", "GTO", (0 << TAM_MAX_BITS) | 99, CAT_FNCT | SLS_ENABLED | US_ENABLED | EIM_DISABLED | PTP_LABEL },
A8: =IF(AND(OR(SOURCE!A8="",ISBLANK(SOURCE!A8)),SOURCE!B8>0),IF(ISBLANK(SOURCE!C8),"",SOURCE!C8), IF(SOURCE!B8<0,VLOOKUP(SOURCE!B8,lookups!A$1:B$25,2,0), IF(ISBLANK(SOURCE!B8), "", "/* "&TEXT(SOURCE!B8,"???0")&" *"& SOURCE!C8&", "& IF(lookups!$E$2-LEN(SOURCE!C8) >= 0, REPT(" ",lookups!$E$2-LEN(SOURCE!C8)), "")& SOURCE!D8&", "& IF(lookups!$F$2-LEN(SOURCE!D8) >= 0, REPT(" ",lookups!$F$2-LEN(SOURCE!D8)), "")& SOURCE!E8&", "& IF(lookups!$G$2-LEN(SOURCE!E8) >=0, REPT(" ",lookups!$G$2-LEN(SOURCE!E8)), "")& SOURCE!F8&", "& IF(lookups!$H$2-LEN(SOURCE!F8) >= 0, REPT(" ",lookups!$H$2-LEN(SOURCE!F8)+2), "")&"("& SUBSTITUTE(TEXT(SOURCE!G8,"??0")," ","")&" << TAM_MAX_BITS) |"& IF(lookups!$I$2-3 >= 0, REPT(" ",MAX(1,lookups!$I$2-5+4+1-1-LEN( IF(ISTEXT(SOURCE!H8),SOURCE!H8, SUBSTITUTE(SUBSTITUTE(TEXT(SOURCE!H8,"????0")," ","")," ","")) ))), "")& IF(ISTEXT(SOURCE!H8),SOURCE!H8, SUBSTITUTE(SUBSTITUTE(TEXT(SOURCE!H8,"????0")," ","")," ","")) &","& IF(lookups!$J$2-3 >= 0, REPT(" ",lookups!$J$2-3-5), "")& SOURCE!I8& " | "& IF(lookups!$K$2-LEN(SOURCE!I8) >= 0, REPT(" ",lookups!$K$2-LEN(SOURCE!I8)), "")& SOURCE!J8& IF(lookups!$L$2-LEN(SOURCE!J8) >= 0, REPT(" ",lookups!$L$2-LEN(SOURCE!J8)), "")& " | "& IF(lookups!$K$2-LEN(SOURCE!I8) >= 0, REPT(" ",lookups!$K$2-LEN(SOURCE!I8)), "")& SOURCE!K8& IF(lookups!$L$2-LEN(SOURCE!K8) >= 0, REPT(" ",lookups!$M$2-LEN(SOURCE!K8)), "")& " | "& SOURCE!L8& IF(lookups!$O$2-LEN(SOURCE!L8) >= 0, REPT(" ",lookups!$O$2-LEN(SOURCE!L8)), "")& " | "& SOURCE!M8& IF(lookups!$P$2-LEN(SOURCE!M8) >= 0, REPT(" ",lookups!$P$2-LEN(SOURCE!M8)), "")& "},"&IF(SOURCE!O8<>"",""&SOURCE!O8,"") ) ) ) -> /* 3 */ { fnExecute, TM_LABEL, "XEQ", "XEQ", (0 << TAM_MAX_BITS) | 99, CAT_FNCT | SLS_ENABLED | US_ENABLED | EIM_DISABLED | PTP_LABEL },
A9: =IF(AND(OR(SOURCE!A9="",ISBLANK(SOURCE!A9)),SOURCE!B9>0),IF(ISBLANK(SOURCE!C9),"",SOURCE!C9), IF(SOURCE!B9<0,VLOOKUP(SOURCE!B9,lookups!A$1:B$25,2,0), IF(ISBLANK(SOURCE!B9), "", "/* "&TEXT(SOURCE!B9,"???0")&" *"& SOURCE!C9&", "& IF(lookups!$E$2-LEN(SOURCE!C9) >= 0, REPT(" ",lookups!$E$2-LEN(SOURCE!C9)), "")& SOURCE!D9&", "& IF(lookups!$F$2-LEN(SOURCE!D9) >= 0, REPT(" ",lookups!$F$2-LEN(SOURCE!D9)), "")& SOURCE!E9&", "& IF(lookups!$G$2-LEN(SOURCE!E9) >=0, REPT(" ",lookups!$G$2-LEN(SOURCE!E9)), "")& SOURCE!F9&", "& IF(lookups!$H$2-LEN(SOURCE!F9) >= 0, REPT(" ",lookups!$H$2-LEN(SOURCE!F9)+2), "")&"("& SUBSTITUTE(TEXT(SOURCE!G9,"??0")," ","")&" << TAM_MAX_BITS) |"& IF(lookups!$I$2-3 >= 0, REPT(" ",MAX(1,lookups!$I$2-5+4+1-1-LEN( IF(ISTEXT(SOURCE!H9),SOURCE!H9, SUBSTITUTE(SUBSTITUTE(TEXT(SOURCE!H9,"????0")," ","")," ","")) ))), "")& IF(ISTEXT(SOURCE!H9),SOURCE!H9, SUBSTITUTE(SUBSTITUTE(TEXT(SOURCE!H9,"????0")," ","")," ","")) &","& IF(lookups!$J$2-3 >= 0, REPT(" ",lookups!$J$2-3-5), "")& SOURCE!I9& " | "& IF(lookups!$K$2-LEN(SOURCE!I9) >= 0, REPT(" ",lookups!$K$2-LEN(SOURCE!I9)), "")& SOURCE!J9& IF(lookups!$L$2-LEN(SOURCE!J9) >= 0, REPT(" ",lookups!$L$2-LEN(SOURCE!J9)), "")& " | "& IF(lookups!$K$2-LEN(SOURCE!I9) >= 0, REPT(" ",lookups!$K$2-LEN(SOURCE!I9)), "")& SOURCE!K9& IF(lookups!$L$2-LEN(SOURCE!K9) >= 0, REPT(" ",lookups!$M$2-LEN(SOURCE!K9)), "")& " | "& SOURCE!L9& IF(lookups!$O$2-LEN(SOURCE!L9) >= 0, REPT(" ",lookups!$O$2-LEN(SOURCE!L9)), "")& " | "& SOURCE!M9& IF(lookups!$P$2-LEN(SOURCE!M9) >= 0, REPT(" ",lookups!$P$2-LEN(SOURCE!M9)), "")& "},"&IF(SOURCE!O9<>"",""&SOURCE!O9,"") ) ) ) -> /* 4 */ { fnReturn, 0, "RTN", "RTN", (0 << TAM_MAX_BITS) | 0, CAT_FNCT | SLS_UNCHANGED | US_UNCHANGED | EIM_DISABLED | PTP_NONE },
A10: =IF(AND(OR(SOURCE!A10="",ISBLANK(SOURCE!A10)),SOURCE!B10>0),IF(ISBLANK(SOURCE!C10),"",SOURCE!C10), IF(SOURCE!B10<0,VLOOKUP(SOURCE!B10,lookups!A$1:B$25,2,0), IF(ISBLANK(SOURCE!B10), "", "/* "&TEXT(SOURCE!B10,"???0")&" *"& SOURCE!C10&", "& IF(lookups!$E$2-LEN(SOURCE!C10) >= 0, REPT(" ",lookups!$E$2-LEN(SOURCE!C10)), "")& SOURCE!D10&", "& IF(lookups!$F$2-LEN(SOURCE!D10) >= 0, REPT(" ",lookups!$F$2-LEN(SOURCE!D10)), "")& SOURCE!E10&", "& IF(lookups!$G$2-LEN(SOURCE!E10) >=0, REPT(" ",lookups!$G$2-LEN(SOURCE!E10)), "")& SOURCE!F10&", "& IF(lookups!$H$2-LEN(SOURCE!F10) >= 0, REPT(" ",lookups!$H$2-LEN(SOURCE!F10)+2), "")&"("& SUBSTITUTE(TEXT(SOURCE!G10,"??0")," ","")&" << TAM_MAX_BITS) |"& IF(lookups!$I$2-3 >= 0, REPT(" ",MAX(1,lookups!$I$2-5+4+1-1-LEN( IF(ISTEXT(SOURCE!H10),SOURCE!H10, SUBSTITUTE(SUBSTITUTE(TEXT(SOURCE!H10,"????0")," ","")," ","")) ))), "")& IF(ISTEXT(SOURCE!H10),SOURCE!H10, SUBSTITUTE(SUBSTITUTE(TEXT(SOURCE!H10,"????0")," ","")," ","")) &","& IF(lookups!$J$2-3 >= 0, REPT(" ",lookups!$J$2-3-5), "")& SOURCE!I10& " | "& IF(lookups!$K$2-LEN(SOURCE!I10) >= 0, REPT(" ",lookups!$K$2-LEN(SOURCE!I10)), "")& SOURCE!J10& IF(lookups!$L$2-LEN(SOURCE!J10) >= 0, REPT(" ",lookups!$L$2-LEN(SOURCE!J10)), "")& " | "& IF(lookups!$K$2-LEN(SOURCE!I10) >= 0, REPT(" ",lookups!$K$2-LEN(SOURCE!I10)), "")& SOURCE!K10& IF(lookups!$L$2-LEN(SOURCE!K10) >= 0, REPT(" ",lookups!$M$2-LEN(SOURCE!K10)), "")& " | "& SOURCE!L10& IF(lookups!$O$2-LEN(SOURCE!L10) >= 0, REPT(" ",lookups!$O$2-LEN(SOURCE!L10)), "")& " | "& SOURCE!M10& IF(lookups!$P$2-LEN(SOURCE!M10) >= 0, REPT(" ",lookups!$P$2-LEN(SOURCE!M10)), "")& "},"&IF(SOURCE!O10<>"",""&SOURCE!O10,"") ) ) ) -> /* 5 */ { fnIse, TM_REGISTER, "ISE", "ISE", (0 << TAM_MAX_BITS) | 99, CAT_FNCT | SLS_ENABLED | US_ENABLED | EIM_DISABLED | PTP_REGISTER },
A11: =IF(AND(OR(SOURCE!A11="",ISBLANK(SOURCE!A11)),SOURCE!B11>0),IF(ISBLANK(SOURCE!C11),"",SOURCE!C11), IF(SOURCE!B11<0,VLOOKUP(SOURCE!B11,lookups!A$1:B$25,2,0), IF(ISBLANK(SOURCE!B11), "", "/* "&TEXT(SOURCE!B11,"???0")&" *"& SOURCE!C11&", "& IF(lookups!$E$2-LEN(SOURCE!C11) >= 0, REPT(" ",lookups!$E$2-LEN(SOURCE!C11)), "")& SOURCE!D11&", "& IF(lookups!$F$2-LEN(SOURCE!D11) >= 0, REPT(" ",lookups!$F$2-LEN(SOURCE!D11)), "")& SOURCE!E11&", "& IF(lookups!$G$2-LEN(SOURCE!E11) >=0, REPT(" ",lookups!$G$2-LEN(SOURCE!E11)), "")& SOURCE!F11&", "& IF(lookups!$H$2-LEN(SOURCE!F11) >= 0, REPT(" ",lookups!$H$2-LEN(SOURCE!F11)+2), "")&"("& SUBSTITUTE(TEXT(SOURCE!G11,"??0")," ","")&" << TAM_MAX_BITS) |"& IF(lookups!$I$2-3 >= 0, REPT(" ",MAX(1,lookups!$I$2-5+4+1-1-LEN( IF(ISTEXT(SOURCE!H11),SOURCE!H11, SUBSTITUTE(SUBSTITUTE(TEXT(SOURCE!H11,"????0")," ","")," ","")) ))), "")& IF(ISTEXT(SOURCE!H11),SOURCE!H11, SUBSTITUTE(SUBSTITUTE(TEXT(SOURCE!H11,"????0")," ","")," ","")) &","& IF(lookups!$J$2-3 >= 0, REPT(" ",lookups!$J$2-3-5), "")& SOURCE!I11& " | "& IF(lookups!$K$2-LEN(SOURCE!I11) >= 0, REPT(" ",lookups!$K$2-LEN(SOURCE!I11)), "")& SOURCE!J11& IF(lookups!$L$2-LEN(SOURCE!J11) >= 0, REPT(" ",lookups!$L$2-LEN(SOURCE!J11)), "")& " | "& IF(lookups!$K$2-LEN(SOURCE!I11) >= 0, REPT(" ",lookups!$K$2-LEN(SOURCE!I11)), "")& SOURCE!K11& IF(lookups!$L$2-LEN(SOURCE!K11) >= 0, REPT(" ",lookups!$M$2-LEN(SOURCE!K11)), "")& " | "& SOURCE!L11& IF(lookups!$O$2-LEN(SOURCE!L11) >= 0, REPT(" ",lookups!$O$2-LEN(SOURCE!L11)), "")& " | "& SOURCE!M11& IF(lookups!$P$2-LEN(SOURCE!M11) >= 0, REPT(" ",lookups!$P$2-LEN(SOURCE!M11)), "")& "},"&IF(SOURCE!O11<>"",""&SOURCE!O11,"") ) ) ) -> /* 6 */ { fnIsg, TM_REGISTER, "ISG", "ISG", (0 << TAM_MAX_BITS) | 99, CAT_FNCT | SLS_ENABLED | US_ENABLED | EIM_DISABLED | PTP_REGISTER },
A12: =IF(AND(OR(SOURCE!A12="",ISBLANK(SOURCE!A12)),SOURCE!B12>0),IF(ISBLANK(SOURCE!C12),"",SOURCE!C12), IF(SOURCE!B12<0,VLOOKUP(SOURCE!B12,lookups!A$1:B$25,2,0), IF(ISBLANK(SOURCE!B12), "", "/* "&TEXT(SOURCE!B12,"???0")&" *"& SOURCE!C12&", "& IF(lookups!$E$2-LEN(SOURCE!C12) >= 0, REPT(" ",lookups!$E$2-LEN(SOURCE!C12)), "")& SOURCE!D12&", "& IF(lookups!$F$2-LEN(SOURCE!D12) >= 0, REPT(" ",lookups!$F$2-LEN(SOURCE!D12)), "")& SOURCE!E12&", "& IF(lookups!$G$2-LEN(SOURCE!E12) >=0, REPT(" ",lookups!$G$2-LEN(SOURCE!E12)), "")& SOURCE!F12&", "& IF(lookups!$H$2-LEN(SOURCE!F12) >= 0, REPT(" ",lookups!$H$2-LEN(SOURCE!F12)+2), "")&"("& SUBSTITUTE(TEXT(SOURCE!G12,"??0")," ","")&" << TAM_MAX_BITS) |"& IF(lookups!$I$2-3 >= 0, REPT(" ",MAX(1,lookups!$I$2-5+4+1-1-LEN( IF(ISTEXT(SOURCE!H12),SOURCE!H12, SUBSTITUTE(SUBSTITUTE(TEXT(SOURCE!H12,"????0")," ","")," ","")) ))), "")& IF(ISTEXT(SOURCE!H12),SOURCE!H12, SUBSTITUTE(SUBSTITUTE(TEXT(SOURCE!H12,"????0")," ","")," ","")) &","& IF(lookups!$J$2-3 >= 0, REPT(" ",lookups!$J$2-3-5), "")& SOURCE!I12& " | "& IF(lookups!$K$2-LEN(SOURCE!I12) >= 0, REPT(" ",lookups!$K$2-LEN(SOURCE!I12)), "")& SOURCE!J12& IF(lookups!$L$2-LEN(SOURCE!J12) >= 0, REPT(" ",lookups!$L$2-LEN(SOURCE!J12)), "")& " | "& IF(lookups!$K$2-LEN(SOURCE!I12) >= 0, REPT(" ",lookups!$K$2-LEN(SOURCE!I12)), "")& SOURCE!K12& IF(lookups!$L$2-LEN(SOURCE!K12) >= 0, REPT(" ",lookups!$M$2-LEN(SOURCE!K12)), "")& " | "& SOURCE!L12& IF(lookups!$O$2-LEN(SOURCE!L12) >= 0, REPT(" ",lookups!$O$2-LEN(SOURCE!L12)), "")& " | "& SOURCE!M12& IF(lookups!$P$2-LEN(SOURCE!M12) >= 0, REPT(" ",lookups!$P$2-LEN(SOURCE!M12)), "")& "},"&IF(SOURCE!O12<>"",""&SOURCE!O12,"") ) ) ) -> /* 7 */ { fnIsz, TM_REGISTER, "ISZ", "ISZ", (0 << TAM_MAX_BITS) | 99, CAT_FNCT | SLS_ENABLED | US_ENABLED | EIM_DISABLED | PTP_REGISTER },
A13: =IF(AND(OR(SOURCE!A13="",ISBLANK(SOURCE!A13)),SOURCE!B13>0),IF(ISBLANK(SOURCE!C13),"",SOURCE!C13), IF(SOURCE!B13<0,VLOOKUP(SOURCE!B13,lookups!A$1:B$25,2,0), IF(ISBLANK(SOURCE!B13), "", "/* "&TEXT(SOURCE!B13,"???0")&" *"& SOURCE!C13&", "& IF(lookups!$E$2-LEN(SOURCE!C13) >= 0, REPT(" ",lookups!$E$2-LEN(SOURCE!C13)), "")& SOURCE!D13&", "& IF(lookups!$F$2-LEN(SOURCE!D13) >= 0, REPT(" ",lookups!$F$2-LEN(SOURCE!D13)), "")& SOURCE!E13&", "& IF(lookups!$G$2-LEN(SOURCE!E13) >=0, REPT(" ",lookups!$G$2-LEN(SOURCE!E13)), "")& SOURCE!F13&", "& IF(lookups!$H$2-LEN(SOURCE!F13) >= 0, REPT(" ",lookups!$H$2-LEN(SOURCE!F13)+2), "")&"("& SUBSTITUTE(TEXT(SOURCE!G13,"??0")," ","")&" << TAM_MAX_BITS) |"& IF(lookups!$I$2-3 >= 0, REPT(" ",MAX(1,lookups!$I$2-5+4+1-1-LEN( IF(ISTEXT(SOURCE!H13),SOURCE!H13, SUBSTITUTE(SUBSTITUTE(TEXT(SOURCE!H13,"????0")," ","")," ","")) ))), "")& IF(ISTEXT(SOURCE!H13),SOURCE!H13, SUBSTITUTE(SUBSTITUTE(TEXT(SOURCE!H13,"????0")," ","")," ","")) &","& IF(lookups!$J$2-3 >= 0, REPT(" ",lookups!$J$2-3-5), "")& SOURCE!I13& " | "& IF(lookups!$K$2-LEN(SOURCE!I13) >= 0, REPT(" ",lookups!$K$2-LEN(SOURCE!I13)), "")& SOURCE!J13& IF(lookups!$L$2-LEN(SOURCE!J13) >= 0, REPT(" ",lookups!$L$2-LEN(SOURCE!J13)), "")& " | "& IF(lookups!$K$2-LEN(SOURCE!I13) >= 0, REPT(" ",lookups!$K$2-LEN(SOURCE!I13)), "")& SOURCE!K13& IF(lookups!$L$2-LEN(SOURCE!K13) >= 0, REPT(" ",lookups!$M$2-LEN(SOURCE!K13)), "")& " | "& SOURCE!L13& IF(lookups!$O$2-LEN(SOURCE!L13) >= 0, REPT(" ",lookups!$O$2-LEN(SOURCE!L13)), "")& " | "& SOURCE!M13& IF(lookups!$P$2-LEN(SOURCE!M13) >= 0, REPT(" ",lookups!$P$2-LEN(SOURCE!M13)), "")& "},"&IF(SOURCE!O13<>"",""&SOURCE!O13,"") ) ) ) -> /* 8 */ { fnDse, TM_REGISTER, "DSE", "DSE", (0 << TAM_MAX_BITS) | 99, CAT_FNCT | SLS_ENABLED | US_ENABLED | EIM_DISABLED | PTP_REGISTER },
A14: =IF(AND(OR(SOURCE!A14="",ISBLANK(SOURCE!A14)),SOURCE!B14>0),IF(ISBLANK(SOURCE!C14),"",SOURCE!C14), IF(SOURCE!B14<0,VLOOKUP(SOURCE!B14,lookups!A$1:B$25,2,0), IF(ISBLANK(SOURCE!B14), "", "/* "&TEXT(SOURCE!B14,"???0")&" *"& SOURCE!C14&", "& IF(lookups!$E$2-LEN(SOURCE!C14) >= 0, REPT(" ",lookups!$E$2-LEN(SOURCE!C14)), "")& SOURCE!D14&", "& IF(lookups!$F$2-LEN(SOURCE!D14) >= 0, REPT(" ",lookups!$F$2-LEN(SOURCE!D14)), "")& SOURCE!E14&", "& IF(lookups!$G$2-LEN(SOURCE!E14) >=0, REPT(" ",lookups!$G$2-LEN(SOURCE!E14)), "")& SOURCE!F14&", "& IF(lookups!$H$2-LEN(SOURCE!F14) >= 0, REPT(" ",lookups!$H$2-LEN(SOURCE!F14)+2), "")&"("& SUBSTITUTE(TEXT(SOURCE!G14,"??0")," ","")&" << TAM_MAX_BITS) |"& IF(lookups!$I$2-3 >= 0, REPT(" ",MAX(1,lookups!$I$2-5+4+1-1-LEN( IF(ISTEXT(SOURCE!H14),SOURCE!H14, SUBSTITUTE(SUBSTITUTE(TEXT(SOURCE!H14,"????0")," ","")," ","")) ))), "")& IF(ISTEXT(SOURCE!H14),SOURCE!H14, SUBSTITUTE(SUBSTITUTE(TEXT(SOURCE!H14,"????0")," ","")," ","")) &","& IF(lookups!$J$2-3 >= 0, REPT(" ",lookups!$J$2-3-5), "")& SOURCE!I14& " | "& IF(lookups!$K$2-LEN(SOURCE!I14) >= 0, REPT(" ",lookups!$K$2-LEN(SOURCE!I14)), "")& SOURCE!J14& IF(lookups!$L$2-LEN(SOURCE!J14) >= 0, REPT(" ",lookups!$L$2-LEN(SOURCE!J14)), "")& " | "& IF(lookups!$K$2-LEN(SOURCE!I14) >= 0, REPT(" ",lookups!$K$2-LEN(SOURCE!I14)), "")& SOURCE!K14& IF(lookups!$L$2-LEN(SOURCE!K14) >= 0, REPT(" ",lookups!$M$2-LEN(SOURCE!K14)), "")& " | "& SOURCE!L14& IF(lookups!$O$2-LEN(SOURCE!L14) >= 0, REPT(" ",lookups!$O$2-LEN(SOURCE!L14)), "")& " | "& SOURCE!M14& IF(lookups!$P$2-LEN(SOURCE!M14) >= 0, REPT(" ",lookups!$P$2-LEN(SOURCE!M14)), "")& "},"&IF(SOURCE!O14<>"",""&SOURCE!O14,"") ) ) ) -> /* 9 */ { fnDsl, TM_REGISTER, "DSL", "DSL", (0 << TAM_MAX_BITS) | 99, CAT_FNCT | SLS_ENABLED | US_ENABLED | EIM_DISABLED | PTP_REGISTER },
... A2275: =IF(AND(OR(SOURCE!A2275="",ISBLANK(SOURCE!A2275)),SOURCE!B2275>0),IF(ISBLANK(SOURCE!C2275),"",SOURCE!C2275), IF(SOURCE!B2275<0,VLOOKUP(SOURCE!B2275,lookups!A$1:B$25,2,0), IF(ISBLANK(SOURCE!B2275), "", "/* "&TEXT(SOURCE!B2275,"???0")&" *"& SOURCE!C2275&", "& IF(lookups!$E$2-LEN(SOURCE!C2275) >= 0, REPT(" ",lookups!$E$2-LEN(SOURCE!C2275)), "")& SOURCE!D2275&", "& IF(lookups!$F$2-LEN(SOURCE!D2275) >= 0, REPT(" ",lookups!$F$2-LEN(SOURCE!D2275)), "")& SOURCE!E2275&", "& IF(lookups!$G$2-LEN(SOURCE!E2275) >=0, REPT(" ",lookups!$G$2-LEN(SOURCE!E2275)), "")& SOURCE!F2275&", "& IF(lookups!$H$2-LEN(SOURCE!F2275) >= 0, REPT(" ",lookups!$H$2-LEN(SOURCE!F2275)+2), "")&"("& SUBSTITUTE(TEXT(SOURCE!G2275,"??0")," ","")&" << TAM_MAX_BITS) |"& IF(lookups!$I$2-3 >= 0, REPT(" ",MAX(1,lookups!$I$2-5+4+1-1-LEN( IF(ISTEXT(SOURCE!H2275),SOURCE!H2275, SUBSTITUTE(SUBSTITUTE(TEXT(SOURCE!H2275,"????0")," ","")," ","")) ))), "")& IF(ISTEXT(SOURCE!H2275),SOURCE!H2275, SUBSTITUTE(SUBSTITUTE(TEXT(SOURCE!H2275,"????0")," ","")," ","")) &","& IF(lookups!$J$2-3 >= 0, REPT(" ",lookups!$J$2-3-5), "")& SOURCE!I2275& " | "& IF(lookups!$K$2-LEN(SOURCE!I2275) >= 0, REPT(" ",lookups!$K$2-LEN(SOURCE!I2275)), "")& SOURCE!J2275& IF(lookups!$L$2-LEN(SOURCE!J2275) >= 0, REPT(" ",lookups!$L$2-LEN(SOURCE!J2275)), "")& " | "& IF(lookups!$K$2-LEN(SOURCE!I2275) >= 0, REPT(" ",lookups!$K$2-LEN(SOURCE!I2275)), "")& SOURCE!K2275& IF(lookups!$L$2-LEN(SOURCE!K2275) >= 0, REPT(" ",lookups!$M$2-LEN(SOURCE!K2275)), "")& " | "& SOURCE!L2275& IF(lookups!$O$2-LEN(SOURCE!L2275) >= 0, REPT(" ",lookups!$O$2-LEN(SOURCE!L2275)), "")& " | "& SOURCE!M2275& IF(lookups!$P$2-LEN(SOURCE!M2275) >= 0, REPT(" ",lookups!$P$2-LEN(SOURCE!M2275)), "")& "},"&IF(SOURCE!O2275<>"",""&SOURCE!O2275,"") ) ) ) -> /* 2231 */ { itemToBeCoded, NOPARAM, "Prefix", "Prefix", (0 << TAM_MAX_BITS) | 0, CAT_MENU | SLS_UNCHANGED | US_UNCHANGED | EIM_DISABLED | PTP_DISABLED },
A2276: =IF(AND(OR(SOURCE!A2282="",ISBLANK(SOURCE!A2282)),SOURCE!B2282>0),IF(ISBLANK(SOURCE!C2282),"",SOURCE!C2282), IF(SOURCE!B2282<0,VLOOKUP(SOURCE!B2282,lookups!A$1:B$25,2,0), IF(ISBLANK(SOURCE!B2282), "", "/* "&TEXT(SOURCE!B2282,"???0")&" *"& SOURCE!C2282&", "& IF(lookups!$E$2-LEN(SOURCE!C2282) >= 0, REPT(" ",lookups!$E$2-LEN(SOURCE!C2282)), "")& SOURCE!D2282&", "& IF(lookups!$F$2-LEN(SOURCE!D2282) >= 0, REPT(" ",lookups!$F$2-LEN(SOURCE!D2282)), "")& SOURCE!E2282&", "& IF(lookups!$G$2-LEN(SOURCE!E2282) >=0, REPT(" ",lookups!$G$2-LEN(SOURCE!E2282)), "")& SOURCE!F2282&", "& IF(lookups!$H$2-LEN(SOURCE!F2282) >= 0, REPT(" ",lookups!$H$2-LEN(SOURCE!F2282)+2), "")&"("& SUBSTITUTE(TEXT(SOURCE!G2282,"??0")," ","")&" << TAM_MAX_BITS) |"& IF(lookups!$I$2-3 >= 0, REPT(" ",MAX(1,lookups!$I$2-5+4+1-1-LEN( IF(ISTEXT(SOURCE!H2282),SOURCE!H2282, SUBSTITUTE(SUBSTITUTE(TEXT(SOURCE!H2282,"????0")," ","")," ","")) ))), "")& IF(ISTEXT(SOURCE!H2282),SOURCE!H2282, SUBSTITUTE(SUBSTITUTE(TEXT(SOURCE!H2282,"????0")," ","")," ","")) &","& IF(lookups!$J$2-3 >= 0, REPT(" ",lookups!$J$2-3-5), "")& SOURCE!I2282& " | "& IF(lookups!$K$2-LEN(SOURCE!I2282) >= 0, REPT(" ",lookups!$K$2-LEN(SOURCE!I2282)), "")& SOURCE!J2282& IF(lookups!$L$2-LEN(SOURCE!J2282) >= 0, REPT(" ",lookups!$L$2-LEN(SOURCE!J2282)), "")& " | "& IF(lookups!$K$2-LEN(SOURCE!I2282) >= 0, REPT(" ",lookups!$K$2-LEN(SOURCE!I2282)), "")& SOURCE!K2282& IF(lookups!$L$2-LEN(SOURCE!K2282) >= 0, REPT(" ",lookups!$M$2-LEN(SOURCE!K2282)), "")& " | "& SOURCE!L2282& IF(lookups!$O$2-LEN(SOURCE!L2282) >= 0, REPT(" ",lookups!$O$2-LEN(SOURCE!L2282)), "")& " | "& SOURCE!M2282& IF(lookups!$P$2-LEN(SOURCE!M2282) >= 0, REPT(" ",lookups!$P$2-LEN(SOURCE!M2282)), "")& "},"&IF(SOURCE!O2282<>"",""&SOURCE!O2282,"") ) ) ) -> 0
A2277: =IF(AND(OR(SOURCE!A2283="",ISBLANK(SOURCE!A2283)),SOURCE!B2283>0),IF(ISBLANK(SOURCE!C2283),"",SOURCE!C2283), IF(SOURCE!B2283<0,VLOOKUP(SOURCE!B2283,lookups!A$1:B$25,2,0), IF(ISBLANK(SOURCE!B2283), "", "/* "&TEXT(SOURCE!B2283,"???0")&" *"& SOURCE!C2283&", "& IF(lookups!$E$2-LEN(SOURCE!C2283) >= 0, REPT(" ",lookups!$E$2-LEN(SOURCE!C2283)), "")& SOURCE!D2283&", "& IF(lookups!$F$2-LEN(SOURCE!D2283) >= 0, REPT(" ",lookups!$F$2-LEN(SOURCE!D2283)), "")& SOURCE!E2283&", "& IF(lookups!$G$2-LEN(SOURCE!E2283) >=0, REPT(" ",lookups!$G$2-LEN(SOURCE!E2283)), "")& SOURCE!F2283&", "& IF(lookups!$H$2-LEN(SOURCE!F2283) >= 0, REPT(" ",lookups!$H$2-LEN(SOURCE!F2283)+2), "")&"("& SUBSTITUTE(TEXT(SOURCE!G2283,"??0")," ","")&" << TAM_MAX_BITS) |"& IF(lookups!$I$2-3 >= 0, REPT(" ",MAX(1,lookups!$I$2-5+4+1-1-LEN( IF(ISTEXT(SOURCE!H2283),SOURCE!H2283, SUBSTITUTE(SUBSTITUTE(TEXT(SOURCE!H2283,"????0")," ","")," ","")) ))), "")& IF(ISTEXT(SOURCE!H2283),SOURCE!H2283, SUBSTITUTE(SUBSTITUTE(TEXT(SOURCE!H2283,"????0")," ","")," ","")) &","& IF(lookups!$J$2-3 >= 0, REPT(" ",lookups!$J$2-3-5), "")& SOURCE!I2283& " | "& IF(lookups!$K$2-LEN(SOURCE!I2283) >= 0, REPT(" ",lookups!$K$2-LEN(SOURCE!I2283)), "")& SOURCE!J2283& IF(lookups!$L$2-LEN(SOURCE!J2283) >= 0, REPT(" ",lookups!$L$2-LEN(SOURCE!J2283)), "")& " | "& IF(lookups!$K$2-LEN(SOURCE!I2283) >= 0, REPT(" ",lookups!$K$2-LEN(SOURCE!I2283)), "")& SOURCE!K2283& IF(lookups!$L$2-LEN(SOURCE!K2283) >= 0, REPT(" ",lookups!$M$2-LEN(SOURCE!K2283)), "")& " | "& SOURCE!L2283& IF(lookups!$O$2-LEN(SOURCE!L2283) >= 0, REPT(" ",lookups!$O$2-LEN(SOURCE!L2283)), "")& " | "& SOURCE!M2283& IF(lookups!$P$2-LEN(SOURCE!M2283) >= 0, REPT(" ",lookups!$P$2-LEN(SOURCE!M2283)), "")& "},"&IF(SOURCE!O2283<>"",""&SOURCE!O2283,"") ) ) ) -> 0
A2278: =IF(AND(OR(SOURCE!A2284="",ISBLANK(SOURCE!A2284)),SOURCE!B2284>0),IF(ISBLANK(SOURCE!C2284),"",SOURCE!C2284), IF(SOURCE!B2284<0,VLOOKUP(SOURCE!B2284,lookups!A$1:B$25,2,0), IF(ISBLANK(SOURCE!B2284), "", "/* "&TEXT(SOURCE!B2284,"???0")&" *"& SOURCE!C2284&", "& IF(lookups!$E$2-LEN(SOURCE!C2284) >= 0, REPT(" ",lookups!$E$2-LEN(SOURCE!C2284)), "")& SOURCE!D2284&", "& IF(lookups!$F$2-LEN(SOURCE!D2284) >= 0, REPT(" ",lookups!$F$2-LEN(SOURCE!D2284)), "")& SOURCE!E2284&", "& IF(lookups!$G$2-LEN(SOURCE!E2284) >=0, REPT(" ",lookups!$G$2-LEN(SOURCE!E2284)), "")& SOURCE!F2284&", "& IF(lookups!$H$2-LEN(SOURCE!F2284) >= 0, REPT(" ",lookups!$H$2-LEN(SOURCE!F2284)+2), "")&"("& SUBSTITUTE(TEXT(SOURCE!G2284,"??0")," ","")&" << TAM_MAX_BITS) |"& IF(lookups!$I$2-3 >= 0, REPT(" ",MAX(1,lookups!$I$2-5+4+1-1-LEN( IF(ISTEXT(SOURCE!H2284),SOURCE!H2284, SUBSTITUTE(SUBSTITUTE(TEXT(SOURCE!H2284,"????0")," ","")," ","")) ))), "")& IF(ISTEXT(SOURCE!H2284),SOURCE!H2284, SUBSTITUTE(SUBSTITUTE(TEXT(SOURCE!H2284,"????0")," ","")," ","")) &","& IF(lookups!$J$2-3 >= 0, REPT(" ",lookups!$J$2-3-5), "")& SOURCE!I2284& " | "& IF(lookups!$K$2-LEN(SOURCE!I2284) >= 0, REPT(" ",lookups!$K$2-LEN(SOURCE!I2284)), "")& SOURCE!J2284& IF(lookups!$L$2-LEN(SOURCE!J2284) >= 0, REPT(" ",lookups!$L$2-LEN(SOURCE!J2284)), "")& " | "& IF(lookups!$K$2-LEN(SOURCE!I2284) >= 0, REPT(" ",lookups!$K$2-LEN(SOURCE!I2284)), "")& SOURCE!K2284& IF(lookups!$L$2-LEN(SOURCE!K2284) >= 0, REPT(" ",lookups!$M$2-LEN(SOURCE!K2284)), "")& " | "& SOURCE!L2284& IF(lookups!$O$2-LEN(SOURCE!L2284) >= 0, REPT(" ",lookups!$O$2-LEN(SOURCE!L2284)), "")& " | "& SOURCE!M2284& IF(lookups!$P$2-LEN(SOURCE!M2284) >= 0, REPT(" ",lookups!$P$2-LEN(SOURCE!M2284)), "")& "},"&IF(SOURCE!O2284<>"",""&SOURCE!O2284,"") ) ) ) -> 0
A2279: =IF(AND(OR(SOURCE!A2285="",ISBLANK(SOURCE!A2285)),SOURCE!B2285>0),IF(ISBLANK(SOURCE!C2285),"",SOURCE!C2285), IF(SOURCE!B2285<0,VLOOKUP(SOURCE!B2285,lookups!A$1:B$25,2,0), IF(ISBLANK(SOURCE!B2285), "", "/* "&TEXT(SOURCE!B2285,"???0")&" *"& SOURCE!C2285&", "& IF(lookups!$E$2-LEN(SOURCE!C2285) >= 0, REPT(" ",lookups!$E$2-LEN(SOURCE!C2285)), "")& SOURCE!D2285&", "& IF(lookups!$F$2-LEN(SOURCE!D2285) >= 0, REPT(" ",lookups!$F$2-LEN(SOURCE!D2285)), "")& SOURCE!E2285&", "& IF(lookups!$G$2-LEN(SOURCE!E2285) >=0, REPT(" ",lookups!$G$2-LEN(SOURCE!E2285)), "")& SOURCE!F2285&", "& IF(lookups!$H$2-LEN(SOURCE!F2285) >= 0, REPT(" ",lookups!$H$2-LEN(SOURCE!F2285)+2), "")&"("& SUBSTITUTE(TEXT(SOURCE!G2285,"??0")," ","")&" << TAM_MAX_BITS) |"& IF(lookups!$I$2-3 >= 0, REPT(" ",MAX(1,lookups!$I$2-5+4+1-1-LEN( IF(ISTEXT(SOURCE!H2285),SOURCE!H2285, SUBSTITUTE(SUBSTITUTE(TEXT(SOURCE!H2285,"????0")," ","")," ","")) ))), "")& IF(ISTEXT(SOURCE!H2285),SOURCE!H2285, SUBSTITUTE(SUBSTITUTE(TEXT(SOURCE!H2285,"????0")," ","")," ","")) &","& IF(lookups!$J$2-3 >= 0, REPT(" ",lookups!$J$2-3-5), "")& SOURCE!I2285& " | "& IF(lookups!$K$2-LEN(SOURCE!I2285) >= 0, REPT(" ",lookups!$K$2-LEN(SOURCE!I2285)), "")& SOURCE!J2285& IF(lookups!$L$2-LEN(SOURCE!J2285) >= 0, REPT(" ",lookups!$L$2-LEN(SOURCE!J2285)), "")& " | "& IF(lookups!$K$2-LEN(SOURCE!I2285) >= 0, REPT(" ",lookups!$K$2-LEN(SOURCE!I2285)), "")& SOURCE!K2285& IF(lookups!$L$2-LEN(SOURCE!K2285) >= 0, REPT(" ",lookups!$M$2-LEN(SOURCE!K2285)), "")& " | "& SOURCE!L2285& IF(lookups!$O$2-LEN(SOURCE!L2285) >= 0, REPT(" ",lookups!$O$2-LEN(SOURCE!L2285)), "")& " | "& SOURCE!M2285& IF(lookups!$P$2-LEN(SOURCE!M2285) >= 0, REPT(" ",lookups!$P$2-LEN(SOURCE!M2285)), "")& "},"&IF(SOURCE!O2285<>"",""&SOURCE!O2285,"") ) ) ) -> 0
A2280: =IF(AND(OR(SOURCE!A2286="",ISBLANK(SOURCE!A2286)),SOURCE!B2286>0),IF(ISBLANK(SOURCE!C2286),"",SOURCE!C2286), IF(SOURCE!B2286<0,VLOOKUP(SOURCE!B2286,lookups!A$1:B$25,2,0), IF(ISBLANK(SOURCE!B2286), "", "/* "&TEXT(SOURCE!B2286,"???0")&" *"& SOURCE!C2286&", "& IF(lookups!$E$2-LEN(SOURCE!C2286) >= 0, REPT(" ",lookups!$E$2-LEN(SOURCE!C2286)), "")& SOURCE!D2286&", "& IF(lookups!$F$2-LEN(SOURCE!D2286) >= 0, REPT(" ",lookups!$F$2-LEN(SOURCE!D2286)), "")& SOURCE!E2286&", "& IF(lookups!$G$2-LEN(SOURCE!E2286) >=0, REPT(" ",lookups!$G$2-LEN(SOURCE!E2286)), "")& SOURCE!F2286&", "& IF(lookups!$H$2-LEN(SOURCE!F2286) >= 0, REPT(" ",lookups!$H$2-LEN(SOURCE!F2286)+2), "")&"("& SUBSTITUTE(TEXT(SOURCE!G2286,"??0")," ","")&" << TAM_MAX_BITS) |"& IF(lookups!$I$2-3 >= 0, REPT(" ",MAX(1,lookups!$I$2-5+4+1-1-LEN( IF(ISTEXT(SOURCE!H2286),SOURCE!H2286, SUBSTITUTE(SUBSTITUTE(TEXT(SOURCE!H2286,"????0")," ","")," ","")) ))), "")& IF(ISTEXT(SOURCE!H2286),SOURCE!H2286, SUBSTITUTE(SUBSTITUTE(TEXT(SOURCE!H2286,"????0")," ","")," ","")) &","& IF(lookups!$J$2-3 >= 0, REPT(" ",lookups!$J$2-3-5), "")& SOURCE!I2286& " | "& IF(lookups!$K$2-LEN(SOURCE!I2286) >= 0, REPT(" ",lookups!$K$2-LEN(SOURCE!I2286)), "")& SOURCE!J2286& IF(lookups!$L$2-LEN(SOURCE!J2286) >= 0, REPT(" ",lookups!$L$2-LEN(SOURCE!J2286)), "")& " | "& IF(lookups!$K$2-LEN(SOURCE!I2286) >= 0, REPT(" ",lookups!$K$2-LEN(SOURCE!I2286)), "")& SOURCE!K2286& IF(lookups!$L$2-LEN(SOURCE!K2286) >= 0, REPT(" ",lookups!$M$2-LEN(SOURCE!K2286)), "")& " | "& SOURCE!L2286& IF(lookups!$O$2-LEN(SOURCE!L2286) >= 0, REPT(" ",lookups!$O$2-LEN(SOURCE!L2286)), "")& " | "& SOURCE!M2286& IF(lookups!$P$2-LEN(SOURCE!M2286) >= 0, REPT(" ",lookups!$P$2-LEN(SOURCE!M2286)), "")& "},"&IF(SOURCE!O2286<>"",""&SOURCE!O2286,"") ) ) ) -> 0
A2281: =IF(AND(OR(SOURCE!A2287="",ISBLANK(SOURCE!A2287)),SOURCE!B2287>0),IF(ISBLANK(SOURCE!C2287),"",SOURCE!C2287), IF(SOURCE!B2287<0,VLOOKUP(SOURCE!B2287,lookups!A$1:B$25,2,0), IF(ISBLANK(SOURCE!B2287), "", "/* "&TEXT(SOURCE!B2287,"???0")&" *"& SOURCE!C2287&", "& IF(lookups!$E$2-LEN(SOURCE!C2287) >= 0, REPT(" ",lookups!$E$2-LEN(SOURCE!C2287)), "")& SOURCE!D2287&", "& IF(lookups!$F$2-LEN(SOURCE!D2287) >= 0, REPT(" ",lookups!$F$2-LEN(SOURCE!D2287)), "")& SOURCE!E2287&", "& IF(lookups!$G$2-LEN(SOURCE!E2287) >=0, REPT(" ",lookups!$G$2-LEN(SOURCE!E2287)), "")& SOURCE!F2287&", "& IF(lookups!$H$2-LEN(SOURCE!F2287) >= 0, REPT(" ",lookups!$H$2-LEN(SOURCE!F2287)+2), "")&"("& SUBSTITUTE(TEXT(SOURCE!G2287,"??0")," ","")&" << TAM_MAX_BITS) |"& IF(lookups!$I$2-3 >= 0, REPT(" ",MAX(1,lookups!$I$2-5+4+1-1-LEN( IF(ISTEXT(SOURCE!H2287),SOURCE!H2287, SUBSTITUTE(SUBSTITUTE(TEXT(SOURCE!H2287,"????0")," ","")," ","")) ))), "")& IF(ISTEXT(SOURCE!H2287),SOURCE!H2287, SUBSTITUTE(SUBSTITUTE(TEXT(SOURCE!H2287,"????0")," ","")," ","")) &","& IF(lookups!$J$2-3 >= 0, REPT(" ",lookups!$J$2-3-5), "")& SOURCE!I2287& " | "& IF(lookups!$K$2-LEN(SOURCE!I2287) >= 0, REPT(" ",lookups!$K$2-LEN(SOURCE!I2287)), "")& SOURCE!J2287& IF(lookups!$L$2-LEN(SOURCE!J2287) >= 0, REPT(" ",lookups!$L$2-LEN(SOURCE!J2287)), "")& " | "& IF(lookups!$K$2-LEN(SOURCE!I2287) >= 0, REPT(" ",lookups!$K$2-LEN(SOURCE!I2287)), "")& SOURCE!K2287& IF(lookups!$L$2-LEN(SOURCE!K2287) >= 0, REPT(" ",lookups!$M$2-LEN(SOURCE!K2287)), "")& " | "& SOURCE!L2287& IF(lookups!$O$2-LEN(SOURCE!L2287) >= 0, REPT(" ",lookups!$O$2-LEN(SOURCE!L2287)), "")& " | "& SOURCE!M2287& IF(lookups!$P$2-LEN(SOURCE!M2287) >= 0, REPT(" ",lookups!$P$2-LEN(SOURCE!M2287)), "")& "},"&IF(SOURCE!O2287<>"",""&SOURCE!O2287,"") ) ) ) -> 0
A2282: =IF(AND(OR(SOURCE!A2288="",ISBLANK(SOURCE!A2288)),SOURCE!B2288>0),IF(ISBLANK(SOURCE!C2288),"",SOURCE!C2288), IF(SOURCE!B2288<0,VLOOKUP(SOURCE!B2288,lookups!A$1:B$25,2,0), IF(ISBLANK(SOURCE!B2288), "", "/* "&TEXT(SOURCE!B2288,"???0")&" *"& SOURCE!C2288&", "& IF(lookups!$E$2-LEN(SOURCE!C2288) >= 0, REPT(" ",lookups!$E$2-LEN(SOURCE!C2288)), "")& SOURCE!D2288&", "& IF(lookups!$F$2-LEN(SOURCE!D2288) >= 0, REPT(" ",lookups!$F$2-LEN(SOURCE!D2288)), "")& SOURCE!E2288&", "& IF(lookups!$G$2-LEN(SOURCE!E2288) >=0, REPT(" ",lookups!$G$2-LEN(SOURCE!E2288)), "")& SOURCE!F2288&", "& IF(lookups!$H$2-LEN(SOURCE!F2288) >= 0, REPT(" ",lookups!$H$2-LEN(SOURCE!F2288)+2), "")&"("& SUBSTITUTE(TEXT(SOURCE!G2288,"??0")," ","")&" << TAM_MAX_BITS) |"& IF(lookups!$I$2-3 >= 0, REPT(" ",MAX(1,lookups!$I$2-5+4+1-1-LEN( IF(ISTEXT(SOURCE!H2288),SOURCE!H2288, SUBSTITUTE(SUBSTITUTE(TEXT(SOURCE!H2288,"????0")," ","")," ","")) ))), "")& IF(ISTEXT(SOURCE!H2288),SOURCE!H2288, SUBSTITUTE(SUBSTITUTE(TEXT(SOURCE!H2288,"????0")," ","")," ","")) &","& IF(lookups!$J$2-3 >= 0, REPT(" ",lookups!$J$2-3-5), "")& SOURCE!I2288& " | "& IF(lookups!$K$2-LEN(SOURCE!I2288) >= 0, REPT(" ",lookups!$K$2-LEN(SOURCE!I2288)), "")& SOURCE!J2288& IF(lookups!$L$2-LEN(SOURCE!J2288) >= 0, REPT(" ",lookups!$L$2-LEN(SOURCE!J2288)), "")& " | "& IF(lookups!$K$2-LEN(SOURCE!I2288) >= 0, REPT(" ",lookups!$K$2-LEN(SOURCE!I2288)), "")& SOURCE!K2288& IF(lookups!$L$2-LEN(SOURCE!K2288) >= 0, REPT(" ",lookups!$M$2-LEN(SOURCE!K2288)), "")& " | "& SOURCE!L2288& IF(lookups!$O$2-LEN(SOURCE!L2288) >= 0, REPT(" ",lookups!$O$2-LEN(SOURCE!L2288)), "")& " | "& SOURCE!M2288& IF(lookups!$P$2-LEN(SOURCE!M2288) >= 0, REPT(" ",lookups!$P$2-LEN(SOURCE!M2288)), "")& "},"&IF(SOURCE!O2288<>"",""&SOURCE!O2288,"") ) ) ) -> 0
A2283: =IF(AND(OR(SOURCE!A2320="",ISBLANK(SOURCE!A2320)),SOURCE!B2320>0),IF(ISBLANK(SOURCE!C2320),"",SOURCE!C2320), IF(SOURCE!B2320<0,VLOOKUP(SOURCE!B2320,lookups!A$1:B$25,2,0), IF(ISBLANK(SOURCE!B2320), "", "/* "&TEXT(SOURCE!B2320,"???0")&" *"& SOURCE!C2320&", "& IF(lookups!$E$2-LEN(SOURCE!C2320) >= 0, REPT(" ",lookups!$E$2-LEN(SOURCE!C2320)), "")& SOURCE!D2320&", "& IF(lookups!$F$2-LEN(SOURCE!D2320) >= 0, REPT(" ",lookups!$F$2-LEN(SOURCE!D2320)), "")& SOURCE!E2320&", "& IF(lookups!$G$2-LEN(SOURCE!E2320) >=0, REPT(" ",lookups!$G$2-LEN(SOURCE!E2320)), "")& SOURCE!F2320&", "& IF(lookups!$H$2-LEN(SOURCE!F2320) >= 0, REPT(" ",lookups!$H$2-LEN(SOURCE!F2320)+2), "")&"("& SUBSTITUTE(TEXT(SOURCE!G2320,"??0")," ","")&" << TAM_MAX_BITS) |"& IF(lookups!$I$2-3 >= 0, REPT(" ",MAX(1,lookups!$I$2-5+4+1-1-LEN( IF(ISTEXT(SOURCE!H2320),SOURCE!H2320, SUBSTITUTE(SUBSTITUTE(TEXT(SOURCE!H2320,"????0")," ","")," ","")) ))), "")& IF(ISTEXT(SOURCE!H2320),SOURCE!H2320, SUBSTITUTE(SUBSTITUTE(TEXT(SOURCE!H2320,"????0")," ","")," ","")) &","& IF(lookups!$J$2-3 >= 0, REPT(" ",lookups!$J$2-3-5), "")& SOURCE!I2320& " | "& IF(lookups!$K$2-LEN(SOURCE!I2320) >= 0, REPT(" ",lookups!$K$2-LEN(SOURCE!I2320)), "")& SOURCE!J2320& IF(lookups!$L$2-LEN(SOURCE!J2320) >= 0, REPT(" ",lookups!$L$2-LEN(SOURCE!J2320)), "")& " | "& IF(lookups!$K$2-LEN(SOURCE!I2320) >= 0, REPT(" ",lookups!$K$2-LEN(SOURCE!I2320)), "")& SOURCE!K2320& IF(lookups!$L$2-LEN(SOURCE!K2320) >= 0, REPT(" ",lookups!$M$2-LEN(SOURCE!K2320)), "")& " | "& SOURCE!L2320& IF(lookups!$O$2-LEN(SOURCE!L2320) >= 0, REPT(" ",lookups!$O$2-LEN(SOURCE!L2320)), "")& " | "& SOURCE!M2320& IF(lookups!$P$2-LEN(SOURCE!M2320) >= 0, REPT(" ",lookups!$P$2-LEN(SOURCE!M2320)), "")& "},"&IF(SOURCE!O2320<>"",""&SOURCE!O2320,"") ) ) ) -> 0
