Workbook
Name CRLF: Sheet2!$B$1

Sheet Sheet2
B1: PC Keyboard codes: | D1: https://docs.oracle.com/cd/E67482_01/oscar/pdf/45/OnlineHelp_45/helpOnPS2keyCodes.html
B3: 5 | C3: 10 | E3: 10 | F3: 20 | G3: 4 | H3: 30
B4: PC Key Code | C4: Exit If NIM | D4: Calculator C47/R47/Std | E4: Calculator Mode | F4: Function to run | G4: Key n to run (from 0-37) Key overrides function Key overrides ExitIfNim ?? Negative is off | H4: Comment | J4: Free42 | K4: Duplicate | L4: Duplicate calc
A5: a | B5: =CODE(A5) -> 97 | C5: ExitIfNim | D5: C47 | E5: CM_NORMAL | F5: ITM_SIGMAPLUS | G5: 0 | H5: [a]ccumulate | I5: 1 | J5: 0 | K5: =IF(L5,"DUPLICATE","") | L5: {=OR(EXACT(A5, $A6:$A$49))} -> FALSE
A6: v | B6: =CODE(A6) -> 118 | C6: ExitIfNim | D6: C47 | E6: CM_NORMAL | F6: ITM_1ONX | G6: 1 | H6: in[v]erse | I6: 1 | J6: 1 | K6: =IF(L6,"DUPLICATE","") | L6: {=OR(EXACT(A6, $A7:$A$49))} -> FALSE
A7: q | B7: =CODE(A7) -> 113 | C7: ExitIfNim | D7: C47 | E7: CM_NORMAL | F7: ITM_SQUAREROOTX | G7: 2 | H7: s[q]rt | I7: 3 | J7: 2 | K7: =IF(L7,"DUPLICATE","") | L7: {=OR(EXACT(A7, $A8:$A$49))} -> FALSE
A8: o | B8: =CODE(A8) -> 111 | C8: ExitIfNim | D8: C47 | E8: CM_NORMAL | F8: ITM_LOG10 | G8: 3 | H8: l[o]g | I8: 3 | J8: 3 | K8: =IF(L8,"DUPLICATE","") | L8: {=OR(EXACT(A8, $A9:$A$49))} -> FALSE
A9: l | B9: =CODE(A9) -> 108 | C9: ExitIfNim | D9: C47 | E9: CM_NORMAL | F9: ITM_LN | G9: 4 | H9: [l]n | I9: 3 | J9: 4 | K9: =IF(L9,"DUPLICATE","") | L9: {=OR(EXACT(A9, $A10:$A$49))} -> FALSE
A10: x | B10: =CODE(A10) -> 120 | C10: ExitIfNim | D10: C47 | E10: CM_NORMAL | F10: ITM_XEQ | G10: 5 | H10: [x]eq | I10: 0 | J10: 5 | K10: =IF(L10,"DUPLICATE","") | L10: {=OR(EXACT(A10, $A11:$A$49))} -> FALSE
A11: m | B11: =CODE(A11) -> 109 | C11: ExitIfNim | D11: C47 | E11: CM_NORMAL | F11: ITM_STO | G11: 6 | H11: [m]emory | I11: 0 | J11: 6 | K11: =IF(L11,"DUPLICATE","") | L11: {=OR(EXACT(A11, $A12:$A$49))} -> FALSE
A12: r | B12: =CODE(A12) -> 114 | C12: ExitIfNim | D12: C47 | E12: CM_NORMAL | F12: ITM_RCL | G12: 7 | H12: [r]cl | I12: 0 | J12: 7 | K12: =IF(L12,"DUPLICATE","") | L12: {=OR(EXACT(A12, $A13:$A$49))} -> FALSE
A13: d | B13: =CODE(A13) -> 100 | C13: ExitIfNim | D13: C47 | E13: CM_NORMAL | F13: ITM_Rdown | G13: 8 | H13: [d]own | I13: 0 | J13: 8 | K13: =IF(L13,"DUPLICATE","") | L13: {=OR(EXACT(A13, $A14:$A$49))} -> FALSE
A14: s | B14: =CODE(A14) -> 115 | C14: ExitIfNim | D14: C47 | E14: CM_NORMAL | F14: ITM_sin | G14: 9 | H14: [s]ine | I14: 2 | J14: 9 | K14: =IF(L14,"DUPLICATE","") | L14: {=OR(EXACT(A14, $A15:$A$49))} -> FALSE
A15: c | B15: =CODE(A15) -> 99 | C15: ExitIfNim | D15: C47 | E15: CM_NORMAL | F15: ITM_cos | G15: 10 | H15: [c]osine | I15: 2 | J15: 10 | K15: =IF(L15,"DUPLICATE","") | L15: {=OR(EXACT(A15, $A16:$A$49))} -> FALSE
A16: t | B16: =CODE(A16) -> 116 | C16: ExitIfNim | D16: C47 | E16: CM_NORMAL | F16: ITM_tan | G16: 11 | H16: [t]angent | I16: 2 | J16: 11 | K16: =IF(L16,"DUPLICATE","") | L16: {=OR(EXACT(A16, $A17:$A$49))} -> FALSE
A17: ENTER | B17: 65421 | C17: !ExitIfNim | D17: Std | E17: CM_NORMAL | F17: ITM_ENTER | G17: 12 | H17: key | I17: 0 | J17: 12 | K17: =IF(L17,"DUPLICATE","") | L17: {=OR(EXACT(A17, $A18:$A$49))} -> FALSE
A18: w | B18: =CODE(A18) -> 119 | C18: !ExitIfNim | D18: Std | E18: CM_NORMAL | F18: ITM_XexY | G18: 13 | H18: s[w]ap | I18: 0 | J18: 13 | K18: =IF(L18,"DUPLICATE","") | L18: {=OR(EXACT(A18, $A19:$A$49))} -> FALSE
A19: n | B19: =CODE(A19) -> 110 | C19: !ExitIfNim | D19: Std | E19: CM_NORMAL | F19: ITM_CHS | G19: 14 | H19: CHS [n]egative | I19: 0 | J19: 14 | K19: =IF(L19,"DUPLICATE","") | L19: {=OR(EXACT(A19, $A20:$A$49))} -> FALSE
A20: e | B20: =CODE(A20) -> 101 | C20: !ExitIfNim | D20: Std | E20: CM_NORMAL | F20: ITM_EXPONENT | G20: 15 | H20: [e]xponent | I20: 0 | J20: 15 | K20: =IF(L20,"DUPLICATE","") | L20: {=OR(EXACT(A20, $A21:$A$49))} -> FALSE
A21: = | B21: =CODE(A21) -> 61 | C21: ExitIfNim | D21: C47 | E21: CM_NORMAL | F21: ITM_DRG | G21: -1 | H21: [=]>D,R,G | I21: 1 | K21: =IF(L21,"DUPLICATE","") | L21: {=OR(EXACT(A21, $A22:$A$49))} -> FALSE
A22: y | B22: =CODE(A22) -> 121 | C22: ExitIfNim | D22: C47 | E22: CM_NORMAL | F22: ITM_YX | G22: -1 | H22: [y]^x | I22: 1 | K22: =IF(L22,"DUPLICATE","") | L22: {=OR(EXACT(A22, $A23:$A$49))} -> FALSE
A23: i | B23: =CODE(A23) -> 105 | C23: ExitIfNim | D23: C47 | E23: CM_NORMAL | F23: ITM_op_j | G23: -1 | H23: i | I23: 4 | K23: =IF(L23,"DUPLICATE","") | L23: {=OR(EXACT(A23, $A30:$A$49))} -> FALSE
A24: X | B24: =CODE(A24) -> 88 | C24: ExitIfNim | D24: C47 | E24: CM_NORMAL | F24: KEY_COMPLEX | G24: -1 | H24: comple[X] | I24: 4 | K24: =IF(L24,"DUPLICATE","") | L24: {=OR(EXACT(A24, $A28:$A$49))} -> FALSE
A25: R | B25: =CODE(A25) -> 82 | C25: ExitIfNim | D25: C47 | E25: CM_NORMAL | F25: ITM_toREC2 | G25: -1 | H25: ->R | I25: 4 | K25: =IF(L25,"DUPLICATE","") | L25: {=OR(EXACT(A25, $A28:$A$49))} -> FALSE
A26: P | B26: =CODE(A26) -> 80 | C26: ExitIfNim | D26: C47 | E26: CM_NORMAL | F26: ITM_toPOL2 | G26: -1 | H26: ->P | I26: 4 | K26: =IF(L26,"DUPLICATE","") | L26: {=OR(EXACT(A26, $A31:$A$49))} -> FALSE
A27: p | B27: =CODE(A27) -> 112 | C27: ExitIfNim | D27: C47 | E27: CM_NORMAL | F27: ITM_CONSTpi | G27: -1 | H27: pi | I27: 1 | K27: =IF(L27,"DUPLICATE","") | L27: {=OR(EXACT(A27, $A28:$A$49))} -> FALSE
A28: V | B28: =CODE(A28) -> 86 | C28: ExitIfNim | D28: C47 | E28: CM_NORMAL | F28: ITM_1ONX | G28: -1 | H28: in[V]erse | I28: 1 | K28: =IF(L28,"DUPLICATE","") | L28: {=OR(EXACT(A28, $A29:$A$49))} -> FALSE
A29: Y | B29: =CODE(A29) -> 89 | C29: ExitIfNim | D29: C47 | E29: CM_NORMAL | F29: ITM_XTHROOT | G29: -1 | H29: xth root of [Y] | I29: 2 | K29: =IF(L29,"DUPLICATE","") | L29: {=OR(EXACT(A29, $A30:$A$49))} -> FALSE
A30: C | B30: =CODE(A30) -> 67 | C30: ExitIfNim | D30: C47 | E30: CM_NORMAL | F30: ITM_arccos | G30: -1 | H30: arc[C]osine | I30: 2 | K30: =IF(L30,"DUPLICATE","") | L30: {=OR(EXACT(A30, $A31:$A$49))} -> FALSE
A31: S | B31: =CODE(A31) -> 83 | C31: ExitIfNim | D31: C47 | E31: CM_NORMAL | F31: ITM_arcsin | G31: -1 | H31: arc[S]ine | I31: 2 | K31: =IF(L31,"DUPLICATE","") | L31: {=OR(EXACT(A31, $A32:$A$49))} -> FALSE
A32: T | B32: =CODE(A32) -> 84 | C32: ExitIfNim | D32: C47 | E32: CM_NORMAL | F32: ITM_arctan | G32: -1 | H32: arc[T]angent | I32: 2 | K32: =IF(L32,"DUPLICATE","") | L32: {=OR(EXACT(A32, $A33:$A$49))} -> FALSE
A33: L | B33: =CODE(A33) -> 76 | C33: ExitIfNim | D33: C47 | E33: CM_NORMAL | F33: ITM_EXP | G33: -1 | H33: anti[L]n e^x | I33: 3 | K33: =IF(L33,"DUPLICATE","") | L33: {=OR(EXACT(A33, $A34:$A$49))} -> FALSE
A34: O | B34: =CODE(A34) -> 79 | C34: ExitIfNim | D34: C47 | E34: CM_NORMAL | F34: ITM_10x | G34: -1 | H34: antil[O]g 10^x | I34: 3 | K34: =IF(L34,"DUPLICATE","") | L34: {=OR(EXACT(A34, $A35:$A$49))} -> FALSE
A35: Q | B35: =CODE(A35) -> 81 | C35: ExitIfNim | D35: C47 | E35: CM_NORMAL | F35: ITM_SQUARE | G35: -1 | H35: s[Q]uare | I35: 3 | K35: =IF(L35,"DUPLICATE","") | L35: {=OR(EXACT(A35, $A37:$A$49))} -> FALSE
A36: D | B36: =CODE(A36) -> 68 | C36: ExitIfNim | D36: C47 | E36: CM_NORMAL | F36: ITM_Rup | G36: -1 | H36: Up [D] | I36: 0 | J36: 8 | K36: =IF(L36,"DUPLICATE","") | L36: {=OR(EXACT(A36, $A37:$A$49))} -> FALSE
A37: I | B37: =CODE(A37) -> 73 | C37: !ExitIfNim | D37: C47 | E37: CM_NORMAL | F37: -MNU_DISP | G37: -1 | H37: D[I]SP | I37: 5 | K37: =IF(L37,"DUPLICATE","") | L37: {=OR(EXACT(A37, $A38:$A$49))} -> FALSE
A38: J | B38: =CODE(A38) -> 74 | C38: !ExitIfNim | D38: C47 | E38: CM_NORMAL | F38: -MNU_EXP | G38: -1 | H38: EXP | I38: 5 | K38: =IF(L38,"DUPLICATE","") | L38: {=OR(EXACT(A38, $A39:$A$49))} -> FALSE
A39: K | B39: =CODE(A39) -> 75 | C39: !ExitIfNim | D39: C47 | E39: CM_NORMAL | F39: -MNU_STK | G39: -1 | H39: ST[K] | I39: 5 | K39: =IF(L39,"DUPLICATE","") | L39: {=OR(EXACT(A39, $A40:$A$49))} -> FALSE
A40: M | B40: =CODE(A40) -> 77 | C40: !ExitIfNim | D40: C47 | E40: CM_NORMAL | F40: -MNU_MODE | G40: -1 | H40: [M]ODE | I40: 5 | K40: =IF(L40,"DUPLICATE","") | L40: {=OR(EXACT(A40, $A41:$A$49))} -> FALSE
A41: F | B41: =CODE(A41) -> 70 | C41: !ExitIfNim | D41: C47 | E41: CM_NORMAL | F41: -MNU_PREFIX | G41: -1 | H41: PRE[F]IX | I41: 5 | K41: =IF(L41,"DUPLICATE","") | L41: {=OR(EXACT(A41, $A42:$A$49))} -> FALSE
...

Sheet EXPORT.C
I1: if(shortCutCommand(w, event_keyval, 61, allowCondition, exitIfNim, 9999, KK, CM_NORMAL, ITM_DRG )) {return true;} else //nn = comm
I2: =SUBSTITUTE(SUBSTITUTE(SUBSTITUTE(SUBSTITUTE(SUBSTITUTE(SUBSTITUTE($I$1,"61",A2),"CM_NORMAL",E2),"ITM_DRG",F2),"nn = comm",H2),"exitIfNim",B2),"allowCondition",D2) -> if(shortCutCommand(w, event_keyval, , , , 9999, KK, , )) {return true;} else //
C4: 29
A5: =REPT(" ",Sheet2!$B$3-LEN(Sheet2!B5))&Sheet2!B5 -> 97 | B5: =REPT(" ",Sheet2!$C$3-LEN(Sheet2!C5))&Sheet2!C5 -> ExitIfNim | C5: =IF(Sheet2!D5="Std","FALSE","shortcutProfile == USER_"&Sheet2!D5) -> shortcutProfile == USER_C47 | D5: =REPT( " ",$C$4-LEN(C5) ) &C5 -> shortcutProfile == USER_C47 | E5: =REPT(" ",Sheet2!$E$3-LEN(Sheet2!E5))&Sheet2!E5 -> CM_NORMAL | F5: =REPT(" ",Sheet2!$F$3-LEN(Sheet2!F5))&Sheet2!F5 -> ITM_SIGMAPLUS | G5: =REPT(" ",Sheet2!$G$3-LEN(TEXT(Sheet2!G5,"00")))&""""&TEXT(Sheet2!G5,"00")&"""" -> "00" | H5: =REPT(" ",Sheet2!$H$3-LEN(Sheet2!H5))&Sheet2!H5 -> [a]ccumulate | I5: =IF(Sheet2!B5="","",SUBSTITUTE(SUBSTITUTE(SUBSTITUTE(SUBSTITUTE(SUBSTITUTE(SUBSTITUTE(SUBSTITUTE($I$1,"61",A5),"CM_NORMAL",E5),"ITM_DRG",F5),"nn = comm",H5),"exitIfNim",B5),"allowCondition",D5),"KK",G5)) -> if(shortCutCommand(w, event_keyval, 97, shortcutProfile == USER_C47, ExitIfNim, 9999, "00", CM_NORMAL, ITM_SIGMAPLUS )) {return true;} else // [a]ccumulate
A6: =REPT(" ",Sheet2!$B$3-LEN(Sheet2!B6))&Sheet2!B6 -> 118 | B6: =REPT(" ",Sheet2!$C$3-LEN(Sheet2!C6))&Sheet2!C6 -> ExitIfNim | C6: =IF(Sheet2!D6="Std","FALSE","shortcutProfile == USER_"&Sheet2!D6) -> shortcutProfile == USER_C47 | D6: =REPT( " ",$C$4-LEN(C6) ) &C6 -> shortcutProfile == USER_C47 | E6: =REPT(" ",Sheet2!$E$3-LEN(Sheet2!E6))&Sheet2!E6 -> CM_NORMAL | F6: =REPT(" ",Sheet2!$F$3-LEN(Sheet2!F6))&Sheet2!F6 -> ITM_1ONX | G6: =REPT(" ",Sheet2!$G$3-LEN(TEXT(Sheet2!G6,"00")))&""""&TEXT(Sheet2!G6,"00")&"""" -> "01" | H6: =REPT(" ",Sheet2!$H$3-LEN(Sheet2!H6))&Sheet2!H6 -> in[v]erse | I6: =IF(Sheet2!B6="","",SUBSTITUTE(SUBSTITUTE(SUBSTITUTE(SUBSTITUTE(SUBSTITUTE(SUBSTITUTE(SUBSTITUTE($I$1,"61",A6),"CM_NORMAL",E6),"ITM_DRG",F6),"nn = comm",H6),"exitIfNim",B6),"allowCondition",D6),"KK",G6)) -> if(shortCutCommand(w, event_keyval, 118, shortcutProfile == USER_C47, ExitIfNim, 9999, "01", CM_NORMAL, ITM_1ONX )) {return true;} else // in[v]erse
A7: =REPT(" ",Sheet2!$B$3-LEN(Sheet2!B7))&Sheet2!B7 -> 113 | B7: =REPT(" ",Sheet2!$C$3-LEN(Sheet2!C7))&Sheet2!C7 -> ExitIfNim | C7: =IF(Sheet2!D7="Std","FALSE","shortcutProfile == USER_"&Sheet2!D7) -> shortcutProfile == USER_C47 | D7: =REPT( " ",$C$4-LEN(C7) ) &C7 -> shortcutProfile == USER_C47 | E7: =REPT(" ",Sheet2!$E$3-LEN(Sheet2!E7))&Sheet2!E7 -> CM_NORMAL | F7: =REPT(" ",Sheet2!$F$3-LEN(Sheet2!F7))&Sheet2!F7 -> ITM_SQUAREROOTX | G7: =REPT(" ",Sheet2!$G$3-LEN(TEXT(Sheet2!G7,"00")))&""""&TEXT(Sheet2!G7,"00")&"""" -> "02" | H7: =REPT(" ",Sheet2!$H$3-LEN(Sheet2!H7))&Sheet2!H7 -> s[q]rt | I7: =IF(Sheet2!B7="","",SUBSTITUTE(SUBSTITUTE(SUBSTITUTE(SUBSTITUTE(SUBSTITUTE(SUBSTITUTE(SUBSTITUTE($I$1,"61",A7),"CM_NORMAL",E7),"ITM_DRG",F7),"nn = comm",H7),"exitIfNim",B7),"allowCondition",D7),"KK",G7)) -> if(shortCutCommand(w, event_keyval, 113, shortcutProfile == USER_C47, ExitIfNim, 9999, "02", CM_NORMAL, ITM_SQUAREROOTX )) {return true;} else // s[q]rt
A8: =REPT(" ",Sheet2!$B$3-LEN(Sheet2!B8))&Sheet2!B8 -> 111 | B8: =REPT(" ",Sheet2!$C$3-LEN(Sheet2!C8))&Sheet2!C8 -> ExitIfNim | C8: =IF(Sheet2!D8="Std","FALSE","shortcutProfile == USER_"&Sheet2!D8) -> shortcutProfile == USER_C47 | D8: =REPT( " ",$C$4-LEN(C8) ) &C8 -> shortcutProfile == USER_C47 | E8: =REPT(" ",Sheet2!$E$3-LEN(Sheet2!E8))&Sheet2!E8 -> CM_NORMAL | F8: =REPT(" ",Sheet2!$F$3-LEN(Sheet2!F8))&Sheet2!F8 -> ITM_LOG10 | G8: =REPT(" ",Sheet2!$G$3-LEN(TEXT(Sheet2!G8,"00")))&""""&TEXT(Sheet2!G8,"00")&"""" -> "03" | H8: =REPT(" ",Sheet2!$H$3-LEN(Sheet2!H8))&Sheet2!H8 -> l[o]g | I8: =IF(Sheet2!B8="","",SUBSTITUTE(SUBSTITUTE(SUBSTITUTE(SUBSTITUTE(SUBSTITUTE(SUBSTITUTE(SUBSTITUTE($I$1,"61",A8),"CM_NORMAL",E8),"ITM_DRG",F8),"nn = comm",H8),"exitIfNim",B8),"allowCondition",D8),"KK",G8)) -> if(shortCutCommand(w, event_keyval, 111, shortcutProfile == USER_C47, ExitIfNim, 9999, "03", CM_NORMAL, ITM_LOG10 )) {return true;} else // l[o]g
A9: =REPT(" ",Sheet2!$B$3-LEN(Sheet2!B9))&Sheet2!B9 -> 108 | B9: =REPT(" ",Sheet2!$C$3-LEN(Sheet2!C9))&Sheet2!C9 -> ExitIfNim | C9: =IF(Sheet2!D9="Std","FALSE","shortcutProfile == USER_"&Sheet2!D9) -> shortcutProfile == USER_C47 | D9: =REPT( " ",$C$4-LEN(C9) ) &C9 -> shortcutProfile == USER_C47 | E9: =REPT(" ",Sheet2!$E$3-LEN(Sheet2!E9))&Sheet2!E9 -> CM_NORMAL | F9: =REPT(" ",Sheet2!$F$3-LEN(Sheet2!F9))&Sheet2!F9 -> ITM_LN | G9: =REPT(" ",Sheet2!$G$3-LEN(TEXT(Sheet2!G9,"00")))&""""&TEXT(Sheet2!G9,"00")&"""" -> "04" | H9: =REPT(" ",Sheet2!$H$3-LEN(Sheet2!H9))&Sheet2!H9 -> [l]n | I9: =IF(Sheet2!B9="","",SUBSTITUTE(SUBSTITUTE(SUBSTITUTE(SUBSTITUTE(SUBSTITUTE(SUBSTITUTE(SUBSTITUTE($I$1,"61",A9),"CM_NORMAL",E9),"ITM_DRG",F9),"nn = comm",H9),"exitIfNim",B9),"allowCondition",D9),"KK",G9)) -> if(shortCutCommand(w, event_keyval, 108, shortcutProfile == USER_C47, ExitIfNim, 9999, "04", CM_NORMAL, ITM_LN )) {return true;} else // [l]n
A10: =REPT(" ",Sheet2!$B$3-LEN(Sheet2!B10))&Sheet2!B10 -> 120 | B10: =REPT(" ",Sheet2!$C$3-LEN(Sheet2!C10))&Sheet2!C10 -> ExitIfNim | C10: =IF(Sheet2!D10="Std","FALSE","shortcutProfile == USER_"&Sheet2!D10) -> shortcutProfile == USER_C47 | D10: =REPT( " ",$C$4-LEN(C10) ) &C10 -> shortcutProfile == USER_C47 | E10: =REPT(" ",Sheet2!$E$3-LEN(Sheet2!E10))&Sheet2!E10 -> CM_NORMAL | F10: =REPT(" ",Sheet2!$F$3-LEN(Sheet2!F10))&Sheet2!F10 -> ITM_XEQ | G10: =REPT(" ",Sheet2!$G$3-LEN(TEXT(Sheet2!G10,"00")))&""""&TEXT(Sheet2!G10,"00")&"""" -> "05" | H10: =REPT(" ",Sheet2!$H$3-LEN(Sheet2!H10))&Sheet2!H10 -> [x]eq | I10: =IF(Sheet2!B10="","",SUBSTITUTE(SUBSTITUTE(SUBSTITUTE(SUBSTITUTE(SUBSTITUTE(SUBSTITUTE(SUBSTITUTE($I$1,"61",A10),"CM_NORMAL",E10),"ITM_DRG",F10),"nn = comm",H10),"exitIfNim",B10),"allowCondition",D10),"KK",G10)) -> if(shortCutCommand(w, event_keyval, 120, shortcutProfile == USER_C47, ExitIfNim, 9999, "05", CM_NORMAL, ITM_XEQ )) {return true;} else // [x]eq
A11: =REPT(" ",Sheet2!$B$3-LEN(Sheet2!B11))&Sheet2!B11 -> 109 | B11: =REPT(" ",Sheet2!$C$3-LEN(Sheet2!C11))&Sheet2!C11 -> ExitIfNim | C11: =IF(Sheet2!D11="Std","FALSE","shortcutProfile == USER_"&Sheet2!D11) -> shortcutProfile == USER_C47 | D11: =REPT( " ",$C$4-LEN(C11) ) &C11 -> shortcutProfile == USER_C47 | E11: =REPT(" ",Sheet2!$E$3-LEN(Sheet2!E11))&Sheet2!E11 -> CM_NORMAL | F11: =REPT(" ",Sheet2!$F$3-LEN(Sheet2!F11))&Sheet2!F11 -> ITM_STO | G11: =REPT(" ",Sheet2!$G$3-LEN(TEXT(Sheet2!G11,"00")))&""""&TEXT(Sheet2!G11,"00")&"""" -> "06" | H11: =REPT(" ",Sheet2!$H$3-LEN(Sheet2!H11))&Sheet2!H11 -> [m]emory | I11: =IF(Sheet2!B11="","",SUBSTITUTE(SUBSTITUTE(SUBSTITUTE(SUBSTITUTE(SUBSTITUTE(SUBSTITUTE(SUBSTITUTE($I$1,"61",A11),"CM_NORMAL",E11),"ITM_DRG",F11),"nn = comm",H11),"exitIfNim",B11),"allowCondition",D11),"KK",G11)) -> if(shortCutCommand(w, event_keyval, 109, shortcutProfile == USER_C47, ExitIfNim, 9999, "06", CM_NORMAL, ITM_STO )) {return true;} else // [m]emory
A12: =REPT(" ",Sheet2!$B$3-LEN(Sheet2!B12))&Sheet2!B12 -> 114 | B12: =REPT(" ",Sheet2!$C$3-LEN(Sheet2!C12))&Sheet2!C12 -> ExitIfNim | C12: =IF(Sheet2!D12="Std","FALSE","shortcutProfile == USER_"&Sheet2!D12) -> shortcutProfile == USER_C47 | D12: =REPT( " ",$C$4-LEN(C12) ) &C12 -> shortcutProfile == USER_C47 | E12: =REPT(" ",Sheet2!$E$3-LEN(Sheet2!E12))&Sheet2!E12 -> CM_NORMAL | F12: =REPT(" ",Sheet2!$F$3-LEN(Sheet2!F12))&Sheet2!F12 -> ITM_RCL | G12: =REPT(" ",Sheet2!$G$3-LEN(TEXT(Sheet2!G12,"00")))&""""&TEXT(Sheet2!G12,"00")&"""" -> "07" | H12: =REPT(" ",Sheet2!$H$3-LEN(Sheet2!H12))&Sheet2!H12 -> [r]cl | I12: =IF(Sheet2!B12="","",SUBSTITUTE(SUBSTITUTE(SUBSTITUTE(SUBSTITUTE(SUBSTITUTE(SUBSTITUTE(SUBSTITUTE($I$1,"61",A12),"CM_NORMAL",E12),"ITM_DRG",F12),"nn = comm",H12),"exitIfNim",B12),"allowCondition",D12),"KK",G12)) -> if(shortCutCommand(w, event_keyval, 114, shortcutProfile == USER_C47, ExitIfNim, 9999, "07", CM_NORMAL, ITM_RCL )) {return true;} else // [r]cl
A13: =REPT(" ",Sheet2!$B$3-LEN(Sheet2!B13))&Sheet2!B13 -> 100 | B13: =REPT(" ",Sheet2!$C$3-LEN(Sheet2!C13))&Sheet2!C13 -> ExitIfNim | C13: =IF(Sheet2!D13="Std","FALSE","shortcutProfile == USER_"&Sheet2!D13) -> shortcutProfile == USER_C47 | D13: =REPT( " ",$C$4-LEN(C13) ) &C13 -> shortcutProfile == USER_C47 | E13: =REPT(" ",Sheet2!$E$3-LEN(Sheet2!E13))&Sheet2!E13 -> CM_NORMAL | F13: =REPT(" ",Sheet2!$F$3-LEN(Sheet2!F13))&Sheet2!F13 -> ITM_Rdown | G13: =REPT(" ",Sheet2!$G$3-LEN(TEXT(Sheet2!G13,"00")))&""""&TEXT(Sheet2!G13,"00")&"""" -> "08" | H13: =REPT(" ",Sheet2!$H$3-LEN(Sheet2!H13))&Sheet2!H13 -> [d]own | I13: =IF(Sheet2!B13="","",SUBSTITUTE(SUBSTITUTE(SUBSTITUTE(SUBSTITUTE(SUBSTITUTE(SUBSTITUTE(SUBSTITUTE($I$1,"61",A13),"CM_NORMAL",E13),"ITM_DRG",F13),"nn = comm",H13),"exitIfNim",B13),"allowCondition",D13),"KK",G13)) -> if(shortCutCommand(w, event_keyval, 100, shortcutProfile == USER_C47, ExitIfNim, 9999, "08", CM_NORMAL, ITM_Rdown )) {return true;} else // [d]own
A14: =REPT(" ",Sheet2!$B$3-LEN(Sheet2!B14))&Sheet2!B14 -> 115 | B14: =REPT(" ",Sheet2!$C$3-LEN(Sheet2!C14))&Sheet2!C14 -> ExitIfNim | C14: =IF(Sheet2!D14="Std","FALSE","shortcutProfile == USER_"&Sheet2!D14) -> shortcutProfile == USER_C47 | D14: =REPT( " ",$C$4-LEN(C14) ) &C14 -> shortcutProfile == USER_C47 | E14: =REPT(" ",Sheet2!$E$3-LEN(Sheet2!E14))&Sheet2!E14 -> CM_NORMAL | F14: =REPT(" ",Sheet2!$F$3-LEN(Sheet2!F14))&Sheet2!F14 -> ITM_sin | G14: =REPT(" ",Sheet2!$G$3-LEN(TEXT(Sheet2!G14,"00")))&""""&TEXT(Sheet2!G14,"00")&"""" -> "09" | H14: =REPT(" ",Sheet2!$H$3-LEN(Sheet2!H14))&Sheet2!H14 -> [s]ine | I14: =IF(Sheet2!B14="","",SUBSTITUTE(SUBSTITUTE(SUBSTITUTE(SUBSTITUTE(SUBSTITUTE(SUBSTITUTE(SUBSTITUTE($I$1,"61",A14),"CM_NORMAL",E14),"ITM_DRG",F14),"nn = comm",H14),"exitIfNim",B14),"allowCondition",D14),"KK",G14)) -> if(shortCutCommand(w, event_keyval, 115, shortcutProfile == USER_C47, ExitIfNim, 9999, "09", CM_NORMAL, ITM_sin )) {return true;} else // [s]ine
A15: =REPT(" ",Sheet2!$B$3-LEN(Sheet2!B15))&Sheet2!B15 -> 99 | B15: =REPT(" ",Sheet2!$C$3-LEN(Sheet2!C15))&Sheet2!C15 -> ExitIfNim | C15: =IF(Sheet2!D15="Std","FALSE","shortcutProfile == USER_"&Sheet2!D15) -> shortcutProfile == USER_C47 | D15: =REPT( " ",$C$4-LEN(C15) ) &C15 -> shortcutProfile == USER_C47 | E15: =REPT(" ",Sheet2!$E$3-LEN(Sheet2!E15))&Sheet2!E15 -> CM_NORMAL | F15: =REPT(" ",Sheet2!$F$3-LEN(Sheet2!F15))&Sheet2!F15 -> ITM_cos | G15: =REPT(" ",Sheet2!$G$3-LEN(TEXT(Sheet2!G15,"00")))&""""&TEXT(Sheet2!G15,"00")&"""" -> "10" | H15: =REPT(" ",Sheet2!$H$3-LEN(Sheet2!H15))&Sheet2!H15 -> [c]osine | I15: =IF(Sheet2!B15="","",SUBSTITUTE(SUBSTITUTE(SUBSTITUTE(SUBSTITUTE(SUBSTITUTE(SUBSTITUTE(SUBSTITUTE($I$1,"61",A15),"CM_NORMAL",E15),"ITM_DRG",F15),"nn = comm",H15),"exitIfNim",B15),"allowCondition",D15),"KK",G15)) -> if(shortCutCommand(w, event_keyval, 99, shortcutProfile == USER_C47, ExitIfNim, 9999, "10", CM_NORMAL, ITM_cos )) {return true;} else // [c]osine
A16: =REPT(" ",Sheet2!$B$3-LEN(Sheet2!B16))&Sheet2!B16 -> 116 | B16: =REPT(" ",Sheet2!$C$3-LEN(Sheet2!C16))&Sheet2!C16 -> ExitIfNim | C16: =IF(Sheet2!D16="Std","FALSE","shortcutProfile == USER_"&Sheet2!D16) -> shortcutProfile == USER_C47 | D16: =REPT( " ",$C$4-LEN(C16) ) &C16 -> shortcutProfile == USER_C47 | E16: =REPT(" ",Sheet2!$E$3-LEN(Sheet2!E16))&Sheet2!E16 -> CM_NORMAL | F16: =REPT(" ",Sheet2!$F$3-LEN(Sheet2!F16))&Sheet2!F16 -> ITM_tan | G16: =REPT(" ",Sheet2!$G$3-LEN(TEXT(Sheet2!G16,"00")))&""""&TEXT(Sheet2!G16,"00")&"""" -> "11" | H16: =REPT(" ",Sheet2!$H$3-LEN(Sheet2!H16))&Sheet2!H16 -> [t]angent | I16: =IF(Sheet2!B16="","",SUBSTITUTE(SUBSTITUTE(SUBSTITUTE(SUBSTITUTE(SUBSTITUTE(SUBSTITUTE(SUBSTITUTE($I$1,"61",A16),"CM_NORMAL",E16),"ITM_DRG",F16),"nn = comm",H16),"exitIfNim",B16),"allowCondition",D16),"KK",G16)) -> if(shortCutCommand(w, event_keyval, 116, shortcutProfile == USER_C47, ExitIfNim, 9999, "11", CM_NORMAL, ITM_tan )) {return true;} else // [t]angent
... A90: =REPT(" ",Sheet2!$B$3-LEN(Sheet2!B90))&Sheet2!B90 | B90: =REPT(" ",Sheet2!$C$3-LEN(Sheet2!C90))&Sheet2!C90 | C90: =IF(Sheet2!D90="Std","FALSE","shortcutProfile == USER_"&Sheet2!D90) -> shortcutProfile == USER_ | D90: =REPT( " ",$C$4-LEN(C90) ) &C90 -> shortcutProfile == USER_ | E90: =REPT(" ",Sheet2!$E$3-LEN(Sheet2!E90))&Sheet2!E90 | F90: =REPT(" ",Sheet2!$F$3-LEN(Sheet2!F90))&Sheet2!F90 | G90: =REPT(" ",Sheet2!$G$3-LEN(TEXT(Sheet2!G90,"00")))&""""&TEXT(Sheet2!G90,"00")&"""" -> "00" | H90: =REPT(" ",Sheet2!$H$3-LEN(Sheet2!H90))&Sheet2!H90 | I90: =IF(Sheet2!B90="","",SUBSTITUTE(SUBSTITUTE(SUBSTITUTE(SUBSTITUTE(SUBSTITUTE(SUBSTITUTE(SUBSTITUTE($I$1,"61",A90),"CM_NORMAL",E90),"ITM_DRG",F90),"nn = comm",H90),"exitIfNim",B90),"allowCondition",D90),"KK",G90))
I2241: =IF(AND(OR(#REF!="",ISBLANK(#REF!)),#REF!>0),IF(ISBLANK(#REF!),"",#REF!), IF(#REF!<0,VLOOKUP(#REF!,#REF!,2,0), IF(ISBLANK(#REF!), "", "/* "&TEXT(#REF!,"???0")&" *" &#REF!&", "& IF(#REF!-LEN(#REF!) >= 0, REPT(" ",#REF!-LEN(#REF!)), "") &#REF!&", "& IF(#REF!-LEN(#REF!) >= 0, REPT(" ",#REF!-LEN(#REF!)), "") &#REF!&", "& IF(#REF!-LEN(#REF!) >=0, REPT(" ",#REF!-LEN(#REF!)), "") &#REF!&", "& IF(#REF!-LEN(#REF!) >= 0, REPT(" ",#REF!-LEN(#REF!)+2), "")&"("& SUBSTITUTE(TEXT(#REF!,"??0")," ","")&" << TAM_MAX_BITS) |"& IF(#REF!-3 >= 0, REPT(" ",MAX(1,#REF!-5+4+1-1-LEN( IF(ISTEXT(#REF!),#REF!, SUBSTITUTE(SUBSTITUTE(TEXT(#REF!,"????0")," ","")," ","")) ))), "")& IF(ISTEXT(#REF!),#REF!, SUBSTITUTE(SUBSTITUTE(TEXT(#REF!,"????0")," ","")," ","")) &","& IF(#REF!-3 >= 0, REPT(" ",#REF!-3-5), "") &#REF!& " | "& IF(#REF!-LEN(#REF!) >= 0, REPT(" ",#REF!-LEN(#REF!)), "") &#REF!& IF(#REF!-LEN(#REF!) >= 0, REPT(" ",#REF!-LEN(#REF!)), "")& " | "& IF(#REF!-LEN(#REF!) >= 0, REPT(" ",#REF!-LEN(#REF!)), "") &#REF!& IF(#REF!-LEN(#REF!) >= 0, REPT(" ",#REF!-LEN(#REF!)), "")& " | " &#REF!& IF(#REF!-LEN(#REF!) >= 0, REPT(" ",#REF!-LEN(#REF!)), "")& " | " &#REF!& IF(#REF!-LEN(#REF!) >= 0, REPT(" ",#REF!-LEN(#REF!)), "")& "},"&IF(#REF!<>"",""&#REF!,"") ) ) ) -> #REF!
I2242: =IF(AND(OR(#REF!="",ISBLANK(#REF!)),#REF!>0),IF(ISBLANK(#REF!),"",#REF!), IF(#REF!<0,VLOOKUP(#REF!,#REF!,2,0), IF(ISBLANK(#REF!), "", "/* "&TEXT(#REF!,"???0")&" *" &#REF!&", "& IF(#REF!-LEN(#REF!) >= 0, REPT(" ",#REF!-LEN(#REF!)), "") &#REF!&", "& IF(#REF!-LEN(#REF!) >= 0, REPT(" ",#REF!-LEN(#REF!)), "") &#REF!&", "& IF(#REF!-LEN(#REF!) >=0, REPT(" ",#REF!-LEN(#REF!)), "") &#REF!&", "& IF(#REF!-LEN(#REF!) >= 0, REPT(" ",#REF!-LEN(#REF!)+2), "")&"("& SUBSTITUTE(TEXT(#REF!,"??0")," ","")&" << TAM_MAX_BITS) |"& IF(#REF!-3 >= 0, REPT(" ",MAX(1,#REF!-5+4+1-1-LEN( IF(ISTEXT(#REF!),#REF!, SUBSTITUTE(SUBSTITUTE(TEXT(#REF!,"????0")," ","")," ","")) ))), "")& IF(ISTEXT(#REF!),#REF!, SUBSTITUTE(SUBSTITUTE(TEXT(#REF!,"????0")," ","")," ","")) &","& IF(#REF!-3 >= 0, REPT(" ",#REF!-3-5), "") &#REF!& " | "& IF(#REF!-LEN(#REF!) >= 0, REPT(" ",#REF!-LEN(#REF!)), "") &#REF!& IF(#REF!-LEN(#REF!) >= 0, REPT(" ",#REF!-LEN(#REF!)), "")& " | "& IF(#REF!-LEN(#REF!) >= 0, REPT(" ",#REF!-LEN(#REF!)), "") &#REF!& IF(#REF!-LEN(#REF!) >= 0, REPT(" ",#REF!-LEN(#REF!)), "")& " | " &#REF!& IF(#REF!-LEN(#REF!) >= 0, REPT(" ",#REF!-LEN(#REF!)), "")& " | " &#REF!& IF(#REF!-LEN(#REF!) >= 0, REPT(" ",#REF!-LEN(#REF!)), "")& "},"&IF(#REF!<>"",""&#REF!,"") ) ) ) -> #REF!
I2243: =IF(AND(OR(#REF!="",ISBLANK(#REF!)),#REF!>0),IF(ISBLANK(#REF!),"",#REF!), IF(#REF!<0,VLOOKUP(#REF!,#REF!,2,0), IF(ISBLANK(#REF!), "", "/* "&TEXT(#REF!,"???0")&" *" &#REF!&", "& IF(#REF!-LEN(#REF!) >= 0, REPT(" ",#REF!-LEN(#REF!)), "") &#REF!&", "& IF(#REF!-LEN(#REF!) >= 0, REPT(" ",#REF!-LEN(#REF!)), "") &#REF!&", "& IF(#REF!-LEN(#REF!) >=0, REPT(" ",#REF!-LEN(#REF!)), "") &#REF!&", "& IF(#REF!-LEN(#REF!) >= 0, REPT(" ",#REF!-LEN(#REF!)+2), "")&"("& SUBSTITUTE(TEXT(#REF!,"??0")," ","")&" << TAM_MAX_BITS) |"& IF(#REF!-3 >= 0, REPT(" ",MAX(1,#REF!-5+4+1-1-LEN( IF(ISTEXT(#REF!),#REF!, SUBSTITUTE(SUBSTITUTE(TEXT(#REF!,"????0")," ","")," ","")) ))), "")& IF(ISTEXT(#REF!),#REF!, SUBSTITUTE(SUBSTITUTE(TEXT(#REF!,"????0")," ","")," ","")) &","& IF(#REF!-3 >= 0, REPT(" ",#REF!-3-5), "") &#REF!& " | "& IF(#REF!-LEN(#REF!) >= 0, REPT(" ",#REF!-LEN(#REF!)), "") &#REF!& IF(#REF!-LEN(#REF!) >= 0, REPT(" ",#REF!-LEN(#REF!)), "")& " | "& IF(#REF!-LEN(#REF!) >= 0, REPT(" ",#REF!-LEN(#REF!)), "") &#REF!& IF(#REF!-LEN(#REF!) >= 0, REPT(" ",#REF!-LEN(#REF!)), "")& " | " &#REF!& IF(#REF!-LEN(#REF!) >= 0, REPT(" ",#REF!-LEN(#REF!)), "")& " | " &#REF!& IF(#REF!-LEN(#REF!) >= 0, REPT(" ",#REF!-LEN(#REF!)), "")& "},"&IF(#REF!<>"",""&#REF!,"") ) ) ) -> #REF!
I2244: =IF(AND(OR(#REF!="",ISBLANK(#REF!)),#REF!>0),IF(ISBLANK(#REF!),"",#REF!), IF(#REF!<0,VLOOKUP(#REF!,#REF!,2,0), IF(ISBLANK(#REF!), "", "/* "&TEXT(#REF!,"???0")&" *" &#REF!&", "& IF(#REF!-LEN(#REF!) >= 0, REPT(" ",#REF!-LEN(#REF!)), "") &#REF!&", "& IF(#REF!-LEN(#REF!) >= 0, REPT(" ",#REF!-LEN(#REF!)), "") &#REF!&", "& IF(#REF!-LEN(#REF!) >=0, REPT(" ",#REF!-LEN(#REF!)), "") &#REF!&", "& IF(#REF!-LEN(#REF!) >= 0, REPT(" ",#REF!-LEN(#REF!)+2), "")&"("& SUBSTITUTE(TEXT(#REF!,"??0")," ","")&" << TAM_MAX_BITS) |"& IF(#REF!-3 >= 0, REPT(" ",MAX(1,#REF!-5+4+1-1-LEN( IF(ISTEXT(#REF!),#REF!, SUBSTITUTE(SUBSTITUTE(TEXT(#REF!,"????0")," ","")," ","")) ))), "")& IF(ISTEXT(#REF!),#REF!, SUBSTITUTE(SUBSTITUTE(TEXT(#REF!,"????0")," ","")," ","")) &","& IF(#REF!-3 >= 0, REPT(" ",#REF!-3-5), "") &#REF!& " | "& IF(#REF!-LEN(#REF!) >= 0, REPT(" ",#REF!-LEN(#REF!)), "") &#REF!& IF(#REF!-LEN(#REF!) >= 0, REPT(" ",#REF!-LEN(#REF!)), "")& " | "& IF(#REF!-LEN(#REF!) >= 0, REPT(" ",#REF!-LEN(#REF!)), "") &#REF!& IF(#REF!-LEN(#REF!) >= 0, REPT(" ",#REF!-LEN(#REF!)), "")& " | " &#REF!& IF(#REF!-LEN(#REF!) >= 0, REPT(" ",#REF!-LEN(#REF!)), "")& " | " &#REF!& IF(#REF!-LEN(#REF!) >= 0, REPT(" ",#REF!-LEN(#REF!)), "")& "},"&IF(#REF!<>"",""&#REF!,"") ) ) ) -> #REF!
I2245: =IF(AND(OR(#REF!="",ISBLANK(#REF!)),#REF!>0),IF(ISBLANK(#REF!),"",#REF!), IF(#REF!<0,VLOOKUP(#REF!,#REF!,2,0), IF(ISBLANK(#REF!), "", "/* "&TEXT(#REF!,"???0")&" *" &#REF!&", "& IF(#REF!-LEN(#REF!) >= 0, REPT(" ",#REF!-LEN(#REF!)), "") &#REF!&", "& IF(#REF!-LEN(#REF!) >= 0, REPT(" ",#REF!-LEN(#REF!)), "") &#REF!&", "& IF(#REF!-LEN(#REF!) >=0, REPT(" ",#REF!-LEN(#REF!)), "") &#REF!&", "& IF(#REF!-LEN(#REF!) >= 0, REPT(" ",#REF!-LEN(#REF!)+2), "")&"("& SUBSTITUTE(TEXT(#REF!,"??0")," ","")&" << TAM_MAX_BITS) |"& IF(#REF!-3 >= 0, REPT(" ",MAX(1,#REF!-5+4+1-1-LEN( IF(ISTEXT(#REF!),#REF!, SUBSTITUTE(SUBSTITUTE(TEXT(#REF!,"????0")," ","")," ","")) ))), "")& IF(ISTEXT(#REF!),#REF!, SUBSTITUTE(SUBSTITUTE(TEXT(#REF!,"????0")," ","")," ","")) &","& IF(#REF!-3 >= 0, REPT(" ",#REF!-3-5), "") &#REF!& " | "& IF(#REF!-LEN(#REF!) >= 0, REPT(" ",#REF!-LEN(#REF!)), "") &#REF!& IF(#REF!-LEN(#REF!) >= 0, REPT(" ",#REF!-LEN(#REF!)), "")& " | "& IF(#REF!-LEN(#REF!) >= 0, REPT(" ",#REF!-LEN(#REF!)), "") &#REF!& IF(#REF!-LEN(#REF!) >= 0, REPT(" ",#REF!-LEN(#REF!)), "")& " | " &#REF!& IF(#REF!-LEN(#REF!) >= 0, REPT(" ",#REF!-LEN(#REF!)), "")& " | " &#REF!& IF(#REF!-LEN(#REF!) >= 0, REPT(" ",#REF!-LEN(#REF!)), "")& "},"&IF(#REF!<>"",""&#REF!,"") ) ) ) -> #REF!
I2246: =IF(AND(OR(#REF!="",ISBLANK(#REF!)),#REF!>0),IF(ISBLANK(#REF!),"",#REF!), IF(#REF!<0,VLOOKUP(#REF!,#REF!,2,0), IF(ISBLANK(#REF!), "", "/* "&TEXT(#REF!,"???0")&" *" &#REF!&", "& IF(#REF!-LEN(#REF!) >= 0, REPT(" ",#REF!-LEN(#REF!)), "") &#REF!&", "& IF(#REF!-LEN(#REF!) >= 0, REPT(" ",#REF!-LEN(#REF!)), "") &#REF!&", "& IF(#REF!-LEN(#REF!) >=0, REPT(" ",#REF!-LEN(#REF!)), "") &#REF!&", "& IF(#REF!-LEN(#REF!) >= 0, REPT(" ",#REF!-LEN(#REF!)+2), "")&"("& SUBSTITUTE(TEXT(#REF!,"??0")," ","")&" << TAM_MAX_BITS) |"& IF(#REF!-3 >= 0, REPT(" ",MAX(1,#REF!-5+4+1-1-LEN( IF(ISTEXT(#REF!),#REF!, SUBSTITUTE(SUBSTITUTE(TEXT(#REF!,"????0")," ","")," ","")) ))), "")& IF(ISTEXT(#REF!),#REF!, SUBSTITUTE(SUBSTITUTE(TEXT(#REF!,"????0")," ","")," ","")) &","& IF(#REF!-3 >= 0, REPT(" ",#REF!-3-5), "") &#REF!& " | "& IF(#REF!-LEN(#REF!) >= 0, REPT(" ",#REF!-LEN(#REF!)), "") &#REF!& IF(#REF!-LEN(#REF!) >= 0, REPT(" ",#REF!-LEN(#REF!)), "")& " | "& IF(#REF!-LEN(#REF!) >= 0, REPT(" ",#REF!-LEN(#REF!)), "") &#REF!& IF(#REF!-LEN(#REF!) >= 0, REPT(" ",#REF!-LEN(#REF!)), "")& " | " &#REF!& IF(#REF!-LEN(#REF!) >= 0, REPT(" ",#REF!-LEN(#REF!)), "")& " | " &#REF!& IF(#REF!-LEN(#REF!) >= 0, REPT(" ",#REF!-LEN(#REF!)), "")& "},"&IF(#REF!<>"",""&#REF!,"") ) ) ) -> #REF!
I2247: =IF(AND(OR(#REF!="",ISBLANK(#REF!)),#REF!>0),IF(ISBLANK(#REF!),"",#REF!), IF(#REF!<0,VLOOKUP(#REF!,#REF!,2,0), IF(ISBLANK(#REF!), "", "/* "&TEXT(#REF!,"???0")&" *" &#REF!&", "& IF(#REF!-LEN(#REF!) >= 0, REPT(" ",#REF!-LEN(#REF!)), "") &#REF!&", "& IF(#REF!-LEN(#REF!) >= 0, REPT(" ",#REF!-LEN(#REF!)), "") &#REF!&", "& IF(#REF!-LEN(#REF!) >=0, REPT(" ",#REF!-LEN(#REF!)), "") &#REF!&", "& IF(#REF!-LEN(#REF!) >= 0, REPT(" ",#REF!-LEN(#REF!)+2), "")&"("& SUBSTITUTE(TEXT(#REF!,"??0")," ","")&" << TAM_MAX_BITS) |"& IF(#REF!-3 >= 0, REPT(" ",MAX(1,#REF!-5+4+1-1-LEN( IF(ISTEXT(#REF!),#REF!, SUBSTITUTE(SUBSTITUTE(TEXT(#REF!,"????0")," ","")," ","")) ))), "")& IF(ISTEXT(#REF!),#REF!, SUBSTITUTE(SUBSTITUTE(TEXT(#REF!,"????0")," ","")," ","")) &","& IF(#REF!-3 >= 0, REPT(" ",#REF!-3-5), "") &#REF!& " | "& IF(#REF!-LEN(#REF!) >= 0, REPT(" ",#REF!-LEN(#REF!)), "") &#REF!& IF(#REF!-LEN(#REF!) >= 0, REPT(" ",#REF!-LEN(#REF!)), "")& " | "& IF(#REF!-LEN(#REF!) >= 0, REPT(" ",#REF!-LEN(#REF!)), "") &#REF!& IF(#REF!-LEN(#REF!) >= 0, REPT(" ",#REF!-LEN(#REF!)), "")& " | " &#REF!& IF(#REF!-LEN(#REF!) >= 0, REPT(" ",#REF!-LEN(#REF!)), "")& " | " &#REF!& IF(#REF!-LEN(#REF!) >= 0, REPT(" ",#REF!-LEN(#REF!)), "")& "},"&IF(#REF!<>"",""&#REF!,"") ) ) ) -> #REF!
I2248: =IF(AND(OR(#REF!="",ISBLANK(#REF!)),#REF!>0),IF(ISBLANK(#REF!),"",#REF!), IF(#REF!<0,VLOOKUP(#REF!,#REF!,2,0), IF(ISBLANK(#REF!), "", "/* "&TEXT(#REF!,"???0")&" *" &#REF!&", "& IF(#REF!-LEN(#REF!) >= 0, REPT(" ",#REF!-LEN(#REF!)), "") &#REF!&", "& IF(#REF!-LEN(#REF!) >= 0, REPT(" ",#REF!-LEN(#REF!)), "") &#REF!&", "& IF(#REF!-LEN(#REF!) >=0, REPT(" ",#REF!-LEN(#REF!)), "") &#REF!&", "& IF(#REF!-LEN(#REF!) >= 0, REPT(" ",#REF!-LEN(#REF!)+2), "")&"("& SUBSTITUTE(TEXT(#REF!,"??0")," ","")&" << TAM_MAX_BITS) |"& IF(#REF!-3 >= 0, REPT(" ",MAX(1,#REF!-5+4+1-1-LEN( IF(ISTEXT(#REF!),#REF!, SUBSTITUTE(SUBSTITUTE(TEXT(#REF!,"????0")," ","")," ","")) ))), "")& IF(ISTEXT(#REF!),#REF!, SUBSTITUTE(SUBSTITUTE(TEXT(#REF!,"????0")," ","")," ","")) &","& IF(#REF!-3 >= 0, REPT(" ",#REF!-3-5), "") &#REF!& " | "& IF(#REF!-LEN(#REF!) >= 0, REPT(" ",#REF!-LEN(#REF!)), "") &#REF!& IF(#REF!-LEN(#REF!) >= 0, REPT(" ",#REF!-LEN(#REF!)), "")& " | "& IF(#REF!-LEN(#REF!) >= 0, REPT(" ",#REF!-LEN(#REF!)), "") &#REF!& IF(#REF!-LEN(#REF!) >= 0, REPT(" ",#REF!-LEN(#REF!)), "")& " | " &#REF!& IF(#REF!-LEN(#REF!) >= 0, REPT(" ",#REF!-LEN(#REF!)), "")& " | " &#REF!& IF(#REF!-LEN(#REF!) >= 0, REPT(" ",#REF!-LEN(#REF!)), "")& "},"&IF(#REF!<>"",""&#REF!,"") ) ) ) -> #REF!
I2249: =IF(AND(OR(#REF!="",ISBLANK(#REF!)),#REF!>0),IF(ISBLANK(#REF!),"",#REF!), IF(#REF!<0,VLOOKUP(#REF!,#REF!,2,0), IF(ISBLANK(#REF!), "", "/* "&TEXT(#REF!,"???0")&" *" &#REF!&", "& IF(#REF!-LEN(#REF!) >= 0, REPT(" ",#REF!-LEN(#REF!)), "") &#REF!&", "& IF(#REF!-LEN(#REF!) >= 0, REPT(" ",#REF!-LEN(#REF!)), "") &#REF!&", "& IF(#REF!-LEN(#REF!) >=0, REPT(" ",#REF!-LEN(#REF!)), "") &#REF!&", "& IF(#REF!-LEN(#REF!) >= 0, REPT(" ",#REF!-LEN(#REF!)+2), "")&"("& SUBSTITUTE(TEXT(#REF!,"??0")," ","")&" << TAM_MAX_BITS) |"& IF(#REF!-3 >= 0, REPT(" ",MAX(1,#REF!-5+4+1-1-LEN( IF(ISTEXT(#REF!),#REF!, SUBSTITUTE(SUBSTITUTE(TEXT(#REF!,"????0")," ","")," ","")) ))), "")& IF(ISTEXT(#REF!),#REF!, SUBSTITUTE(SUBSTITUTE(TEXT(#REF!,"????0")," ","")," ","")) &","& IF(#REF!-3 >= 0, REPT(" ",#REF!-3-5), "") &#REF!& " | "& IF(#REF!-LEN(#REF!) >= 0, REPT(" ",#REF!-LEN(#REF!)), "") &#REF!& IF(#REF!-LEN(#REF!) >= 0, REPT(" ",#REF!-LEN(#REF!)), "")& " | "& IF(#REF!-LEN(#REF!) >= 0, REPT(" ",#REF!-LEN(#REF!)), "") &#REF!& IF(#REF!-LEN(#REF!) >= 0, REPT(" ",#REF!-LEN(#REF!)), "")& " | " &#REF!& IF(#REF!-LEN(#REF!) >= 0, REPT(" ",#REF!-LEN(#REF!)), "")& " | " &#REF!& IF(#REF!-LEN(#REF!) >= 0, REPT(" ",#REF!-LEN(#REF!)), "")& "},"&IF(#REF!<>"",""&#REF!,"") ) ) ) -> #REF!
I2250: =IF(AND(OR(#REF!="",ISBLANK(#REF!)),#REF!>0),IF(ISBLANK(#REF!),"",#REF!), IF(#REF!<0,VLOOKUP(#REF!,#REF!,2,0), IF(ISBLANK(#REF!), "", "/* "&TEXT(#REF!,"???0")&" *" &#REF!&", "& IF(#REF!-LEN(#REF!) >= 0, REPT(" ",#REF!-LEN(#REF!)), "") &#REF!&", "& IF(#REF!-LEN(#REF!) >= 0, REPT(" ",#REF!-LEN(#REF!)), "") &#REF!&", "& IF(#REF!-LEN(#REF!) >=0, REPT(" ",#REF!-LEN(#REF!)), "") &#REF!&", "& IF(#REF!-LEN(#REF!) >= 0, REPT(" ",#REF!-LEN(#REF!)+2), "")&"("& SUBSTITUTE(TEXT(#REF!,"??0")," ","")&" << TAM_MAX_BITS) |"& IF(#REF!-3 >= 0, REPT(" ",MAX(1,#REF!-5+4+1-1-LEN( IF(ISTEXT(#REF!),#REF!, SUBSTITUTE(SUBSTITUTE(TEXT(#REF!,"????0")," ","")," ","")) ))), "")& IF(ISTEXT(#REF!),#REF!, SUBSTITUTE(SUBSTITUTE(TEXT(#REF!,"????0")," ","")," ","")) &","& IF(#REF!-3 >= 0, REPT(" ",#REF!-3-5), "") &#REF!& " | "& IF(#REF!-LEN(#REF!) >= 0, REPT(" ",#REF!-LEN(#REF!)), "") &#REF!& IF(#REF!-LEN(#REF!) >= 0, REPT(" ",#REF!-LEN(#REF!)), "")& " | "& IF(#REF!-LEN(#REF!) >= 0, REPT(" ",#REF!-LEN(#REF!)), "") &#REF!& IF(#REF!-LEN(#REF!) >= 0, REPT(" ",#REF!-LEN(#REF!)), "")& " | " &#REF!& IF(#REF!-LEN(#REF!) >= 0, REPT(" ",#REF!-LEN(#REF!)), "")& " | " &#REF!& IF(#REF!-LEN(#REF!) >= 0, REPT(" ",#REF!-LEN(#REF!)), "")& "},"&IF(#REF!<>"",""&#REF!,"") ) ) ) -> #REF!
I2251: =IF(AND(OR(#REF!="",ISBLANK(#REF!)),#REF!>0),IF(ISBLANK(#REF!),"",#REF!), IF(#REF!<0,VLOOKUP(#REF!,#REF!,2,0), IF(ISBLANK(#REF!), "", "/* "&TEXT(#REF!,"???0")&" *" &#REF!&", "& IF(#REF!-LEN(#REF!) >= 0, REPT(" ",#REF!-LEN(#REF!)), "") &#REF!&", "& IF(#REF!-LEN(#REF!) >= 0, REPT(" ",#REF!-LEN(#REF!)), "") &#REF!&", "& IF(#REF!-LEN(#REF!) >=0, REPT(" ",#REF!-LEN(#REF!)), "") &#REF!&", "& IF(#REF!-LEN(#REF!) >= 0, REPT(" ",#REF!-LEN(#REF!)+2), "")&"("& SUBSTITUTE(TEXT(#REF!,"??0")," ","")&" << TAM_MAX_BITS) |"& IF(#REF!-3 >= 0, REPT(" ",MAX(1,#REF!-5+4+1-1-LEN( IF(ISTEXT(#REF!),#REF!, SUBSTITUTE(SUBSTITUTE(TEXT(#REF!,"????0")," ","")," ","")) ))), "")& IF(ISTEXT(#REF!),#REF!, SUBSTITUTE(SUBSTITUTE(TEXT(#REF!,"????0")," ","")," ","")) &","& IF(#REF!-3 >= 0, REPT(" ",#REF!-3-5), "") &#REF!& " | "& IF(#REF!-LEN(#REF!) >= 0, REPT(" ",#REF!-LEN(#REF!)), "") &#REF!& IF(#REF!-LEN(#REF!) >= 0, REPT(" ",#REF!-LEN(#REF!)), "")& " | "& IF(#REF!-LEN(#REF!) >= 0, REPT(" ",#REF!-LEN(#REF!)), "") &#REF!& IF(#REF!-LEN(#REF!) >= 0, REPT(" ",#REF!-LEN(#REF!)), "")& " | " &#REF!& IF(#REF!-LEN(#REF!) >= 0, REPT(" ",#REF!-LEN(#REF!)), "")& " | " &#REF!& IF(#REF!-LEN(#REF!) >= 0, REPT(" ",#REF!-LEN(#REF!)), "")& "},"&IF(#REF!<>"",""&#REF!,"") ) ) ) -> #REF!
I2252: =IF(AND(OR(#REF!="",ISBLANK(#REF!)),#REF!>0),IF(ISBLANK(#REF!),"",#REF!), IF(#REF!<0,VLOOKUP(#REF!,#REF!,2,0), IF(ISBLANK(#REF!), "", "/* "&TEXT(#REF!,"???0")&" *" &#REF!&", "& IF(#REF!-LEN(#REF!) >= 0, REPT(" ",#REF!-LEN(#REF!)), "") &#REF!&", "& IF(#REF!-LEN(#REF!) >= 0, REPT(" ",#REF!-LEN(#REF!)), "") &#REF!&", "& IF(#REF!-LEN(#REF!) >=0, REPT(" ",#REF!-LEN(#REF!)), "") &#REF!&", "& IF(#REF!-LEN(#REF!) >= 0, REPT(" ",#REF!-LEN(#REF!)+2), "")&"("& SUBSTITUTE(TEXT(#REF!,"??0")," ","")&" << TAM_MAX_BITS) |"& IF(#REF!-3 >= 0, REPT(" ",MAX(1,#REF!-5+4+1-1-LEN( IF(ISTEXT(#REF!),#REF!, SUBSTITUTE(SUBSTITUTE(TEXT(#REF!,"????0")," ","")," ","")) ))), "")& IF(ISTEXT(#REF!),#REF!, SUBSTITUTE(SUBSTITUTE(TEXT(#REF!,"????0")," ","")," ","")) &","& IF(#REF!-3 >= 0, REPT(" ",#REF!-3-5), "") &#REF!& " | "& IF(#REF!-LEN(#REF!) >= 0, REPT(" ",#REF!-LEN(#REF!)), "") &#REF!& IF(#REF!-LEN(#REF!) >= 0, REPT(" ",#REF!-LEN(#REF!)), "")& " | "& IF(#REF!-LEN(#REF!) >= 0, REPT(" ",#REF!-LEN(#REF!)), "") &#REF!& IF(#REF!-LEN(#REF!) >= 0, REPT(" ",#REF!-LEN(#REF!)), "")& " | " &#REF!& IF(#REF!-LEN(#REF!) >= 0, REPT(" ",#REF!-LEN(#REF!)), "")& " | " &#REF!& IF(#REF!-LEN(#REF!) >= 0, REPT(" ",#REF!-LEN(#REF!)), "")& "},"&IF(#REF!<>"",""&#REF!,"") ) ) ) -> #REF!
... I2641: =IF(AND(OR(#REF!="",ISBLANK(#REF!)),#REF!>0),IF(ISBLANK(#REF!),"",#REF!), IF(#REF!<0,VLOOKUP(#REF!,#REF!,2,0), IF(ISBLANK(#REF!), "", "/* "&TEXT(#REF!,"???0")&" *" &#REF!&", "& IF(#REF!-LEN(#REF!) >= 0, REPT(" ",#REF!-LEN(#REF!)), "") &#REF!&", "& IF(#REF!-LEN(#REF!) >= 0, REPT(" ",#REF!-LEN(#REF!)), "") &#REF!&", "& IF(#REF!-LEN(#REF!) >=0, REPT(" ",#REF!-LEN(#REF!)), "") &#REF!&", "& IF(#REF!-LEN(#REF!) >= 0, REPT(" ",#REF!-LEN(#REF!)+2), "")&"("& SUBSTITUTE(TEXT(#REF!,"??0")," ","")&" << TAM_MAX_BITS) |"& IF(#REF!-3 >= 0, REPT(" ",MAX(1,#REF!-5+4+1-1-LEN( IF(ISTEXT(#REF!),#REF!, SUBSTITUTE(SUBSTITUTE(TEXT(#REF!,"????0")," ","")," ","")) ))), "")& IF(ISTEXT(#REF!),#REF!, SUBSTITUTE(SUBSTITUTE(TEXT(#REF!,"????0")," ","")," ","")) &","& IF(#REF!-3 >= 0, REPT(" ",#REF!-3-5), "") &#REF!& " | "& IF(#REF!-LEN(#REF!) >= 0, REPT(" ",#REF!-LEN(#REF!)), "") &#REF!& IF(#REF!-LEN(#REF!) >= 0, REPT(" ",#REF!-LEN(#REF!)), "")& " | "& IF(#REF!-LEN(#REF!) >= 0, REPT(" ",#REF!-LEN(#REF!)), "") &#REF!& IF(#REF!-LEN(#REF!) >= 0, REPT(" ",#REF!-LEN(#REF!)), "")& " | " &#REF!& IF(#REF!-LEN(#REF!) >= 0, REPT(" ",#REF!-LEN(#REF!)), "")& " | " &#REF!& IF(#REF!-LEN(#REF!) >= 0, REPT(" ",#REF!-LEN(#REF!)), "")& "},"&IF(#REF!<>"",""&#REF!,"") ) ) ) -> #REF!
