Workbook
Name CRLF: Sheet2!$B$1

Sheet Sheet2
B1: PC Keyboard codes: | D1: https://docs.oracle.com/cd/E67482_01/oscar/pdf/45/OnlineHelp_45/helpOnPS2keyCodes.html
B3: 5 | C3: 10 | E3: 10 | F3: 17 | G3: 20 | H3: 4 | I3: 30
B4: PC Key Code | C4: Exit If NIM | D4: Calculator C47/R47/Std | E4: Calculator Mode | F4: Disable condition | G4: Function to run | H4: Key n to run (from 0-37) Key overrides function Key overrides ExitIfNim ?? Negative is off | I4: Comment | K4: Free42 | L4: Duplicate | M4: Duplicate calc
A5: a | B5: =CODE(A5) -> 97 | C5: ExitIfNim | D5: C47 | E5: CM_NORMAL | F5: tam.mode | G5: ITM_SIGMAPLUS | H5: 0 | I5: [a]ccumulate | J5: 1 | K5: 0 | L5: =IF(M5,"DUPLICATE","") | M5: {=OR(EXACT(A5, $A6:$A$49))} -> FALSE
A6: v | B6: =CODE(A6) -> 118 | C6: ExitIfNim | D6: C47 | E6: CM_NORMAL | F6: tam.mode | G6: ITM_1ONX | H6: 1 | I6: in[v]erse | J6: 1 | K6: 1 | L6: =IF(M6,"DUPLICATE","") | M6: {=OR(EXACT(A6, $A7:$A$49))} -> FALSE
A7: q | B7: =CODE(A7) -> 113 | C7: ExitIfNim | D7: C47 | E7: CM_NORMAL | F7: tam.mode | G7: ITM_SQUAREROOTX | H7: 2 | I7: s[q]rt | J7: 3 | K7: 2 | L7: =IF(M7,"DUPLICATE","") | M7: {=OR(EXACT(A7, $A8:$A$49))} -> FALSE
A8: o | B8: =CODE(A8) -> 111 | C8: ExitIfNim | D8: C47 | E8: CM_NORMAL | F8: tam.mode | G8: ITM_LOG10 | H8: 3 | I8: l[o]g | J8: 3 | K8: 3 | L8: =IF(M8,"DUPLICATE","") | M8: {=OR(EXACT(A8, $A9:$A$49))} -> FALSE
A9: l | B9: =CODE(A9) -> 108 | C9: ExitIfNim | D9: C47 | E9: CM_NORMAL | F9: tam.mode | G9: ITM_LN | H9: 4 | I9: [l]n | J9: 3 | K9: 4 | L9: =IF(M9,"DUPLICATE","") | M9: {=OR(EXACT(A9, $A10:$A$49))} -> FALSE
A10: x | B10: =CODE(A10) -> 120 | C10: !ExitIfNim | D10: C47 | E10: CM_NORMAL | F10: FALSE | G10: ITM_XEQ | H10: 5 | I10: [x]eq | J10: 0 | K10: 5 | L10: =IF(M10,"DUPLICATE","") | M10: {=OR(EXACT(A10, $A11:$A$49))} -> FALSE
A11: m | B11: =CODE(A11) -> 109 | C11: ExitIfNim | D11: C47 | E11: CM_NORMAL | F11: tam.mode | G11: ITM_STO | H11: 6 | I11: [m]emory | J11: 0 | K11: 6 | L11: =IF(M11,"DUPLICATE","") | M11: {=OR(EXACT(A11, $A12:$A$49))} -> FALSE
A12: r | B12: =CODE(A12) -> 114 | C12: ExitIfNim | D12: C47 | E12: CM_NORMAL | F12: tam.mode | G12: ITM_RCL | H12: 7 | I12: [r]cl | J12: 0 | K12: 7 | L12: =IF(M12,"DUPLICATE","") | M12: {=OR(EXACT(A12, $A13:$A$49))} -> FALSE
A13: d | B13: =CODE(A13) -> 100 | C13: ExitIfNim | D13: C47 | E13: CM_NORMAL | F13: tam.mode | G13: ITM_Rdown | H13: 8 | I13: [d]own | J13: 0 | K13: 8 | L13: =IF(M13,"DUPLICATE","") | M13: {=OR(EXACT(A13, $A14:$A$49))} -> FALSE
A14: s | B14: =CODE(A14) -> 115 | C14: ExitIfNim | D14: C47 | E14: CM_NORMAL | F14: tam.mode | G14: ITM_sin | H14: 9 | I14: [s]ine | J14: 2 | K14: 9 | L14: =IF(M14,"DUPLICATE","") | M14: {=OR(EXACT(A14, $A15:$A$49))} -> FALSE
A15: c | B15: =CODE(A15) -> 99 | C15: ExitIfNim | D15: C47 | E15: CM_NORMAL | F15: tam.mode | G15: ITM_cos | H15: 10 | I15: [c]osine | J15: 2 | K15: 10 | L15: =IF(M15,"DUPLICATE","") | M15: {=OR(EXACT(A15, $A16:$A$49))} -> FALSE
A16: t | B16: =CODE(A16) -> 116 | C16: ExitIfNim | D16: C47 | E16: CM_NORMAL | F16: tam.mode | G16: ITM_tan | H16: 11 | I16: [t]angent | J16: 2 | K16: 11 | L16: =IF(M16,"DUPLICATE","") | M16: {=OR(EXACT(A16, $A17:$A$49))} -> FALSE
A17: ENTER | B17: 65421 | C17: !ExitIfNim | D17: Std | E17: CM_NORMAL | F17: FALSE | G17: ITM_ENTER | H17: 12 | I17: key | J17: 0 | K17: 12 | L17: =IF(M17,"DUPLICATE","") | M17: {=OR(EXACT(A17, $A18:$A$49))} -> FALSE
A18: w | B18: =CODE(A18) -> 119 | C18: !ExitIfNim | D18: Std | E18: CM_NORMAL | F18: tam.mode | G18: ITM_XexY | H18: 13 | I18: s[w]ap | J18: 0 | K18: 13 | L18: =IF(M18,"DUPLICATE","") | M18: {=OR(EXACT(A18, $A19:$A$49))} -> FALSE
A19: n | B19: =CODE(A19) -> 110 | C19: !ExitIfNim | D19: Std | E19: CM_NORMAL | F19: tam.mode | G19: ITM_CHS | H19: 14 | I19: CHS [n]egative | J19: 0 | K19: 14 | L19: =IF(M19,"DUPLICATE","") | M19: {=OR(EXACT(A19, $A20:$A$49))} -> FALSE
A20: e | B20: =CODE(A20) -> 101 | C20: !ExitIfNim | D20: Std | E20: CM_NORMAL | F20: tam.mode | G20: ITM_EXPONENT | H20: 15 | I20: [e]xponent | J20: 0 | K20: 15 | L20: =IF(M20,"DUPLICATE","") | M20: {=OR(EXACT(A20, $A21:$A$49))} -> FALSE
A21: = | B21: =CODE(A21) -> 61 | C21: ExitIfNim | D21: C47 | E21: CM_NORMAL | F21: tam.mode | G21: ITM_DRG | H21: -1 | I21: [=]>D,R,G | J21: 1 | L21: =IF(M21,"DUPLICATE","") | M21: {=OR(EXACT(A21, $A22:$A$49))} -> FALSE
A22: Y | B22: =CODE(A22) -> 89 | C22: ExitIfNim | D22: C47 | E22: CM_NORMAL | F22: tam.mode | G22: ITM_YX | H22: -1 | I22: [y]^x | J22: 1 | L22: =IF(M22,"DUPLICATE","") | M22: {=OR(EXACT(A22, $A23:$A$49))} -> FALSE
A23: i | B23: =CODE(A23) -> 105 | C23: ExitIfNim | D23: C47 | E23: CM_NORMAL | F23: tam.mode | G23: ITM_op_j | H23: -1 | I23: i | J23: 4 | L23: =IF(M23,"DUPLICATE","") | M23: {=OR(EXACT(A23, $A30:$A$49))} -> FALSE
A24: X | B24: =CODE(A24) -> 88 | C24: ExitIfNim | D24: C47 | E24: CM_NORMAL | F24: tam.mode | G24: KEY_COMPLEX | H24: -1 | I24: comple[X] | J24: 4 | L24: =IF(M24,"DUPLICATE","") | M24: {=OR(EXACT(A24, $A28:$A$49))} -> FALSE
A25: R | B25: =CODE(A25) -> 82 | C25: ExitIfNim | D25: C47 | E25: CM_NORMAL | F25: tam.mode | G25: ITM_toREC2 | H25: -1 | I25: ->R | J25: 4 | L25: =IF(M25,"DUPLICATE","") | M25: {=OR(EXACT(A25, $A28:$A$49))} -> FALSE
A26: P | B26: =CODE(A26) -> 80 | C26: ExitIfNim | D26: C47 | E26: CM_NORMAL | F26: tam.mode | G26: ITM_toPOL2 | H26: -1 | I26: ->P | J26: 4 | L26: =IF(M26,"DUPLICATE","") | M26: {=OR(EXACT(A26, $A31:$A$49))} -> FALSE
A27: p | B27: =CODE(A27) -> 112 | C27: ExitIfNim | D27: C47 | E27: CM_NORMAL | F27: tam.mode | G27: ITM_CONSTpi | H27: -1 | I27: pi | J27: 1 | L27: =IF(M27,"DUPLICATE","") | M27: {=OR(EXACT(A27, $A28:$A$49))} -> FALSE
A28: V | B28: =CODE(A28) -> 86 | C28: ExitIfNim | D28: C47 | E28: CM_NORMAL | F28: tam.mode | G28: ITM_1ONX | H28: -1 | I28: in[V]erse | J28: 1 | L28: =IF(M28,"DUPLICATE","") | M28: {=OR(EXACT(A28, $A29:$A$49))} -> FALSE
A29: y | B29: =CODE(A29) -> 121 | C29: ExitIfNim | D29: C47 | E29: CM_NORMAL | F29: tam.mode | G29: ITM_XTHROOT | H29: -1 | I29: xth root of [Y] | J29: 2 | L29: =IF(M29,"DUPLICATE","") | M29: {=OR(EXACT(A29, $A30:$A$49))} -> FALSE
A30: C | B30: =CODE(A30) -> 67 | C30: ExitIfNim | D30: C47 | E30: CM_NORMAL | F30: tam.mode | G30: ITM_arccos | H30: -1 | I30: arc[C]osine | J30: 2 | L30: =IF(M30,"DUPLICATE","") | M30: {=OR(EXACT(A30, $A31:$A$49))} -> FALSE
A31: S | B31: =CODE(A31) -> 83 | C31: ExitIfNim | D31: C47 | E31: CM_NORMAL | F31: tam.mode | G31: ITM_arcsin | H31: -1 | I31: arc[S]ine | J31: 2 | L31: =IF(M31,"DUPLICATE","") | M31: {=OR(EXACT(A31, $A32:$A$49))} -> FALSE
A32: T | B32: =CODE(A32) -> 84 | C32: ExitIfNim | D32: C47 | E32: CM_NORMAL | F32: tam.mode | G32: ITM_arctan | H32: -1 | I32: arc[T]angent | J32: 2 | L32: =IF(M32,"DUPLICATE","") | M32: {=OR(EXACT(A32, $A33:$A$49))} -> FALSE
A33: L | B33: =CODE(A33) -> 76 | C33: ExitIfNim | D33: C47 | E33: CM_NORMAL | F33: tam.mode | G33: ITM_EXP | H33: -1 | I33: anti[L]n e^x | J33: 3 | L33: =IF(M33,"DUPLICATE","") | M33: {=OR(EXACT(A33, $A34:$A$49))} -> FALSE
A34: O | B34: =CODE(A34) -> 79 | C34: ExitIfNim | D34: C47 | E34: CM_NORMAL | F34: tam.mode | G34: ITM_10x | H34: -1 | I34: antil[O]g 10^x | J34: 3 | L34: =IF(M34,"DUPLICATE","") | M34: {=OR(EXACT(A34, $A35:$A$49))} -> FALSE
A35: Q | B35: =CODE(A35) -> 81 | C35: ExitIfNim | D35: C47 | E35: CM_NORMAL | F35: tam.mode | G35: ITM_SQUARE | H35: -1 | I35: s[Q]uare | J35: 3 | L35: =IF(M35,"DUPLICATE","") | M35: {=OR(EXACT(A35, $A37:$A$49))} -> FALSE
A36: D | B36: =CODE(A36) -> 68 | C36: ExitIfNim | D36: C47 | E36: CM_NORMAL | F36: tam.mode | G36: ITM_Rup | H36: -1 | I36: Up [D] | J36: 0 | K36: 8 | L36: =IF(M36,"DUPLICATE","") | M36: {=OR(EXACT(A36, $A37:$A$49))} -> FALSE
A37: I | B37: =CODE(A37) -> 73 | C37: !ExitIfNim | D37: C47 | E37: CM_NORMAL | F37: FALSE | G37: -MNU_DISP | H37: -1 | I37: D[I]SP | J37: 5 | L37: =IF(M37,"DUPLICATE","") | M37: {=OR(EXACT(A37, $A38:$A$49))} -> FALSE
A38: J | B38: =CODE(A38) -> 74 | C38: !ExitIfNim | D38: C47 | E38: CM_NORMAL | F38: FALSE | G38: -MNU_EXP | H38: -1 | I38: EXP | J38: 5 | L38: =IF(M38,"DUPLICATE","") | M38: {=OR(EXACT(A38, $A39:$A$49))} -> FALSE
A39: K | B39: =CODE(A39) -> 75 | C39: !ExitIfNim | D39: C47 | E39: CM_NORMAL | F39: FALSE | G39: -MNU_STK | H39: -1 | I39: ST[K] | J39: 5 | L39: =IF(M39,"DUPLICATE","") | M39: {=OR(EXACT(A39, $A40:$A$49))} -> FALSE
A40: M | B40: =CODE(A40) -> 77 | C40: !ExitIfNim | D40: C47 | E40: CM_NORMAL | F40: FALSE | G40: -MNU_MODE | H40: -1 | I40: [M]ODE | J40: 5 | L40: =IF(M40,"DUPLICATE","") | M40: {=OR(EXACT(A40, $A41:$A$49))} -> FALSE
A41: F | B41: =CODE(A41) -> 70 | C41: !ExitIfNim | D41: C47 | E41: CM_NORMAL | F41: FALSE | G41: -MNU_PREFIX | H41: -1 | I41: PRE[F]IX | J41: 5 | L41: =IF(M41,"DUPLICATE","") | M41: {=OR(EXACT(A41, $A42:$A$49))} -> FALSE
...

Sheet EXPORT.C
J1: if(shortCutCommand(w, event_keyval, 61, allowCondition, exitIfNim, 9999, KK, CM_NORMAL, ITM_DRG )) {return true;} else //nn = comm
J2: =SUBSTITUTE(SUBSTITUTE(SUBSTITUTE(SUBSTITUTE(SUBSTITUTE(SUBSTITUTE($J$1,"61",A2),"CM_NORMAL",E2),"ITM_DRG",G2),"nn = comm",I2),"exitIfNim",B2),"allowCondition",D2) -> if(shortCutCommand(w, event_keyval, , , , 9999, KK, , )) {return true;} else //
C4: 29
A5: =REPT(" ",Sheet2!$B$3-LEN(Sheet2!B5))&Sheet2!B5 -> 97 | B5: =REPT(" ",Sheet2!$C$3-LEN(Sheet2!C5))&Sheet2!C5 -> ExitIfNim | C5: =IF(Sheet2!D5="Std","FALSE","shortcutProfile == USER_"&Sheet2!D5) -> shortcutProfile == USER_C47 | D5: =REPT( " ",$C$4-LEN(C5) ) &C5 -> shortcutProfile == USER_C47 | E5: =REPT(" ",Sheet2!$E$3-LEN(Sheet2!E5))&Sheet2!E5 -> CM_NORMAL | F5: =REPT(" ",Sheet2!$E$3-LEN(Sheet2!F5))&Sheet2!F5 -> tam.mode | G5: =REPT(" ",Sheet2!$G$3-LEN(Sheet2!G5))&Sheet2!G5 -> ITM_SIGMAPLUS | H5: =REPT(" ",Sheet2!$H$3-LEN(TEXT(Sheet2!H5,"00")))&""""&TEXT(Sheet2!H5,"00")&"""" -> "00" | I5: =REPT(" ",Sheet2!$I$3-LEN(Sheet2!I5))&Sheet2!I5 -> [a]ccumulate | J5: =IF(Sheet2!B5="","",SUBSTITUTE(SUBSTITUTE(SUBSTITUTE(SUBSTITUTE(SUBSTITUTE(SUBSTITUTE(SUBSTITUTE(SUBSTITUTE($J$1,"61",A5),"CM_NORMAL",E5),"ITM_DRG",G5),"nn = comm",I5),"exitIfNim",B5),"allowCondition",D5),"KK",H5),"9999",F5)) -> if(shortCutCommand(w, event_keyval, 97, shortcutProfile == USER_C47, ExitIfNim, tam.mode, "00", CM_NORMAL, ITM_SIGMAPLUS )) {return true;} else // [a]ccumulate
A6: =REPT(" ",Sheet2!$B$3-LEN(Sheet2!B6))&Sheet2!B6 -> 118 | B6: =REPT(" ",Sheet2!$C$3-LEN(Sheet2!C6))&Sheet2!C6 -> ExitIfNim | C6: =IF(Sheet2!D6="Std","FALSE","shortcutProfile == USER_"&Sheet2!D6) -> shortcutProfile == USER_C47 | D6: =REPT( " ",$C$4-LEN(C6) ) &C6 -> shortcutProfile == USER_C47 | E6: =REPT(" ",Sheet2!$E$3-LEN(Sheet2!E6))&Sheet2!E6 -> CM_NORMAL | F6: =REPT(" ",Sheet2!$E$3-LEN(Sheet2!F6))&Sheet2!F6 -> tam.mode | G6: =REPT(" ",Sheet2!$G$3-LEN(Sheet2!G6))&Sheet2!G6 -> ITM_1ONX | H6: =REPT(" ",Sheet2!$H$3-LEN(TEXT(Sheet2!H6,"00")))&""""&TEXT(Sheet2!H6,"00")&"""" -> "01" | I6: =REPT(" ",Sheet2!$I$3-LEN(Sheet2!I6))&Sheet2!I6 -> in[v]erse | J6: =IF(Sheet2!B6="","",SUBSTITUTE(SUBSTITUTE(SUBSTITUTE(SUBSTITUTE(SUBSTITUTE(SUBSTITUTE(SUBSTITUTE(SUBSTITUTE($J$1,"61",A6),"CM_NORMAL",E6),"ITM_DRG",G6),"nn = comm",I6),"exitIfNim",B6),"allowCondition",D6),"KK",H6),"9999",F6)) -> if(shortCutCommand(w, event_keyval, 118, shortcutProfile == USER_C47, ExitIfNim, tam.mode, "01", CM_NORMAL, ITM_1ONX )) {return true;} else // in[v]erse
A7: =REPT(" ",Sheet2!$B$3-LEN(Sheet2!B7))&Sheet2!B7 -> 113 | B7: =REPT(" ",Sheet2!$C$3-LEN(Sheet2!C7))&Sheet2!C7 -> ExitIfNim | C7: =IF(Sheet2!D7="Std","FALSE","shortcutProfile == USER_"&Sheet2!D7) -> shortcutProfile == USER_C47 | D7: =REPT( " ",$C$4-LEN(C7) ) &C7 -> shortcutProfile == USER_C47 | E7: =REPT(" ",Sheet2!$E$3-LEN(Sheet2!E7))&Sheet2!E7 -> CM_NORMAL | F7: =REPT(" ",Sheet2!$E$3-LEN(Sheet2!F7))&Sheet2!F7 -> tam.mode | G7: =REPT(" ",Sheet2!$G$3-LEN(Sheet2!G7))&Sheet2!G7 -> ITM_SQUAREROOTX | H7: =REPT(" ",Sheet2!$H$3-LEN(TEXT(Sheet2!H7,"00")))&""""&TEXT(Sheet2!H7,"00")&"""" -> "02" | I7: =REPT(" ",Sheet2!$I$3-LEN(Sheet2!I7))&Sheet2!I7 -> s[q]rt | J7: =IF(Sheet2!B7="","",SUBSTITUTE(SUBSTITUTE(SUBSTITUTE(SUBSTITUTE(SUBSTITUTE(SUBSTITUTE(SUBSTITUTE(SUBSTITUTE($J$1,"61",A7),"CM_NORMAL",E7),"ITM_DRG",G7),"nn = comm",I7),"exitIfNim",B7),"allowCondition",D7),"KK",H7),"9999",F7)) -> if(shortCutCommand(w, event_keyval, 113, shortcutProfile == USER_C47, ExitIfNim, tam.mode, "02", CM_NORMAL, ITM_SQUAREROOTX )) {return true;} else // s[q]rt
A8: =REPT(" ",Sheet2!$B$3-LEN(Sheet2!B8))&Sheet2!B8 -> 111 | B8: =REPT(" ",Sheet2!$C$3-LEN(Sheet2!C8))&Sheet2!C8 -> ExitIfNim | C8: =IF(Sheet2!D8="Std","FALSE","shortcutProfile == USER_"&Sheet2!D8) -> shortcutProfile == USER_C47 | D8: =REPT( " ",$C$4-LEN(C8) ) &C8 -> shortcutProfile == USER_C47 | E8: =REPT(" ",Sheet2!$E$3-LEN(Sheet2!E8))&Sheet2!E8 -> CM_NORMAL | F8: =REPT(" ",Sheet2!$E$3-LEN(Sheet2!F8))&Sheet2!F8 -> tam.mode | G8: =REPT(" ",Sheet2!$G$3-LEN(Sheet2!G8))&Sheet2!G8 -> ITM_LOG10 | H8: =REPT(" ",Sheet2!$H$3-LEN(TEXT(Sheet2!H8,"00")))&""""&TEXT(Sheet2!H8,"00")&"""" -> "03" | I8: =REPT(" ",Sheet2!$I$3-LEN(Sheet2!I8))&Sheet2!I8 -> l[o]g | J8: =IF(Sheet2!B8="","",SUBSTITUTE(SUBSTITUTE(SUBSTITUTE(SUBSTITUTE(SUBSTITUTE(SUBSTITUTE(SUBSTITUTE(SUBSTITUTE($J$1,"61",A8),"CM_NORMAL",E8),"ITM_DRG",G8),"nn = comm",I8),"exitIfNim",B8),"allowCondition",D8),"KK",H8),"9999",F8)) -> if(shortCutCommand(w, event_keyval, 111, shortcutProfile == USER_C47, ExitIfNim, tam.mode, "03", CM_NORMAL, ITM_LOG10 )) {return true;} else // l[o]g
A9: =REPT(" ",Sheet2!$B$3-LEN(Sheet2!B9))&Sheet2!B9 -> 108 | B9: =REPT(" ",Sheet2!$C$3-LEN(Sheet2!C9))&Sheet2!C9 -> ExitIfNim | C9: =IF(Sheet2!D9="Std","FALSE","shortcutProfile == USER_"&Sheet2!D9) -> shortcutProfile == USER_C47 | D9: =REPT( " ",$C$4-LEN(C9) ) &C9 -> shortcutProfile == USER_C47 | E9: =REPT(" ",Sheet2!$E$3-LEN(Sheet2!E9))&Sheet2!E9 -> CM_NORMAL | F9: =REPT(" ",Sheet2!$E$3-LEN(Sheet2!F9))&Sheet2!F9 -> tam.mode | G9: =REPT(" ",Sheet2!$G$3-LEN(Sheet2!G9))&Sheet2!G9 -> ITM_LN | H9: =REPT(" ",Sheet2!$H$3-LEN(TEXT(Sheet2!H9,"00")))&""""&TEXT(Sheet2!H9,"00")&"""" -> "04" | I9: =REPT(" ",Sheet2!$I$3-LEN(Sheet2!I9))&Sheet2!I9 -> [l]n | J9: =IF(Sheet2!B9="","",SUBSTITUTE(SUBSTITUTE(SUBSTITUTE(SUBSTITUTE(SUBSTITUTE(SUBSTITUTE(SUBSTITUTE(SUBSTITUTE($J$1,"61",A9),"CM_NORMAL",E9),"ITM_DRG",G9),"nn = comm",I9),"exitIfNim",B9),"allowCondition",D9),"KK",H9),"9999",F9)) -> if(shortCutCommand(w, event_keyval, 108, shortcutProfile == USER_C47, ExitIfNim, tam.mode, "04", CM_NORMAL, ITM_LN )) {return true;} else // [l]n
A10: =REPT(" ",Sheet2!$B$3-LEN(Sheet2!B10))&Sheet2!B10 -> 120 | B10: =REPT(" ",Sheet2!$C$3-LEN(Sheet2!C10))&Sheet2!C10 -> !ExitIfNim | C10: =IF(Sheet2!D10="Std","FALSE","shortcutProfile == USER_"&Sheet2!D10) -> shortcutProfile == USER_C47 | D10: =REPT( " ",$C$4-LEN(C10) ) &C10 -> shortcutProfile == USER_C47 | E10: =REPT(" ",Sheet2!$E$3-LEN(Sheet2!E10))&Sheet2!E10 -> CM_NORMAL | F10: =REPT(" ",Sheet2!$E$3-LEN(Sheet2!F10))&Sheet2!F10 -> FALSE | G10: =REPT(" ",Sheet2!$G$3-LEN(Sheet2!G10))&Sheet2!G10 -> ITM_XEQ | H10: =REPT(" ",Sheet2!$H$3-LEN(TEXT(Sheet2!H10,"00")))&""""&TEXT(Sheet2!H10,"00")&"""" -> "05" | I10: =REPT(" ",Sheet2!$I$3-LEN(Sheet2!I10))&Sheet2!I10 -> [x]eq | J10: =IF(Sheet2!B10="","",SUBSTITUTE(SUBSTITUTE(SUBSTITUTE(SUBSTITUTE(SUBSTITUTE(SUBSTITUTE(SUBSTITUTE(SUBSTITUTE($J$1,"61",A10),"CM_NORMAL",E10),"ITM_DRG",G10),"nn = comm",I10),"exitIfNim",B10),"allowCondition",D10),"KK",H10),"9999",F10)) -> if(shortCutCommand(w, event_keyval, 120, shortcutProfile == USER_C47, !ExitIfNim, FALSE, "05", CM_NORMAL, ITM_XEQ )) {return true;} else // [x]eq
A11: =REPT(" ",Sheet2!$B$3-LEN(Sheet2!B11))&Sheet2!B11 -> 109 | B11: =REPT(" ",Sheet2!$C$3-LEN(Sheet2!C11))&Sheet2!C11 -> ExitIfNim | C11: =IF(Sheet2!D11="Std","FALSE","shortcutProfile == USER_"&Sheet2!D11) -> shortcutProfile == USER_C47 | D11: =REPT( " ",$C$4-LEN(C11) ) &C11 -> shortcutProfile == USER_C47 | E11: =REPT(" ",Sheet2!$E$3-LEN(Sheet2!E11))&Sheet2!E11 -> CM_NORMAL | F11: =REPT(" ",Sheet2!$E$3-LEN(Sheet2!F11))&Sheet2!F11 -> tam.mode | G11: =REPT(" ",Sheet2!$G$3-LEN(Sheet2!G11))&Sheet2!G11 -> ITM_STO | H11: =REPT(" ",Sheet2!$H$3-LEN(TEXT(Sheet2!H11,"00")))&""""&TEXT(Sheet2!H11,"00")&"""" -> "06" | I11: =REPT(" ",Sheet2!$I$3-LEN(Sheet2!I11))&Sheet2!I11 -> [m]emory | J11: =IF(Sheet2!B11="","",SUBSTITUTE(SUBSTITUTE(SUBSTITUTE(SUBSTITUTE(SUBSTITUTE(SUBSTITUTE(SUBSTITUTE(SUBSTITUTE($J$1,"61",A11),"CM_NORMAL",E11),"ITM_DRG",G11),"nn = comm",I11),"exitIfNim",B11),"allowCondition",D11),"KK",H11),"9999",F11)) -> if(shortCutCommand(w, event_keyval, 109, shortcutProfile == USER_C47, ExitIfNim, tam.mode, "06", CM_NORMAL, ITM_STO )) {return true;} else // [m]emory
A12: =REPT(" ",Sheet2!$B$3-LEN(Sheet2!B12))&Sheet2!B12 -> 114 | B12: =REPT(" ",Sheet2!$C$3-LEN(Sheet2!C12))&Sheet2!C12 -> ExitIfNim | C12: =IF(Sheet2!D12="Std","FALSE","shortcutProfile == USER_"&Sheet2!D12) -> shortcutProfile == USER_C47 | D12: =REPT( " ",$C$4-LEN(C12) ) &C12 -> shortcutProfile == USER_C47 | E12: =REPT(" ",Sheet2!$E$3-LEN(Sheet2!E12))&Sheet2!E12 -> CM_NORMAL | F12: =REPT(" ",Sheet2!$E$3-LEN(Sheet2!F12))&Sheet2!F12 -> tam.mode | G12: =REPT(" ",Sheet2!$G$3-LEN(Sheet2!G12))&Sheet2!G12 -> ITM_RCL | H12: =REPT(" ",Sheet2!$H$3-LEN(TEXT(Sheet2!H12,"00")))&""""&TEXT(Sheet2!H12,"00")&"""" -> "07" | I12: =REPT(" ",Sheet2!$I$3-LEN(Sheet2!I12))&Sheet2!I12 -> [r]cl | J12: =IF(Sheet2!B12="","",SUBSTITUTE(SUBSTITUTE(SUBSTITUTE(SUBSTITUTE(SUBSTITUTE(SUBSTITUTE(SUBSTITUTE(SUBSTITUTE($J$1,"61",A12),"CM_NORMAL",E12),"ITM_DRG",G12),"nn = comm",I12),"exitIfNim",B12),"allowCondition",D12),"KK",H12),"9999",F12)) -> if(shortCutCommand(w, event_keyval, 114, shortcutProfile == USER_C47, ExitIfNim, tam.mode, "07", CM_NORMAL, ITM_RCL )) {return true;} else // [r]cl
A13: =REPT(" ",Sheet2!$B$3-LEN(Sheet2!B13))&Sheet2!B13 -> 100 | B13: =REPT(" ",Sheet2!$C$3-LEN(Sheet2!C13))&Sheet2!C13 -> ExitIfNim | C13: =IF(Sheet2!D13="Std","FALSE","shortcutProfile == USER_"&Sheet2!D13) -> shortcutProfile == USER_C47 | D13: =REPT( " ",$C$4-LEN(C13) ) &C13 -> shortcutProfile == USER_C47 | E13: =REPT(" ",Sheet2!$E$3-LEN(Sheet2!E13))&Sheet2!E13 -> CM_NORMAL | F13: =REPT(" ",Sheet2!$E$3-LEN(Sheet2!F13))&Sheet2!F13 -> tam.mode | G13: =REPT(" ",Sheet2!$G$3-LEN(Sheet2!G13))&Sheet2!G13 -> ITM_Rdown | H13: =REPT(" ",Sheet2!$H$3-LEN(TEXT(Sheet2!H13,"00")))&""""&TEXT(Sheet2!H13,"00")&"""" -> "08" | I13: =REPT(" ",Sheet2!$I$3-LEN(Sheet2!I13))&Sheet2!I13 -> [d]own | J13: =IF(Sheet2!B13="","",SUBSTITUTE(SUBSTITUTE(SUBSTITUTE(SUBSTITUTE(SUBSTITUTE(SUBSTITUTE(SUBSTITUTE(SUBSTITUTE($J$1,"61",A13),"CM_NORMAL",E13),"ITM_DRG",G13),"nn = comm",I13),"exitIfNim",B13),"allowCondition",D13),"KK",H13),"9999",F13)) -> if(shortCutCommand(w, event_keyval, 100, shortcutProfile == USER_C47, ExitIfNim, tam.mode, "08", CM_NORMAL, ITM_Rdown )) {return true;} else // [d]own
A14: =REPT(" ",Sheet2!$B$3-LEN(Sheet2!B14))&Sheet2!B14 -> 115 | B14: =REPT(" ",Sheet2!$C$3-LEN(Sheet2!C14))&Sheet2!C14 -> ExitIfNim | C14: =IF(Sheet2!D14="Std","FALSE","shortcutProfile == USER_"&Sheet2!D14) -> shortcutProfile == USER_C47 | D14: =REPT( " ",$C$4-LEN(C14) ) &C14 -> shortcutProfile == USER_C47 | E14: =REPT(" ",Sheet2!$E$3-LEN(Sheet2!E14))&Sheet2!E14 -> CM_NORMAL | F14: =REPT(" ",Sheet2!$E$3-LEN(Sheet2!F14))&Sheet2!F14 -> tam.mode | G14: =REPT(" ",Sheet2!$G$3-LEN(Sheet2!G14))&Sheet2!G14 -> ITM_sin | H14: =REPT(" ",Sheet2!$H$3-LEN(TEXT(Sheet2!H14,"00")))&""""&TEXT(Sheet2!H14,"00")&"""" -> "09" | I14: =REPT(" ",Sheet2!$I$3-LEN(Sheet2!I14))&Sheet2!I14 -> [s]ine | J14: =IF(Sheet2!B14="","",SUBSTITUTE(SUBSTITUTE(SUBSTITUTE(SUBSTITUTE(SUBSTITUTE(SUBSTITUTE(SUBSTITUTE(SUBSTITUTE($J$1,"61",A14),"CM_NORMAL",E14),"ITM_DRG",G14),"nn = comm",I14),"exitIfNim",B14),"allowCondition",D14),"KK",H14),"9999",F14)) -> if(shortCutCommand(w, event_keyval, 115, shortcutProfile == USER_C47, ExitIfNim, tam.mode, "09", CM_NORMAL, ITM_sin )) {return true;} else // [s]ine
A15: =REPT(" ",Sheet2!$B$3-LEN(Sheet2!B15))&Sheet2!B15 -> 99 | B15: =REPT(" ",Sheet2!$C$3-LEN(Sheet2!C15))&Sheet2!C15 -> ExitIfNim | C15: =IF(Sheet2!D15="Std","FALSE","shortcutProfile == USER_"&Sheet2!D15) -> shortcutProfile == USER_C47 | D15: =REPT( " ",$C$4-LEN(C15) ) &C15 -> shortcutProfile == USER_C47 | E15: =REPT(" ",Sheet2!$E$3-LEN(Sheet2!E15))&Sheet2!E15 -> CM_NORMAL | F15: =REPT(" ",Sheet2!$E$3-LEN(Sheet2!F15))&Sheet2!F15 -> tam.mode | G15: =REPT(" ",Sheet2!$G$3-LEN(Sheet2!G15))&Sheet2!G15 -> ITM_cos | H15: =REPT(" ",Sheet2!$H$3-LEN(TEXT(Sheet2!H15,"00")))&""""&TEXT(Sheet2!H15,"00")&"""" -> "10" | I15: =REPT(" ",Sheet2!$I$3-LEN(Sheet2!I15))&Sheet2!I15 -> [c]osine | J15: =IF(Sheet2!B15="","",SUBSTITUTE(SUBSTITUTE(SUBSTITUTE(SUBSTITUTE(SUBSTITUTE(SUBSTITUTE(SUBSTITUTE(SUBSTITUTE($J$1,"61",A15),"CM_NORMAL",E15),"ITM_DRG",G15),"nn = comm",I15),"exitIfNim",B15),"allowCondition",D15),"KK",H15),"9999",F15)) -> if(shortCutCommand(w, event_keyval, 99, shortcutProfile == USER_C47, ExitIfNim, tam.mode, "10", CM_NORMAL, ITM_cos )) {return true;} else // [c]osine
A16: =REPT(" ",Sheet2!$B$3-LEN(Sheet2!B16))&Sheet2!B16 -> 116 | B16: =REPT(" ",Sheet2!$C$3-LEN(Sheet2!C16))&Sheet2!C16 -> ExitIfNim | C16: =IF(Sheet2!D16="Std","FALSE","shortcutProfile == USER_"&Sheet2!D16) -> shortcutProfile == USER_C47 | D16: =REPT( " ",$C$4-LEN(C16) ) &C16 -> shortcutProfile == USER_C47 | E16: =REPT(" ",Sheet2!$E$3-LEN(Sheet2!E16))&Sheet2!E16 -> CM_NORMAL | F16: =REPT(" ",Sheet2!$E$3-LEN(Sheet2!F16))&Sheet2!F16 -> tam.mode | G16: =REPT(" ",Sheet2!$G$3-LEN(Sheet2!G16))&Sheet2!G16 -> ITM_tan | H16: =REPT(" ",Sheet2!$H$3-LEN(TEXT(Sheet2!H16,"00")))&""""&TEXT(Sheet2!H16,"00")&"""" -> "11" | I16: =REPT(" ",Sheet2!$I$3-LEN(Sheet2!I16))&Sheet2!I16 -> [t]angent | J16: =IF(Sheet2!B16="","",SUBSTITUTE(SUBSTITUTE(SUBSTITUTE(SUBSTITUTE(SUBSTITUTE(SUBSTITUTE(SUBSTITUTE(SUBSTITUTE($J$1,"61",A16),"CM_NORMAL",E16),"ITM_DRG",G16),"nn = comm",I16),"exitIfNim",B16),"allowCondition",D16),"KK",H16),"9999",F16)) -> if(shortCutCommand(w, event_keyval, 116, shortcutProfile == USER_C47, ExitIfNim, tam.mode, "11", CM_NORMAL, ITM_tan )) {return true;} else // [t]angent
... A46: =REPT(" ",Sheet2!$B$3-LEN(Sheet2!B46))&Sheet2!B46 -> 71 | B46: =REPT(" ",Sheet2!$C$3-LEN(Sheet2!C46))&Sheet2!C46 -> ExitIfNim | C46: =IF(Sheet2!D46="Std","FALSE","shortcutProfile == USER_"&Sheet2!D46) -> shortcutProfile == USER_C47 | D46: =REPT( " ",$C$4-LEN(C46) ) &C46 -> shortcutProfile == USER_C47 | E46: =REPT(" ",Sheet2!$E$3-LEN(Sheet2!E46))&Sheet2!E46 -> CM_NORMAL | F46: =REPT(" ",Sheet2!$E$3-LEN(Sheet2!F46))&Sheet2!F46 -> tam.mode | G46: =REPT(" ",Sheet2!$G$3-LEN(Sheet2!G46))&Sheet2!G46 -> ITM_GTO | H46: =REPT(" ",Sheet2!$H$3-LEN(TEXT(Sheet2!H46,"00")))&""""&TEXT(Sheet2!H46,"00")&"""" -> "-01" | I46: =REPT(" ",Sheet2!$I$3-LEN(Sheet2!I46))&Sheet2!I46 -> [g]TO | J46: =IF(Sheet2!B46="","",SUBSTITUTE(SUBSTITUTE(SUBSTITUTE(SUBSTITUTE(SUBSTITUTE(SUBSTITUTE(SUBSTITUTE(SUBSTITUTE($J$1,"61",A46),"CM_NORMAL",E46),"ITM_DRG",G46),"nn = comm",I46),"exitIfNim",B46),"allowCondition",D46),"KK",H46),"9999",F46)) -> if(shortCutCommand(w, event_keyval, 71, shortcutProfile == USER_C47, ExitIfNim, tam.mode, "-01", CM_NORMAL, ITM_GTO )) {return true;} else // [g]TO
A47: =REPT(" ",Sheet2!$B$3-LEN(Sheet2!B47))&Sheet2!B47 -> 39 | B47: =REPT(" ",Sheet2!$C$3-LEN(Sheet2!C47))&Sheet2!C47 -> ExitIfNim | C47: =IF(Sheet2!D47="Std","FALSE","shortcutProfile == USER_"&Sheet2!D47) -> shortcutProfile == USER_C47 | D47: =REPT( " ",$C$4-LEN(C47) ) &C47 -> shortcutProfile == USER_C47 | E47: =REPT(" ",Sheet2!$E$3-LEN(Sheet2!E47))&Sheet2!E47 -> CM_NORMAL | F47: =REPT(" ",Sheet2!$F$3-LEN(Sheet2!F47))&Sheet2!F47 -> tam.mode!=10009 | G47: =REPT(" ",Sheet2!$G$3-LEN(Sheet2!G47))&Sheet2!G47 -> ITM_alpha | H47: =REPT(" ",Sheet2!$H$3-LEN(TEXT(Sheet2!H47,"00")))&""""&TEXT(Sheet2!H47,"00")&"""" -> "-01" | I47: =REPT(" ",Sheet2!$I$3-LEN(Sheet2!I47))&Sheet2!I47 -> during TAM | J47: =IF(Sheet2!B47="","",SUBSTITUTE(SUBSTITUTE(SUBSTITUTE(SUBSTITUTE(SUBSTITUTE(SUBSTITUTE(SUBSTITUTE(SUBSTITUTE($J$1,"61",A47),"CM_NORMAL",E47),"ITM_DRG",G47),"nn = comm",I47),"exitIfNim",B47),"allowCondition",D47),"KK",H47),"9999",F47)) -> if(shortCutCommand(w, event_keyval, 39, shortcutProfile == USER_C47, ExitIfNim, tam.mode!=10009, "-01", CM_NORMAL, ITM_alpha )) {return true;} else // during TAM
A48: =REPT(" ",Sheet2!$B$3-LEN(Sheet2!B48))&Sheet2!B48 | B48: =REPT(" ",Sheet2!$C$3-LEN(Sheet2!C48))&Sheet2!C48 | C48: =IF(Sheet2!D48="Std","FALSE","shortcutProfile == USER_"&Sheet2!D48) -> shortcutProfile == USER_ | D48: =REPT( " ",$C$4-LEN(C48) ) &C48 -> shortcutProfile == USER_ | E48: =REPT(" ",Sheet2!$E$3-LEN(Sheet2!E48))&Sheet2!E48 | F48: =REPT(" ",Sheet2!$E$3-LEN(Sheet2!F48))&Sheet2!F48 | G48: =REPT(" ",Sheet2!$G$3-LEN(Sheet2!G48))&Sheet2!G48 | H48: =REPT(" ",Sheet2!$H$3-LEN(TEXT(Sheet2!H48,"00")))&""""&TEXT(Sheet2!H48,"00")&"""" -> "00" | I48: =REPT(" ",Sheet2!$I$3-LEN(Sheet2!I48))&Sheet2!I48 | J48: =IF(Sheet2!B48="","",SUBSTITUTE(SUBSTITUTE(SUBSTITUTE(SUBSTITUTE(SUBSTITUTE(SUBSTITUTE(SUBSTITUTE(SUBSTITUTE($J$1,"61",A48),"CM_NORMAL",E48),"ITM_DRG",G48),"nn = comm",I48),"exitIfNim",B48),"allowCondition",D48),"KK",H48),"9999",F48))
A49: =REPT(" ",Sheet2!$B$3-LEN(Sheet2!B49))&Sheet2!B49 | B49: =REPT(" ",Sheet2!$C$3-LEN(Sheet2!C49))&Sheet2!C49 | C49: =IF(Sheet2!D49="Std","FALSE","shortcutProfile == USER_"&Sheet2!D49) -> shortcutProfile == USER_ | D49: =REPT( " ",$C$4-LEN(C49) ) &C49 -> shortcutProfile == USER_ | E49: =REPT(" ",Sheet2!$E$3-LEN(Sheet2!E49))&Sheet2!E49 | F49: =REPT(" ",Sheet2!$E$3-LEN(Sheet2!F49))&Sheet2!F49 | G49: =REPT(" ",Sheet2!$G$3-LEN(Sheet2!G49))&Sheet2!G49 | H49: =REPT(" ",Sheet2!$H$3-LEN(TEXT(Sheet2!H49,"00")))&""""&TEXT(Sheet2!H49,"00")&"""" -> "00" | I49: =REPT(" ",Sheet2!$I$3-LEN(Sheet2!I49))&Sheet2!I49 | J49: =IF(Sheet2!B49="","",SUBSTITUTE(SUBSTITUTE(SUBSTITUTE(SUBSTITUTE(SUBSTITUTE(SUBSTITUTE(SUBSTITUTE(SUBSTITUTE($J$1,"61",A49),"CM_NORMAL",E49),"ITM_DRG",G49),"nn = comm",I49),"exitIfNim",B49),"allowCondition",D49),"KK",H49),"9999",F49))
A50: =REPT(" ",Sheet2!$B$3-LEN(Sheet2!B50))&Sheet2!B50 -> 81 | B50: =REPT(" ",Sheet2!$C$3-LEN(Sheet2!C50))&Sheet2!C50 -> ExitIfNim | C50: =IF(Sheet2!D50="Std","FALSE","shortcutProfile == USER_"&Sheet2!D50) -> shortcutProfile == USER_R47 | D50: =REPT( " ",$C$4-LEN(C50) ) &C50 -> shortcutProfile == USER_R47 | E50: =REPT(" ",Sheet2!$E$3-LEN(Sheet2!E50))&Sheet2!E50 -> CM_NORMAL | F50: =REPT(" ",Sheet2!$E$3-LEN(Sheet2!F50))&Sheet2!F50 -> tam.mode | G50: =REPT(" ",Sheet2!$G$3-LEN(Sheet2!G50))&Sheet2!G50 -> ITM_SQUARE | H50: =REPT(" ",Sheet2!$H$3-LEN(TEXT(Sheet2!H50,"00")))&""""&TEXT(Sheet2!H50,"00")&"""" -> "00" | I50: =REPT(" ",Sheet2!$I$3-LEN(Sheet2!I50))&Sheet2!I50 -> s[Q]uare | J50: =IF(Sheet2!B50="","",SUBSTITUTE(SUBSTITUTE(SUBSTITUTE(SUBSTITUTE(SUBSTITUTE(SUBSTITUTE(SUBSTITUTE(SUBSTITUTE($J$1,"61",A50),"CM_NORMAL",E50),"ITM_DRG",G50),"nn = comm",I50),"exitIfNim",B50),"allowCondition",D50),"KK",H50),"9999",F50)) -> if(shortCutCommand(w, event_keyval, 81, shortcutProfile == USER_R47, ExitIfNim, tam.mode, "00", CM_NORMAL, ITM_SQUARE )) {return true;} else // s[Q]uare
A51: =REPT(" ",Sheet2!$B$3-LEN(Sheet2!B51))&Sheet2!B51 -> 113 | B51: =REPT(" ",Sheet2!$C$3-LEN(Sheet2!C51))&Sheet2!C51 -> ExitIfNim | C51: =IF(Sheet2!D51="Std","FALSE","shortcutProfile == USER_"&Sheet2!D51) -> shortcutProfile == USER_R47 | D51: =REPT( " ",$C$4-LEN(C51) ) &C51 -> shortcutProfile == USER_R47 | E51: =REPT(" ",Sheet2!$E$3-LEN(Sheet2!E51))&Sheet2!E51 -> CM_NORMAL | F51: =REPT(" ",Sheet2!$E$3-LEN(Sheet2!F51))&Sheet2!F51 -> tam.mode | G51: =REPT(" ",Sheet2!$G$3-LEN(Sheet2!G51))&Sheet2!G51 -> ITM_SQUAREROOTX | H51: =REPT(" ",Sheet2!$H$3-LEN(TEXT(Sheet2!H51,"00")))&""""&TEXT(Sheet2!H51,"00")&"""" -> "01" | I51: =REPT(" ",Sheet2!$I$3-LEN(Sheet2!I51))&Sheet2!I51 -> s[q]rt | J51: =IF(Sheet2!B51="","",SUBSTITUTE(SUBSTITUTE(SUBSTITUTE(SUBSTITUTE(SUBSTITUTE(SUBSTITUTE(SUBSTITUTE(SUBSTITUTE($J$1,"61",A51),"CM_NORMAL",E51),"ITM_DRG",G51),"nn = comm",I51),"exitIfNim",B51),"allowCondition",D51),"KK",H51),"9999",F51)) -> if(shortCutCommand(w, event_keyval, 113, shortcutProfile == USER_R47, ExitIfNim, tam.mode, "01", CM_NORMAL, ITM_SQUAREROOTX )) {return true;} else // s[q]rt
A52: =REPT(" ",Sheet2!$B$3-LEN(Sheet2!B52))&Sheet2!B52 -> 118 | B52: =REPT(" ",Sheet2!$C$3-LEN(Sheet2!C52))&Sheet2!C52 -> ExitIfNim | C52: =IF(Sheet2!D52="Std","FALSE","shortcutProfile == USER_"&Sheet2!D52) -> shortcutProfile == USER_R47 | D52: =REPT( " ",$C$4-LEN(C52) ) &C52 -> shortcutProfile == USER_R47 | E52: =REPT(" ",Sheet2!$E$3-LEN(Sheet2!E52))&Sheet2!E52 -> CM_NORMAL | F52: =REPT(" ",Sheet2!$E$3-LEN(Sheet2!F52))&Sheet2!F52 -> tam.mode | G52: =REPT(" ",Sheet2!$G$3-LEN(Sheet2!G52))&Sheet2!G52 -> ITM_1ONX | H52: =REPT(" ",Sheet2!$H$3-LEN(TEXT(Sheet2!H52,"00")))&""""&TEXT(Sheet2!H52,"00")&"""" -> "02" | I52: =REPT(" ",Sheet2!$I$3-LEN(Sheet2!I52))&Sheet2!I52 -> in[v]erse | J52: =IF(Sheet2!B52="","",SUBSTITUTE(SUBSTITUTE(SUBSTITUTE(SUBSTITUTE(SUBSTITUTE(SUBSTITUTE(SUBSTITUTE(SUBSTITUTE($J$1,"61",A52),"CM_NORMAL",E52),"ITM_DRG",G52),"nn = comm",I52),"exitIfNim",B52),"allowCondition",D52),"KK",H52),"9999",F52)) -> if(shortCutCommand(w, event_keyval, 118, shortcutProfile == USER_R47, ExitIfNim, tam.mode, "02", CM_NORMAL, ITM_1ONX )) {return true;} else // in[v]erse
A53: =REPT(" ",Sheet2!$B$3-LEN(Sheet2!B53))&Sheet2!B53 -> 121 | B53: =REPT(" ",Sheet2!$C$3-LEN(Sheet2!C53))&Sheet2!C53 -> ExitIfNim | C53: =IF(Sheet2!D53="Std","FALSE","shortcutProfile == USER_"&Sheet2!D53) -> shortcutProfile == USER_R47 | D53: =REPT( " ",$C$4-LEN(C53) ) &C53 -> shortcutProfile == USER_R47 | E53: =REPT(" ",Sheet2!$E$3-LEN(Sheet2!E53))&Sheet2!E53 -> CM_NORMAL | F53: =REPT(" ",Sheet2!$E$3-LEN(Sheet2!F53))&Sheet2!F53 -> tam.mode | G53: =REPT(" ",Sheet2!$G$3-LEN(Sheet2!G53))&Sheet2!G53 -> ITM_YX | H53: =REPT(" ",Sheet2!$H$3-LEN(TEXT(Sheet2!H53,"00")))&""""&TEXT(Sheet2!H53,"00")&"""" -> "03" | I53: =REPT(" ",Sheet2!$I$3-LEN(Sheet2!I53))&Sheet2!I53 -> [y]^x | J53: =IF(Sheet2!B53="","",SUBSTITUTE(SUBSTITUTE(SUBSTITUTE(SUBSTITUTE(SUBSTITUTE(SUBSTITUTE(SUBSTITUTE(SUBSTITUTE($J$1,"61",A53),"CM_NORMAL",E53),"ITM_DRG",G53),"nn = comm",I53),"exitIfNim",B53),"allowCondition",D53),"KK",H53),"9999",F53)) -> if(shortCutCommand(w, event_keyval, 121, shortcutProfile == USER_R47, ExitIfNim, tam.mode, "03", CM_NORMAL, ITM_YX )) {return true;} else // [y]^x
A54: =REPT(" ",Sheet2!$B$3-LEN(Sheet2!B54))&Sheet2!B54 -> 111 | B54: =REPT(" ",Sheet2!$C$3-LEN(Sheet2!C54))&Sheet2!C54 -> ExitIfNim | C54: =IF(Sheet2!D54="Std","FALSE","shortcutProfile == USER_"&Sheet2!D54) -> shortcutProfile == USER_R47 | D54: =REPT( " ",$C$4-LEN(C54) ) &C54 -> shortcutProfile == USER_R47 | E54: =REPT(" ",Sheet2!$E$3-LEN(Sheet2!E54))&Sheet2!E54 -> CM_NORMAL | F54: =REPT(" ",Sheet2!$E$3-LEN(Sheet2!F54))&Sheet2!F54 -> tam.mode | G54: =REPT(" ",Sheet2!$G$3-LEN(Sheet2!G54))&Sheet2!G54 -> ITM_LOG10 | H54: =REPT(" ",Sheet2!$H$3-LEN(TEXT(Sheet2!H54,"00")))&""""&TEXT(Sheet2!H54,"00")&"""" -> "04" | I54: =REPT(" ",Sheet2!$I$3-LEN(Sheet2!I54))&Sheet2!I54 -> l[o]g | J54: =IF(Sheet2!B54="","",SUBSTITUTE(SUBSTITUTE(SUBSTITUTE(SUBSTITUTE(SUBSTITUTE(SUBSTITUTE(SUBSTITUTE(SUBSTITUTE($J$1,"61",A54),"CM_NORMAL",E54),"ITM_DRG",G54),"nn = comm",I54),"exitIfNim",B54),"allowCondition",D54),"KK",H54),"9999",F54)) -> if(shortCutCommand(w, event_keyval, 111, shortcutProfile == USER_R47, ExitIfNim, tam.mode, "04", CM_NORMAL, ITM_LOG10 )) {return true;} else // l[o]g
A55: =REPT(" ",Sheet2!$B$3-LEN(Sheet2!B55))&Sheet2!B55 -> 108 | B55: =REPT(" ",Sheet2!$C$3-LEN(Sheet2!C55))&Sheet2!C55 -> ExitIfNim | C55: =IF(Sheet2!D55="Std","FALSE","shortcutProfile == USER_"&Sheet2!D55) -> shortcutProfile == USER_R47 | D55: =REPT( " ",$C$4-LEN(C55) ) &C55 -> shortcutProfile == USER_R47 | E55: =REPT(" ",Sheet2!$E$3-LEN(Sheet2!E55))&Sheet2!E55 -> CM_NORMAL | F55: =REPT(" ",Sheet2!$E$3-LEN(Sheet2!F55))&Sheet2!F55 -> tam.mode | G55: =REPT(" ",Sheet2!$G$3-LEN(Sheet2!G55))&Sheet2!G55 -> ITM_LN | H55: =REPT(" ",Sheet2!$H$3-LEN(TEXT(Sheet2!H55,"00")))&""""&TEXT(Sheet2!H55,"00")&"""" -> "05" | I55: =REPT(" ",Sheet2!$I$3-LEN(Sheet2!I55))&Sheet2!I55 -> [l]n | J55: =IF(Sheet2!B55="","",SUBSTITUTE(SUBSTITUTE(SUBSTITUTE(SUBSTITUTE(SUBSTITUTE(SUBSTITUTE(SUBSTITUTE(SUBSTITUTE($J$1,"61",A55),"CM_NORMAL",E55),"ITM_DRG",G55),"nn = comm",I55),"exitIfNim",B55),"allowCondition",D55),"KK",H55),"9999",F55)) -> if(shortCutCommand(w, event_keyval, 108, shortcutProfile == USER_R47, ExitIfNim, tam.mode, "05", CM_NORMAL, ITM_LN )) {return true;} else // [l]n
A56: =REPT(" ",Sheet2!$B$3-LEN(Sheet2!B56))&Sheet2!B56 -> 109 | B56: =REPT(" ",Sheet2!$C$3-LEN(Sheet2!C56))&Sheet2!C56 -> ExitIfNim | C56: =IF(Sheet2!D56="Std","FALSE","shortcutProfile == USER_"&Sheet2!D56) -> shortcutProfile == USER_R47 | D56: =REPT( " ",$C$4-LEN(C56) ) &C56 -> shortcutProfile == USER_R47 | E56: =REPT(" ",Sheet2!$E$3-LEN(Sheet2!E56))&Sheet2!E56 -> CM_NORMAL | F56: =REPT(" ",Sheet2!$E$3-LEN(Sheet2!F56))&Sheet2!F56 -> tam.mode | G56: =REPT(" ",Sheet2!$G$3-LEN(Sheet2!G56))&Sheet2!G56 -> ITM_STO | H56: =REPT(" ",Sheet2!$H$3-LEN(TEXT(Sheet2!H56,"00")))&""""&TEXT(Sheet2!H56,"00")&"""" -> "06" | I56: =REPT(" ",Sheet2!$I$3-LEN(Sheet2!I56))&Sheet2!I56 -> [m]emory | J56: =IF(Sheet2!B56="","",SUBSTITUTE(SUBSTITUTE(SUBSTITUTE(SUBSTITUTE(SUBSTITUTE(SUBSTITUTE(SUBSTITUTE(SUBSTITUTE($J$1,"61",A56),"CM_NORMAL",E56),"ITM_DRG",G56),"nn = comm",I56),"exitIfNim",B56),"allowCondition",D56),"KK",H56),"9999",F56)) -> if(shortCutCommand(w, event_keyval, 109, shortcutProfile == USER_R47, ExitIfNim, tam.mode, "06", CM_NORMAL, ITM_STO )) {return true;} else // [m]emory
A57: =REPT(" ",Sheet2!$B$3-LEN(Sheet2!B57))&Sheet2!B57 -> 114 | B57: =REPT(" ",Sheet2!$C$3-LEN(Sheet2!C57))&Sheet2!C57 -> ExitIfNim | C57: =IF(Sheet2!D57="Std","FALSE","shortcutProfile == USER_"&Sheet2!D57) -> shortcutProfile == USER_R47 | D57: =REPT( " ",$C$4-LEN(C57) ) &C57 -> shortcutProfile == USER_R47 | E57: =REPT(" ",Sheet2!$E$3-LEN(Sheet2!E57))&Sheet2!E57 -> CM_NORMAL | F57: =REPT(" ",Sheet2!$E$3-LEN(Sheet2!F57))&Sheet2!F57 -> tam.mode | G57: =REPT(" ",Sheet2!$G$3-LEN(Sheet2!G57))&Sheet2!G57 -> ITM_RCL | H57: =REPT(" ",Sheet2!$H$3-LEN(TEXT(Sheet2!H57,"00")))&""""&TEXT(Sheet2!H57,"00")&"""" -> "07" | I57: =REPT(" ",Sheet2!$I$3-LEN(Sheet2!I57))&Sheet2!I57 -> [r]cl | J57: =IF(Sheet2!B57="","",SUBSTITUTE(SUBSTITUTE(SUBSTITUTE(SUBSTITUTE(SUBSTITUTE(SUBSTITUTE(SUBSTITUTE(SUBSTITUTE($J$1,"61",A57),"CM_NORMAL",E57),"ITM_DRG",G57),"nn = comm",I57),"exitIfNim",B57),"allowCondition",D57),"KK",H57),"9999",F57)) -> if(shortCutCommand(w, event_keyval, 114, shortcutProfile == USER_R47, ExitIfNim, tam.mode, "07", CM_NORMAL, ITM_RCL )) {return true;} else // [r]cl
A58: =REPT(" ",Sheet2!$B$3-LEN(Sheet2!B58))&Sheet2!B58 -> 100 | B58: =REPT(" ",Sheet2!$C$3-LEN(Sheet2!C58))&Sheet2!C58 -> ExitIfNim | C58: =IF(Sheet2!D58="Std","FALSE","shortcutProfile == USER_"&Sheet2!D58) -> shortcutProfile == USER_R47 | D58: =REPT( " ",$C$4-LEN(C58) ) &C58 -> shortcutProfile == USER_R47 | E58: =REPT(" ",Sheet2!$E$3-LEN(Sheet2!E58))&Sheet2!E58 -> CM_NORMAL | F58: =REPT(" ",Sheet2!$E$3-LEN(Sheet2!F58))&Sheet2!F58 -> tam.mode | G58: =REPT(" ",Sheet2!$G$3-LEN(Sheet2!G58))&Sheet2!G58 -> ITM_Rdown | H58: =REPT(" ",Sheet2!$H$3-LEN(TEXT(Sheet2!H58,"00")))&""""&TEXT(Sheet2!H58,"00")&"""" -> "08" | I58: =REPT(" ",Sheet2!$I$3-LEN(Sheet2!I58))&Sheet2!I58 -> [d]own | J58: =IF(Sheet2!B58="","",SUBSTITUTE(SUBSTITUTE(SUBSTITUTE(SUBSTITUTE(SUBSTITUTE(SUBSTITUTE(SUBSTITUTE(SUBSTITUTE($J$1,"61",A58),"CM_NORMAL",E58),"ITM_DRG",G58),"nn = comm",I58),"exitIfNim",B58),"allowCondition",D58),"KK",H58),"9999",F58)) -> if(shortCutCommand(w, event_keyval, 100, shortcutProfile == USER_R47, ExitIfNim, tam.mode, "08", CM_NORMAL, ITM_Rdown )) {return true;} else // [d]own
A59: =REPT(" ",Sheet2!$B$3-LEN(Sheet2!B59))&Sheet2!B59 -> 61 | B59: =REPT(" ",Sheet2!$C$3-LEN(Sheet2!C59))&Sheet2!C59 -> ExitIfNim | C59: =IF(Sheet2!D59="Std","FALSE","shortcutProfile == USER_"&Sheet2!D59) -> shortcutProfile == USER_R47 | D59: =REPT( " ",$C$4-LEN(C59) ) &C59 -> shortcutProfile == USER_R47 | E59: =REPT(" ",Sheet2!$E$3-LEN(Sheet2!E59))&Sheet2!E59 -> CM_NORMAL | F59: =REPT(" ",Sheet2!$E$3-LEN(Sheet2!F59))&Sheet2!F59 -> tam.mode | G59: =REPT(" ",Sheet2!$G$3-LEN(Sheet2!G59))&Sheet2!G59 -> ITM_DRG | H59: =REPT(" ",Sheet2!$H$3-LEN(TEXT(Sheet2!H59,"00")))&""""&TEXT(Sheet2!H59,"00")&"""" -> "-01" | I59: =REPT(" ",Sheet2!$I$3-LEN(Sheet2!I59))&Sheet2!I59 -> [=]>D,R,G | J59: =IF(Sheet2!B59="","",SUBSTITUTE(SUBSTITUTE(SUBSTITUTE(SUBSTITUTE(SUBSTITUTE(SUBSTITUTE(SUBSTITUTE(SUBSTITUTE($J$1,"61",A59),"CM_NORMAL",E59),"ITM_DRG",G59),"nn = comm",I59),"exitIfNim",B59),"allowCondition",D59),"KK",H59),"9999",F59)) -> if(shortCutCommand(w, event_keyval, 61, shortcutProfile == USER_R47, ExitIfNim, tam.mode, "-01", CM_NORMAL, ITM_DRG )) {return true;} else // [=]>D,R,G
... A93: =REPT(" ",Sheet2!$B$3-LEN(Sheet2!B93))&Sheet2!B93 -> 71 | B93: =REPT(" ",Sheet2!$C$3-LEN(Sheet2!C93))&Sheet2!C93 -> ExitIfNim | C93: =IF(Sheet2!D93="Std","FALSE","shortcutProfile == USER_"&Sheet2!D93) -> shortcutProfile == USER_R47 | D93: =REPT( " ",$C$4-LEN(C93) ) &C93 -> shortcutProfile == USER_R47 | E93: =REPT(" ",Sheet2!$E$3-LEN(Sheet2!E93))&Sheet2!E93 -> CM_NORMAL | F93: =REPT(" ",Sheet2!$E$3-LEN(Sheet2!F93))&Sheet2!F93 -> tam.mode | G93: =REPT(" ",Sheet2!$G$3-LEN(Sheet2!G93))&Sheet2!G93 -> ITM_GTO | H93: =REPT(" ",Sheet2!$H$3-LEN(TEXT(Sheet2!H93,"00")))&""""&TEXT(Sheet2!H93,"00")&"""" -> "-01" | I93: =REPT(" ",Sheet2!$I$3-LEN(Sheet2!I93))&Sheet2!I93 -> [g]TO | J93: =IF(Sheet2!B93="","",SUBSTITUTE(SUBSTITUTE(SUBSTITUTE(SUBSTITUTE(SUBSTITUTE(SUBSTITUTE(SUBSTITUTE(SUBSTITUTE($J$1,"61",A93),"CM_NORMAL",E93),"ITM_DRG",G93),"nn = comm",I93),"exitIfNim",B93),"allowCondition",D93),"KK",H93),"9999",F93)) -> if(shortCutCommand(w, event_keyval, 71, shortcutProfile == USER_R47, ExitIfNim, tam.mode, "-01", CM_NORMAL, ITM_GTO )) {return true;} else // [g]TO
A94: =REPT(" ",Sheet2!$B$3-LEN(Sheet2!B94))&Sheet2!B94 -> 39 | B94: =REPT(" ",Sheet2!$C$3-LEN(Sheet2!C94))&Sheet2!C94 -> ExitIfNim | C94: =IF(Sheet2!D94="Std","FALSE","shortcutProfile == USER_"&Sheet2!D94) -> shortcutProfile == USER_R47 | D94: =REPT( " ",$C$4-LEN(C94) ) &C94 -> shortcutProfile == USER_R47 | E94: =REPT(" ",Sheet2!$E$3-LEN(Sheet2!E94))&Sheet2!E94 -> CM_NORMAL | F94: =REPT(" ",Sheet2!$F$3-LEN(Sheet2!F94))&Sheet2!F94 -> tam.mode!=10009 | G94: =REPT(" ",Sheet2!$G$3-LEN(Sheet2!G94))&Sheet2!G94 -> ITM_alpha | H94: =REPT(" ",Sheet2!$H$3-LEN(TEXT(Sheet2!H94,"00")))&""""&TEXT(Sheet2!H94,"00")&"""" -> "-01" | I94: =REPT(" ",Sheet2!$I$3-LEN(Sheet2!I94))&Sheet2!I94 -> during TAM | J94: =IF(Sheet2!B94="","",SUBSTITUTE(SUBSTITUTE(SUBSTITUTE(SUBSTITUTE(SUBSTITUTE(SUBSTITUTE(SUBSTITUTE(SUBSTITUTE($J$1,"61",A94),"CM_NORMAL",E94),"ITM_DRG",G94),"nn = comm",I94),"exitIfNim",B94),"allowCondition",D94),"KK",H94),"9999",F94)) -> if(shortCutCommand(w, event_keyval, 39, shortcutProfile == USER_R47, ExitIfNim, tam.mode!=10009, "-01", CM_NORMAL, ITM_alpha )) {return true;} else // during TAM
A95: =REPT(" ",Sheet2!$B$3-LEN(Sheet2!B95))&Sheet2!B95 | B95: =REPT(" ",Sheet2!$C$3-LEN(Sheet2!C95))&Sheet2!C95 | C95: =IF(Sheet2!D95="Std","FALSE","shortcutProfile == USER_"&Sheet2!D95) -> shortcutProfile == USER_ | D95: =REPT( " ",$C$4-LEN(C95) ) &C95 -> shortcutProfile == USER_ | E95: =REPT(" ",Sheet2!$E$3-LEN(Sheet2!E95))&Sheet2!E95 | F95: =REPT(" ",Sheet2!$E$3-LEN(Sheet2!F95))&Sheet2!F95 | G95: =REPT(" ",Sheet2!$G$3-LEN(Sheet2!G95))&Sheet2!G95 | H95: =REPT(" ",Sheet2!$H$3-LEN(TEXT(Sheet2!H95,"00")))&""""&TEXT(Sheet2!H95,"00")&"""" -> "00" | I95: =REPT(" ",Sheet2!$I$3-LEN(Sheet2!I95))&Sheet2!I95 | J95: =IF(Sheet2!B95="","",SUBSTITUTE(SUBSTITUTE(SUBSTITUTE(SUBSTITUTE(SUBSTITUTE(SUBSTITUTE(SUBSTITUTE(SUBSTITUTE($J$1,"61",A95),"CM_NORMAL",E95),"ITM_DRG",G95),"nn = comm",I95),"exitIfNim",B95),"allowCondition",D95),"KK",H95),"9999",F95))
J2241: =IF(AND(OR(#REF!="",ISBLANK(#REF!)),#REF!>0),IF(ISBLANK(#REF!),"",#REF!), IF(#REF!<0,VLOOKUP(#REF!,#REF!,2,0), IF(ISBLANK(#REF!), "", "/* "&TEXT(#REF!,"???0")&" *" &#REF!&", "& IF(#REF!-LEN(#REF!) >= 0, REPT(" ",#REF!-LEN(#REF!)), "") &#REF!&", "& IF(#REF!-LEN(#REF!) >= 0, REPT(" ",#REF!-LEN(#REF!)), "") &#REF!&", "& IF(#REF!-LEN(#REF!) >=0, REPT(" ",#REF!-LEN(#REF!)), "") &#REF!&", "& IF(#REF!-LEN(#REF!) >= 0, REPT(" ",#REF!-LEN(#REF!)+2), "")&"("& SUBSTITUTE(TEXT(#REF!,"??0")," ","")&" << TAM_MAX_BITS) |"& IF(#REF!-3 >= 0, REPT(" ",MAX(1,#REF!-5+4+1-1-LEN( IF(ISTEXT(#REF!),#REF!, SUBSTITUTE(SUBSTITUTE(TEXT(#REF!,"????0")," ","")," ","")) ))), "")& IF(ISTEXT(#REF!),#REF!, SUBSTITUTE(SUBSTITUTE(TEXT(#REF!,"????0")," ","")," ","")) &","& IF(#REF!-3 >= 0, REPT(" ",#REF!-3-5), "") &#REF!& " | "& IF(#REF!-LEN(#REF!) >= 0, REPT(" ",#REF!-LEN(#REF!)), "") &#REF!& IF(#REF!-LEN(#REF!) >= 0, REPT(" ",#REF!-LEN(#REF!)), "")& " | "& IF(#REF!-LEN(#REF!) >= 0, REPT(" ",#REF!-LEN(#REF!)), "") &#REF!& IF(#REF!-LEN(#REF!) >= 0, REPT(" ",#REF!-LEN(#REF!)), "")& " | " &#REF!& IF(#REF!-LEN(#REF!) >= 0, REPT(" ",#REF!-LEN(#REF!)), "")& " | " &#REF!& IF(#REF!-LEN(#REF!) >= 0, REPT(" ",#REF!-LEN(#REF!)), "")& "},"&IF(#REF!<>"",""&#REF!,"") ) ) ) -> #REF!
J2242: =IF(AND(OR(#REF!="",ISBLANK(#REF!)),#REF!>0),IF(ISBLANK(#REF!),"",#REF!), IF(#REF!<0,VLOOKUP(#REF!,#REF!,2,0), IF(ISBLANK(#REF!), "", "/* "&TEXT(#REF!,"???0")&" *" &#REF!&", "& IF(#REF!-LEN(#REF!) >= 0, REPT(" ",#REF!-LEN(#REF!)), "") &#REF!&", "& IF(#REF!-LEN(#REF!) >= 0, REPT(" ",#REF!-LEN(#REF!)), "") &#REF!&", "& IF(#REF!-LEN(#REF!) >=0, REPT(" ",#REF!-LEN(#REF!)), "") &#REF!&", "& IF(#REF!-LEN(#REF!) >= 0, REPT(" ",#REF!-LEN(#REF!)+2), "")&"("& SUBSTITUTE(TEXT(#REF!,"??0")," ","")&" << TAM_MAX_BITS) |"& IF(#REF!-3 >= 0, REPT(" ",MAX(1,#REF!-5+4+1-1-LEN( IF(ISTEXT(#REF!),#REF!, SUBSTITUTE(SUBSTITUTE(TEXT(#REF!,"????0")," ","")," ","")) ))), "")& IF(ISTEXT(#REF!),#REF!, SUBSTITUTE(SUBSTITUTE(TEXT(#REF!,"????0")," ","")," ","")) &","& IF(#REF!-3 >= 0, REPT(" ",#REF!-3-5), "") &#REF!& " | "& IF(#REF!-LEN(#REF!) >= 0, REPT(" ",#REF!-LEN(#REF!)), "") &#REF!& IF(#REF!-LEN(#REF!) >= 0, REPT(" ",#REF!-LEN(#REF!)), "")& " | "& IF(#REF!-LEN(#REF!) >= 0, REPT(" ",#REF!-LEN(#REF!)), "") &#REF!& IF(#REF!-LEN(#REF!) >= 0, REPT(" ",#REF!-LEN(#REF!)), "")& " | " &#REF!& IF(#REF!-LEN(#REF!) >= 0, REPT(" ",#REF!-LEN(#REF!)), "")& " | " &#REF!& IF(#REF!-LEN(#REF!) >= 0, REPT(" ",#REF!-LEN(#REF!)), "")& "},"&IF(#REF!<>"",""&#REF!,"") ) ) ) -> #REF!
J2243: =IF(AND(OR(#REF!="",ISBLANK(#REF!)),#REF!>0),IF(ISBLANK(#REF!),"",#REF!), IF(#REF!<0,VLOOKUP(#REF!,#REF!,2,0), IF(ISBLANK(#REF!), "", "/* "&TEXT(#REF!,"???0")&" *" &#REF!&", "& IF(#REF!-LEN(#REF!) >= 0, REPT(" ",#REF!-LEN(#REF!)), "") &#REF!&", "& IF(#REF!-LEN(#REF!) >= 0, REPT(" ",#REF!-LEN(#REF!)), "") &#REF!&", "& IF(#REF!-LEN(#REF!) >=0, REPT(" ",#REF!-LEN(#REF!)), "") &#REF!&", "& IF(#REF!-LEN(#REF!) >= 0, REPT(" ",#REF!-LEN(#REF!)+2), "")&"("& SUBSTITUTE(TEXT(#REF!,"??0")," ","")&" << TAM_MAX_BITS) |"& IF(#REF!-3 >= 0, REPT(" ",MAX(1,#REF!-5+4+1-1-LEN( IF(ISTEXT(#REF!),#REF!, SUBSTITUTE(SUBSTITUTE(TEXT(#REF!,"????0")," ","")," ","")) ))), "")& IF(ISTEXT(#REF!),#REF!, SUBSTITUTE(SUBSTITUTE(TEXT(#REF!,"????0")," ","")," ","")) &","& IF(#REF!-3 >= 0, REPT(" ",#REF!-3-5), "") &#REF!& " | "& IF(#REF!-LEN(#REF!) >= 0, REPT(" ",#REF!-LEN(#REF!)), "") &#REF!& IF(#REF!-LEN(#REF!) >= 0, REPT(" ",#REF!-LEN(#REF!)), "")& " | "& IF(#REF!-LEN(#REF!) >= 0, REPT(" ",#REF!-LEN(#REF!)), "") &#REF!& IF(#REF!-LEN(#REF!) >= 0, REPT(" ",#REF!-LEN(#REF!)), "")& " | " &#REF!& IF(#REF!-LEN(#REF!) >= 0, REPT(" ",#REF!-LEN(#REF!)), "")& " | " &#REF!& IF(#REF!-LEN(#REF!) >= 0, REPT(" ",#REF!-LEN(#REF!)), "")& "},"&IF(#REF!<>"",""&#REF!,"") ) ) ) -> #REF!
J2244: =IF(AND(OR(#REF!="",ISBLANK(#REF!)),#REF!>0),IF(ISBLANK(#REF!),"",#REF!), IF(#REF!<0,VLOOKUP(#REF!,#REF!,2,0), IF(ISBLANK(#REF!), "", "/* "&TEXT(#REF!,"???0")&" *" &#REF!&", "& IF(#REF!-LEN(#REF!) >= 0, REPT(" ",#REF!-LEN(#REF!)), "") &#REF!&", "& IF(#REF!-LEN(#REF!) >= 0, REPT(" ",#REF!-LEN(#REF!)), "") &#REF!&", "& IF(#REF!-LEN(#REF!) >=0, REPT(" ",#REF!-LEN(#REF!)), "") &#REF!&", "& IF(#REF!-LEN(#REF!) >= 0, REPT(" ",#REF!-LEN(#REF!)+2), "")&"("& SUBSTITUTE(TEXT(#REF!,"??0")," ","")&" << TAM_MAX_BITS) |"& IF(#REF!-3 >= 0, REPT(" ",MAX(1,#REF!-5+4+1-1-LEN( IF(ISTEXT(#REF!),#REF!, SUBSTITUTE(SUBSTITUTE(TEXT(#REF!,"????0")," ","")," ","")) ))), "")& IF(ISTEXT(#REF!),#REF!, SUBSTITUTE(SUBSTITUTE(TEXT(#REF!,"????0")," ","")," ","")) &","& IF(#REF!-3 >= 0, REPT(" ",#REF!-3-5), "") &#REF!& " | "& IF(#REF!-LEN(#REF!) >= 0, REPT(" ",#REF!-LEN(#REF!)), "") &#REF!& IF(#REF!-LEN(#REF!) >= 0, REPT(" ",#REF!-LEN(#REF!)), "")& " | "& IF(#REF!-LEN(#REF!) >= 0, REPT(" ",#REF!-LEN(#REF!)), "") &#REF!& IF(#REF!-LEN(#REF!) >= 0, REPT(" ",#REF!-LEN(#REF!)), "")& " | " &#REF!& IF(#REF!-LEN(#REF!) >= 0, REPT(" ",#REF!-LEN(#REF!)), "")& " | " &#REF!& IF(#REF!-LEN(#REF!) >= 0, REPT(" ",#REF!-LEN(#REF!)), "")& "},"&IF(#REF!<>"",""&#REF!,"") ) ) ) -> #REF!
J2245: =IF(AND(OR(#REF!="",ISBLANK(#REF!)),#REF!>0),IF(ISBLANK(#REF!),"",#REF!), IF(#REF!<0,VLOOKUP(#REF!,#REF!,2,0), IF(ISBLANK(#REF!), "", "/* "&TEXT(#REF!,"???0")&" *" &#REF!&", "& IF(#REF!-LEN(#REF!) >= 0, REPT(" ",#REF!-LEN(#REF!)), "") &#REF!&", "& IF(#REF!-LEN(#REF!) >= 0, REPT(" ",#REF!-LEN(#REF!)), "") &#REF!&", "& IF(#REF!-LEN(#REF!) >=0, REPT(" ",#REF!-LEN(#REF!)), "") &#REF!&", "& IF(#REF!-LEN(#REF!) >= 0, REPT(" ",#REF!-LEN(#REF!)+2), "")&"("& SUBSTITUTE(TEXT(#REF!,"??0")," ","")&" << TAM_MAX_BITS) |"& IF(#REF!-3 >= 0, REPT(" ",MAX(1,#REF!-5+4+1-1-LEN( IF(ISTEXT(#REF!),#REF!, SUBSTITUTE(SUBSTITUTE(TEXT(#REF!,"????0")," ","")," ","")) ))), "")& IF(ISTEXT(#REF!),#REF!, SUBSTITUTE(SUBSTITUTE(TEXT(#REF!,"????0")," ","")," ","")) &","& IF(#REF!-3 >= 0, REPT(" ",#REF!-3-5), "") &#REF!& " | "& IF(#REF!-LEN(#REF!) >= 0, REPT(" ",#REF!-LEN(#REF!)), "") &#REF!& IF(#REF!-LEN(#REF!) >= 0, REPT(" ",#REF!-LEN(#REF!)), "")& " | "& IF(#REF!-LEN(#REF!) >= 0, REPT(" ",#REF!-LEN(#REF!)), "") &#REF!& IF(#REF!-LEN(#REF!) >= 0, REPT(" ",#REF!-LEN(#REF!)), "")& " | " &#REF!& IF(#REF!-LEN(#REF!) >= 0, REPT(" ",#REF!-LEN(#REF!)), "")& " | " &#REF!& IF(#REF!-LEN(#REF!) >= 0, REPT(" ",#REF!-LEN(#REF!)), "")& "},"&IF(#REF!<>"",""&#REF!,"") ) ) ) -> #REF!
J2246: =IF(AND(OR(#REF!="",ISBLANK(#REF!)),#REF!>0),IF(ISBLANK(#REF!),"",#REF!), IF(#REF!<0,VLOOKUP(#REF!,#REF!,2,0), IF(ISBLANK(#REF!), "", "/* "&TEXT(#REF!,"???0")&" *" &#REF!&", "& IF(#REF!-LEN(#REF!) >= 0, REPT(" ",#REF!-LEN(#REF!)), "") &#REF!&", "& IF(#REF!-LEN(#REF!) >= 0, REPT(" ",#REF!-LEN(#REF!)), "") &#REF!&", "& IF(#REF!-LEN(#REF!) >=0, REPT(" ",#REF!-LEN(#REF!)), "") &#REF!&", "& IF(#REF!-LEN(#REF!) >= 0, REPT(" ",#REF!-LEN(#REF!)+2), "")&"("& SUBSTITUTE(TEXT(#REF!,"??0")," ","")&" << TAM_MAX_BITS) |"& IF(#REF!-3 >= 0, REPT(" ",MAX(1,#REF!-5+4+1-1-LEN( IF(ISTEXT(#REF!),#REF!, SUBSTITUTE(SUBSTITUTE(TEXT(#REF!,"????0")," ","")," ","")) ))), "")& IF(ISTEXT(#REF!),#REF!, SUBSTITUTE(SUBSTITUTE(TEXT(#REF!,"????0")," ","")," ","")) &","& IF(#REF!-3 >= 0, REPT(" ",#REF!-3-5), "") &#REF!& " | "& IF(#REF!-LEN(#REF!) >= 0, REPT(" ",#REF!-LEN(#REF!)), "") &#REF!& IF(#REF!-LEN(#REF!) >= 0, REPT(" ",#REF!-LEN(#REF!)), "")& " | "& IF(#REF!-LEN(#REF!) >= 0, REPT(" ",#REF!-LEN(#REF!)), "") &#REF!& IF(#REF!-LEN(#REF!) >= 0, REPT(" ",#REF!-LEN(#REF!)), "")& " | " &#REF!& IF(#REF!-LEN(#REF!) >= 0, REPT(" ",#REF!-LEN(#REF!)), "")& " | " &#REF!& IF(#REF!-LEN(#REF!) >= 0, REPT(" ",#REF!-LEN(#REF!)), "")& "},"&IF(#REF!<>"",""&#REF!,"") ) ) ) -> #REF!
J2247: =IF(AND(OR(#REF!="",ISBLANK(#REF!)),#REF!>0),IF(ISBLANK(#REF!),"",#REF!), IF(#REF!<0,VLOOKUP(#REF!,#REF!,2,0), IF(ISBLANK(#REF!), "", "/* "&TEXT(#REF!,"???0")&" *" &#REF!&", "& IF(#REF!-LEN(#REF!) >= 0, REPT(" ",#REF!-LEN(#REF!)), "") &#REF!&", "& IF(#REF!-LEN(#REF!) >= 0, REPT(" ",#REF!-LEN(#REF!)), "") &#REF!&", "& IF(#REF!-LEN(#REF!) >=0, REPT(" ",#REF!-LEN(#REF!)), "") &#REF!&", "& IF(#REF!-LEN(#REF!) >= 0, REPT(" ",#REF!-LEN(#REF!)+2), "")&"("& SUBSTITUTE(TEXT(#REF!,"??0")," ","")&" << TAM_MAX_BITS) |"& IF(#REF!-3 >= 0, REPT(" ",MAX(1,#REF!-5+4+1-1-LEN( IF(ISTEXT(#REF!),#REF!, SUBSTITUTE(SUBSTITUTE(TEXT(#REF!,"????0")," ","")," ","")) ))), "")& IF(ISTEXT(#REF!),#REF!, SUBSTITUTE(SUBSTITUTE(TEXT(#REF!,"????0")," ","")," ","")) &","& IF(#REF!-3 >= 0, REPT(" ",#REF!-3-5), "") &#REF!& " | "& IF(#REF!-LEN(#REF!) >= 0, REPT(" ",#REF!-LEN(#REF!)), "") &#REF!& IF(#REF!-LEN(#REF!) >= 0, REPT(" ",#REF!-LEN(#REF!)), "")& " | "& IF(#REF!-LEN(#REF!) >= 0, REPT(" ",#REF!-LEN(#REF!)), "") &#REF!& IF(#REF!-LEN(#REF!) >= 0, REPT(" ",#REF!-LEN(#REF!)), "")& " | " &#REF!& IF(#REF!-LEN(#REF!) >= 0, REPT(" ",#REF!-LEN(#REF!)), "")& " | " &#REF!& IF(#REF!-LEN(#REF!) >= 0, REPT(" ",#REF!-LEN(#REF!)), "")& "},"&IF(#REF!<>"",""&#REF!,"") ) ) ) -> #REF!
J2248: =IF(AND(OR(#REF!="",ISBLANK(#REF!)),#REF!>0),IF(ISBLANK(#REF!),"",#REF!), IF(#REF!<0,VLOOKUP(#REF!,#REF!,2,0), IF(ISBLANK(#REF!), "", "/* "&TEXT(#REF!,"???0")&" *" &#REF!&", "& IF(#REF!-LEN(#REF!) >= 0, REPT(" ",#REF!-LEN(#REF!)), "") &#REF!&", "& IF(#REF!-LEN(#REF!) >= 0, REPT(" ",#REF!-LEN(#REF!)), "") &#REF!&", "& IF(#REF!-LEN(#REF!) >=0, REPT(" ",#REF!-LEN(#REF!)), "") &#REF!&", "& IF(#REF!-LEN(#REF!) >= 0, REPT(" ",#REF!-LEN(#REF!)+2), "")&"("& SUBSTITUTE(TEXT(#REF!,"??0")," ","")&" << TAM_MAX_BITS) |"& IF(#REF!-3 >= 0, REPT(" ",MAX(1,#REF!-5+4+1-1-LEN( IF(ISTEXT(#REF!),#REF!, SUBSTITUTE(SUBSTITUTE(TEXT(#REF!,"????0")," ","")," ","")) ))), "")& IF(ISTEXT(#REF!),#REF!, SUBSTITUTE(SUBSTITUTE(TEXT(#REF!,"????0")," ","")," ","")) &","& IF(#REF!-3 >= 0, REPT(" ",#REF!-3-5), "") &#REF!& " | "& IF(#REF!-LEN(#REF!) >= 0, REPT(" ",#REF!-LEN(#REF!)), "") &#REF!& IF(#REF!-LEN(#REF!) >= 0, REPT(" ",#REF!-LEN(#REF!)), "")& " | "& IF(#REF!-LEN(#REF!) >= 0, REPT(" ",#REF!-LEN(#REF!)), "") &#REF!& IF(#REF!-LEN(#REF!) >= 0, REPT(" ",#REF!-LEN(#REF!)), "")& " | " &#REF!& IF(#REF!-LEN(#REF!) >= 0, REPT(" ",#REF!-LEN(#REF!)), "")& " | " &#REF!& IF(#REF!-LEN(#REF!) >= 0, REPT(" ",#REF!-LEN(#REF!)), "")& "},"&IF(#REF!<>"",""&#REF!,"") ) ) ) -> #REF!
...

Sheet Sheet1
A1: On Linux, now k does not activate STK, terminal shows: Keyboard Key code: event->keyval=107 even_keyval=107 (SHIFT_State=-)(ShiftF=0)----- skipping to rest of key detections
A2: q and to a lesser extent Q seem to bounce on Windows, but it must be the sim itself (I tried Word, the q does not bounce)
A3: X for XEQ on R47 is not ok with double click, errors: No such label found
A4: X for XEQ on C47 is ok with double click, it activates alpha (AIM)
A5: C47: I think everything works except for the I = [DISP]
A6: R47 DISP OK.
A7: Linux R47 only misses xx (double click XEQ), same error: No such label found. No DISP issue.
A8: On Linux it still works, if I press x another time, XEQ 'F' then XEQ 'FF' etc. until XEQ 'FFFFFF' then No such function, maybe this will put you on the right track
A12: k | B12: =CODE(A12) -> 107
