Workbook
Name stdform: STD!$A:$B
Name units: Factors!$C$3:$F$18

Sheet Items and code
F1: =LEN(F24) -> 57 | H1: 60
A3: items.h | B3: Label | C3: Status | D3: conversionUnit.h | E3: temp | F3: temp | G3: temp | H3: items.c | I3: temp | J3: temp | K3: temp | L3: generateConstants.c | N3: conversionUnits.c
A4: ITM_CUPCtoFZUS | B4: cup␮⒞→floz␮ | C4: new | D4: =VLOOKUP(A4,Factors!D:K,8,0) -> constFactorCupcFzus | E4: =VLOOKUP(A4,Factors!D:N,10,0) -> multiply | F4: =VLOOKUP(A4,stdform,2,0) -> "cup" STD_US STD_SUB_c STD_RIGHT_ARROW "floz" STD_US | G4: =MID(F4,1,SEARCH("STD_RIGHT_ARROW",F4)-2)&" STD_RIGHT_ARROW" -> "cup" STD_US STD_SUB_c STD_RIGHT_ARROW | H4: ="/* NNNN */ UNIT_CONV("&D4&","&REPT(CHAR(32),21-LEN(D4))&" "&E4&", "&F4&","&REPT(CHAR(32),60-LEN(F4))&G4&REPT(CHAR(32),60-LEN(G4))&")," -> /* NNNN */ UNIT_CONV(constFactorCupcFzus, multiply, "cup" STD_US STD_SUB_c STD_RIGHT_ARROW "floz" STD_US, "cup" STD_US STD_SUB_c STD_RIGHT_ARROW ), | I4: =VLOOKUP(A4,Factors!D:G,4,0) -> 8.000008 | J4: =SUBSTITUTE(TEXT(I4,"0.000000000000000000000000000000000000000000000000000000E+00"),"E","e") -> 8.000007997024360000000000000000000000000000000000000000e+00 | K4: =VLOOKUP(A4,Factors!D:N,11,0) -> CupcFzus | L4: =IF(E4="multiply"," generateConstantArray("&CHAR(34)&K4&CHAR(34)&","&REPT(CHAR(32),14-LEN(K4))&CHAR(34)&"+"&J4&CHAR(34)&");","") -> generateConstantArray("CupcFzus", "+8.000007997024360000000000000000000000000000000000000000e+00"); | N4: =" ["&D4&"] = "&CHAR(38)&"const_"&K4&"," -> [constFactorCupcFzus] = &const_CupcFzus,
A5: ITM_CUPCtoML | B5: cup␮⒞→ml | C5: new | D5: =VLOOKUP(A5,Factors!D:K,8,0) -> constFactorCupcMl | E5: =VLOOKUP(A5,Factors!D:N,10,0) -> multiply | F5: =VLOOKUP(A5,stdform,2,0) -> "cup" STD_US STD_SUB_c STD_RIGHT_ARROW "ml" | G5: =MID(F5,1,SEARCH("STD_RIGHT_ARROW",F5)-2)&" STD_RIGHT_ARROW" -> "cup" STD_US STD_SUB_c STD_RIGHT_ARROW | H5: ="/* NNNN */ UNIT_CONV("&D5&","&REPT(CHAR(32),21-LEN(D5))&" "&E5&", "&F5&","&REPT(CHAR(32),60-LEN(F5))&G5&REPT(CHAR(32),60-LEN(G5))&")," -> /* NNNN */ UNIT_CONV(constFactorCupcMl, multiply, "cup" STD_US STD_SUB_c STD_RIGHT_ARROW "ml", "cup" STD_US STD_SUB_c STD_RIGHT_ARROW ), | I5: =VLOOKUP(A5,Factors!D:G,4,0) -> 236.58824 | J5: =SUBSTITUTE(TEXT(I5,"0.000000000000000000000000000000000000000000000000000000E+00"),"E","e") -> 2.365882365000000000000000000000000000000000000000000000e+02 | K5: =VLOOKUP(A5,Factors!D:N,11,0) -> CupcMl | L5: =IF(E5="multiply"," generateConstantArray("&CHAR(34)&K5&CHAR(34)&","&REPT(CHAR(32),14-LEN(K5))&CHAR(34)&"+"&J5&CHAR(34)&");","") -> generateConstantArray("CupcMl", "+2.365882365000000000000000000000000000000000000000000000e+02"); | N5: =" ["&D5&"] = "&CHAR(38)&"const_"&K5&"," -> [constFactorCupcMl] = &const_CupcMl,
A6: ITM_CUPUKtoFZUK | B6: cup␭→floz␭ | C6: new | D6: =VLOOKUP(A6,Factors!D:K,8,0) -> constFactorCupukFzuk | E6: =VLOOKUP(A6,Factors!D:N,10,0) -> multiply | F6: =VLOOKUP(A6,stdform,2,0) -> "cup" STD_UK STD_RIGHT_ARROW "floz" STD_UK | G6: =MID(F6,1,SEARCH("STD_RIGHT_ARROW",F6)-2)&" STD_RIGHT_ARROW" -> "cup" STD_UK STD_RIGHT_ARROW | H6: ="/* NNNN */ UNIT_CONV("&D6&","&REPT(CHAR(32),21-LEN(D6))&" "&E6&", "&F6&","&REPT(CHAR(32),60-LEN(F6))&G6&REPT(CHAR(32),60-LEN(G6))&")," -> /* NNNN */ UNIT_CONV(constFactorCupukFzuk, multiply, "cup" STD_UK STD_RIGHT_ARROW "floz" STD_UK, "cup" STD_UK STD_RIGHT_ARROW ), | I6: =VLOOKUP(A6,Factors!D:G,4,0) -> 9.9999868 | J6: =SUBSTITUTE(TEXT(I6,"0.000000000000000000000000000000000000000000000000000000E+00"),"E","e") -> 9.999986801862520000000000000000000000000000000000000000e+00 | K6: =VLOOKUP(A6,Factors!D:N,11,0) -> CupukFzuk | L6: =IF(E6="multiply"," generateConstantArray("&CHAR(34)&K6&CHAR(34)&","&REPT(CHAR(32),14-LEN(K6))&CHAR(34)&"+"&J6&CHAR(34)&");","") -> generateConstantArray("CupukFzuk", "+9.999986801862520000000000000000000000000000000000000000e+00"); | N6: =" ["&D6&"] = "&CHAR(38)&"const_"&K6&"," -> [constFactorCupukFzuk] = &const_CupukFzuk,
A7: ITM_CUPUKtoML | B7: cup␭→ml | C7: new | D7: =VLOOKUP(A7,Factors!D:K,8,0) -> constFactorCupukMl | E7: =VLOOKUP(A7,Factors!D:N,10,0) -> multiply | F7: =VLOOKUP(A7,stdform,2,0) -> "cup" STD_UK STD_RIGHT_ARROW "ml" | G7: =MID(F7,1,SEARCH("STD_RIGHT_ARROW",F7)-2)&" STD_RIGHT_ARROW" -> "cup" STD_UK STD_RIGHT_ARROW | H7: ="/* NNNN */ UNIT_CONV("&D7&","&REPT(CHAR(32),21-LEN(D7))&" "&E7&", "&F7&","&REPT(CHAR(32),60-LEN(F7))&G7&REPT(CHAR(32),60-LEN(G7))&")," -> /* NNNN */ UNIT_CONV(constFactorCupukMl, multiply, "cup" STD_UK STD_RIGHT_ARROW "ml", "cup" STD_UK STD_RIGHT_ARROW ), | I7: =VLOOKUP(A7,Factors!D:G,4,0) -> 284.13063 | J7: =SUBSTITUTE(TEXT(I7,"0.000000000000000000000000000000000000000000000000000000E+00"),"E","e") -> 2.841306250000000000000000000000000000000000000000000000e+02 | K7: =VLOOKUP(A7,Factors!D:N,11,0) -> CupukMl | L7: =IF(E7="multiply"," generateConstantArray("&CHAR(34)&K7&CHAR(34)&","&REPT(CHAR(32),14-LEN(K7))&CHAR(34)&"+"&J7&CHAR(34)&");","") -> generateConstantArray("CupukMl", "+2.841306250000000000000000000000000000000000000000000000e+02"); | N7: =" ["&D7&"] = "&CHAR(38)&"const_"&K7&"," -> [constFactorCupukMl] = &const_CupukMl,
A8: ITM_FZUKtoCUPUK | B8: floz␭→cup␭ | C8: new | D8: =VLOOKUP(A8,Factors!D:K,8,0) -> constFactorFzukCupuk | E8: =VLOOKUP(A8,Factors!D:N,10,0) -> divide | F8: =VLOOKUP(A8,stdform,2,0) -> "floz" STD_UK STD_RIGHT_ARROW "cup" STD_UK | G8: =MID(F8,1,SEARCH("STD_RIGHT_ARROW",F8)-2)&" STD_RIGHT_ARROW" -> "floz" STD_UK STD_RIGHT_ARROW | H8: ="/* NNNN */ UNIT_CONV("&D8&","&REPT(CHAR(32),21-LEN(D8))&" "&E8&", "&F8&","&REPT(CHAR(32),60-LEN(F8))&G8&REPT(CHAR(32),60-LEN(G8))&")," -> /* NNNN */ UNIT_CONV(constFactorFzukCupuk, divide, "floz" STD_UK STD_RIGHT_ARROW "cup" STD_UK, "floz" STD_UK STD_RIGHT_ARROW ), | I8: =VLOOKUP(A8,Factors!D:G,4,0) -> 9.9999868 | J8: =SUBSTITUTE(TEXT(I8,"0.000000000000000000000000000000000000000000000000000000E+00"),"E","e") -> 9.999986801862520000000000000000000000000000000000000000e+00 | K8: =VLOOKUP(A8,Factors!D:N,11,0) -> CupukFzuk | L8: =IF(E8="multiply"," generateConstantArray("&CHAR(34)&K8&CHAR(34)&","&REPT(CHAR(32),14-LEN(K8))&CHAR(34)&"+"&J8&CHAR(34)&");","") | N8: =" ["&D8&"] = "&CHAR(38)&"const_"&K8&"," -> [constFactorFzukCupuk] = &const_CupukFzuk,
A9: ITM_FZUKtoTBSPUK | B9: floz␭→tbsp␭ | C9: new | D9: =VLOOKUP(A9,Factors!D:K,8,0) -> constFactorFzukTbspuk | E9: =VLOOKUP(A9,Factors!D:N,10,0) -> multiply | F9: =VLOOKUP(A9,stdform,2,0) -> "floz" STD_UK STD_RIGHT_ARROW "Tbsp" STD_UK | G9: =MID(F9,1,SEARCH("STD_RIGHT_ARROW",F9)-2)&" STD_RIGHT_ARROW" -> "floz" STD_UK STD_RIGHT_ARROW | H9: ="/* NNNN */ UNIT_CONV("&D9&","&REPT(CHAR(32),21-LEN(D9))&" "&E9&", "&F9&","&REPT(CHAR(32),60-LEN(F9))&G9&REPT(CHAR(32),60-LEN(G9))&")," -> /* NNNN */ UNIT_CONV(constFactorFzukTbspuk, multiply, "floz" STD_UK STD_RIGHT_ARROW "Tbsp" STD_UK, "floz" STD_UK STD_RIGHT_ARROW ), | I9: =VLOOKUP(A9,Factors!D:G,4,0) -> 1.6000021 | J9: =SUBSTITUTE(TEXT(I9,"0.000000000000000000000000000000000000000000000000000000E+00"),"E","e") -> 1.600002111704780000000000000000000000000000000000000000e+00 | K9: =VLOOKUP(A9,Factors!D:N,11,0) -> FzukTbspuk | L9: =IF(E9="multiply"," generateConstantArray("&CHAR(34)&K9&CHAR(34)&","&REPT(CHAR(32),14-LEN(K9))&CHAR(34)&"+"&J9&CHAR(34)&");","") -> generateConstantArray("FzukTbspuk", "+1.600002111704780000000000000000000000000000000000000000e+00"); | N9: =" ["&D9&"] = "&CHAR(38)&"const_"&K9&"," -> [constFactorFzukTbspuk] = &const_FzukTbspuk,
A10: ITM_FZUKtoTSPUK | B10: floz␭→tsp␭ | C10: new | D10: =VLOOKUP(A10,Factors!D:K,8,0) -> constFactorFzukTspuk | E10: =VLOOKUP(A10,Factors!D:N,10,0) -> multiply | F10: =VLOOKUP(A10,stdform,2,0) -> "floz" STD_UK STD_RIGHT_ARROW "tsp" STD_UK | G10: =MID(F10,1,SEARCH("STD_RIGHT_ARROW",F10)-2)&" STD_RIGHT_ARROW" -> "floz" STD_UK STD_RIGHT_ARROW | H10: ="/* NNNN */ UNIT_CONV("&D10&","&REPT(CHAR(32),21-LEN(D10))&" "&E10&", "&F10&","&REPT(CHAR(32),60-LEN(F10))&G10&REPT(CHAR(32),60-LEN(G10))&")," -> /* NNNN */ UNIT_CONV(constFactorFzukTspuk, multiply, "floz" STD_UK STD_RIGHT_ARROW "tsp" STD_UK, "floz" STD_UK STD_RIGHT_ARROW ), | I10: =VLOOKUP(A10,Factors!D:G,4,0) -> 4.8000063 | J10: =SUBSTITUTE(TEXT(I10,"0.000000000000000000000000000000000000000000000000000000E+00"),"E","e") -> 4.800006335114380000000000000000000000000000000000000000e+00 | K10: =VLOOKUP(A10,Factors!D:N,11,0) -> FzukTspuk | L10: =IF(E10="multiply"," generateConstantArray("&CHAR(34)&K10&CHAR(34)&","&REPT(CHAR(32),14-LEN(K10))&CHAR(34)&"+"&J10&CHAR(34)&");","") -> generateConstantArray("FzukTspuk", "+4.800006335114380000000000000000000000000000000000000000e+00"); | N10: =" ["&D10&"] = "&CHAR(38)&"const_"&K10&"," -> [constFactorFzukTspuk] = &const_FzukTspuk,
A11: ITM_FZUStoCUPC | B11: floz␮→cup␮⒞ | C11: new | D11: =VLOOKUP(A11,Factors!D:K,8,0) -> constFactorFzusCupc | E11: =VLOOKUP(A11,Factors!D:N,10,0) -> divide | F11: =VLOOKUP(A11,stdform,2,0) -> "floz" STD_US STD_RIGHT_ARROW "cup" STD_US STD_SUB_c | G11: =MID(F11,1,SEARCH("STD_RIGHT_ARROW",F11)-2)&" STD_RIGHT_ARROW" -> "floz" STD_US STD_RIGHT_ARROW | H11: ="/* NNNN */ UNIT_CONV("&D11&","&REPT(CHAR(32),21-LEN(D11))&" "&E11&", "&F11&","&REPT(CHAR(32),60-LEN(F11))&G11&REPT(CHAR(32),60-LEN(G11))&")," -> /* NNNN */ UNIT_CONV(constFactorFzusCupc, divide, "floz" STD_US STD_RIGHT_ARROW "cup" STD_US STD_SUB_c, "floz" STD_US STD_RIGHT_ARROW ), | I11: =VLOOKUP(A11,Factors!D:G,4,0) -> 8.000008 | J11: =SUBSTITUTE(TEXT(I11,"0.000000000000000000000000000000000000000000000000000000E+00"),"E","e") -> 8.000007997024360000000000000000000000000000000000000000e+00 | K11: =VLOOKUP(A11,Factors!D:N,11,0) -> CupcFzus | L11: =IF(E11="multiply"," generateConstantArray("&CHAR(34)&K11&CHAR(34)&","&REPT(CHAR(32),14-LEN(K11))&CHAR(34)&"+"&J11&CHAR(34)&");","") | N11: =" ["&D11&"] = "&CHAR(38)&"const_"&K11&"," -> [constFactorFzusCupc] = &const_CupcFzus,
A12: ITM_FZUStoTBSPC | B12: floz␮→tbsp␮⒞ | C12: new | D12: =VLOOKUP(A12,Factors!D:K,8,0) -> constFactorFzusTbspc | E12: =VLOOKUP(A12,Factors!D:N,10,0) -> multiply | F12: =VLOOKUP(A12,stdform,2,0) -> "floz" STD_US STD_RIGHT_ARROW "Tbsp" STD_US STD_SUB_c | G12: =MID(F12,1,SEARCH("STD_RIGHT_ARROW",F12)-2)&" STD_RIGHT_ARROW" -> "floz" STD_US STD_RIGHT_ARROW | H12: ="/* NNNN */ UNIT_CONV("&D12&","&REPT(CHAR(32),21-LEN(D12))&" "&E12&", "&F12&","&REPT(CHAR(32),60-LEN(F12))&G12&REPT(CHAR(32),60-LEN(G12))&")," -> /* NNNN */ UNIT_CONV(constFactorFzusTbspc, multiply, "floz" STD_US STD_RIGHT_ARROW "Tbsp" STD_US STD_SUB_c, "floz" STD_US STD_RIGHT_ARROW ), | I12: =VLOOKUP(A12,Factors!D:G,4,0) -> 1.999998 | J12: =SUBSTITUTE(TEXT(I12,"0.000000000000000000000000000000000000000000000000000000E+00"),"E","e") -> 1.999998000745910000000000000000000000000000000000000000e+00 | K12: =VLOOKUP(A12,Factors!D:N,11,0) -> FzusTbspc | L12: =IF(E12="multiply"," generateConstantArray("&CHAR(34)&K12&CHAR(34)&","&REPT(CHAR(32),14-LEN(K12))&CHAR(34)&"+"&J12&CHAR(34)&");","") -> generateConstantArray("FzusTbspc", "+1.999998000745910000000000000000000000000000000000000000e+00"); | N12: =" ["&D12&"] = "&CHAR(38)&"const_"&K12&"," -> [constFactorFzusTbspc] = &const_FzusTbspc,
A13: ITM_FZUStoTSPC | B13: floz␮→tsp␮⒞ | C13: new | D13: =VLOOKUP(A13,Factors!D:K,8,0) -> constFactorFzusTspc | E13: =VLOOKUP(A13,Factors!D:N,10,0) -> multiply | F13: =VLOOKUP(A13,stdform,2,0) -> "floz" STD_US STD_RIGHT_ARROW "tsp" STD_US STD_SUB_c | G13: =MID(F13,1,SEARCH("STD_RIGHT_ARROW",F13)-2)&" STD_RIGHT_ARROW" -> "floz" STD_US STD_RIGHT_ARROW | H13: ="/* NNNN */ UNIT_CONV("&D13&","&REPT(CHAR(32),21-LEN(D13))&" "&E13&", "&F13&","&REPT(CHAR(32),60-LEN(F13))&G13&REPT(CHAR(32),60-LEN(G13))&")," -> /* NNNN */ UNIT_CONV(constFactorFzusTspc, multiply, "floz" STD_US STD_RIGHT_ARROW "tsp" STD_US STD_SUB_c, "floz" STD_US STD_RIGHT_ARROW ), | I13: =VLOOKUP(A13,Factors!D:G,4,0) -> 5.999994 | J13: =SUBSTITUTE(TEXT(I13,"0.000000000000000000000000000000000000000000000000000000E+00"),"E","e") -> 5.999994002237720000000000000000000000000000000000000000e+00 | K13: =VLOOKUP(A13,Factors!D:N,11,0) -> FzusTspc | L13: =IF(E13="multiply"," generateConstantArray("&CHAR(34)&K13&CHAR(34)&","&REPT(CHAR(32),14-LEN(K13))&CHAR(34)&"+"&J13&CHAR(34)&");","") -> generateConstantArray("FzusTspc", "+5.999994002237720000000000000000000000000000000000000000e+00"); | N13: =" ["&D13&"] = "&CHAR(38)&"const_"&K13&"," -> [constFactorFzusTspc] = &const_FzusTspc,
A14: ITM_MLtoCUPC | B14: ml→cup␮⒞ | C14: new | D14: =VLOOKUP(A14,Factors!D:K,8,0) -> constFactorMlCupc | E14: =VLOOKUP(A14,Factors!D:N,10,0) -> divide | F14: =VLOOKUP(A14,stdform,2,0) -> "ml" STD_RIGHT_ARROW "cup" STD_US STD_SUB_c | G14: =MID(F14,1,SEARCH("STD_RIGHT_ARROW",F14)-2)&" STD_RIGHT_ARROW" -> "ml" STD_RIGHT_ARROW | H14: ="/* NNNN */ UNIT_CONV("&D14&","&REPT(CHAR(32),21-LEN(D14))&" "&E14&", "&F14&","&REPT(CHAR(32),60-LEN(F14))&G14&REPT(CHAR(32),60-LEN(G14))&")," -> /* NNNN */ UNIT_CONV(constFactorMlCupc, divide, "ml" STD_RIGHT_ARROW "cup" STD_US STD_SUB_c, "ml" STD_RIGHT_ARROW ), | I14: =VLOOKUP(A14,Factors!D:G,4,0) -> 236.58824 | J14: =SUBSTITUTE(TEXT(I14,"0.000000000000000000000000000000000000000000000000000000E+00"),"E","e") -> 2.365882365000000000000000000000000000000000000000000000e+02 | K14: =VLOOKUP(A14,Factors!D:N,11,0) -> CupcMl | L14: =IF(E14="multiply"," generateConstantArray("&CHAR(34)&K14&CHAR(34)&","&REPT(CHAR(32),14-LEN(K14))&CHAR(34)&"+"&J14&CHAR(34)&");","") | N14: =" ["&D14&"] = "&CHAR(38)&"const_"&K14&"," -> [constFactorMlCupc] = &const_CupcMl,
A15: ITM_MLtoCUPUK | B15: ml→cup␭ | C15: new | D15: =VLOOKUP(A15,Factors!D:K,8,0) -> constFactorMlCupuk | E15: =VLOOKUP(A15,Factors!D:N,10,0) -> divide | F15: =VLOOKUP(A15,stdform,2,0) -> "ml" STD_RIGHT_ARROW "cup" STD_UK | G15: =MID(F15,1,SEARCH("STD_RIGHT_ARROW",F15)-2)&" STD_RIGHT_ARROW" -> "ml" STD_RIGHT_ARROW | H15: ="/* NNNN */ UNIT_CONV("&D15&","&REPT(CHAR(32),21-LEN(D15))&" "&E15&", "&F15&","&REPT(CHAR(32),60-LEN(F15))&G15&REPT(CHAR(32),60-LEN(G15))&")," -> /* NNNN */ UNIT_CONV(constFactorMlCupuk, divide, "ml" STD_RIGHT_ARROW "cup" STD_UK, "ml" STD_RIGHT_ARROW ), | I15: =VLOOKUP(A15,Factors!D:G,4,0) -> 284.13063 | J15: =SUBSTITUTE(TEXT(I15,"0.000000000000000000000000000000000000000000000000000000E+00"),"E","e") -> 2.841306250000000000000000000000000000000000000000000000e+02 | K15: =VLOOKUP(A15,Factors!D:N,11,0) -> CupukMl | L15: =IF(E15="multiply"," generateConstantArray("&CHAR(34)&K15&CHAR(34)&","&REPT(CHAR(32),14-LEN(K15))&CHAR(34)&"+"&J15&CHAR(34)&");","") | N15: =" ["&D15&"] = "&CHAR(38)&"const_"&K15&"," -> [constFactorMlCupuk] = &const_CupukMl,
... A35: ITM_TSPUKtoML | B35: tsp␭→ml | C35: new | D35: =VLOOKUP(A35,Factors!D:K,8,0) -> constFactorTspukMl | E35: =VLOOKUP(A35,Factors!D:N,10,0) -> multiply | F35: =VLOOKUP(A35,stdform,2,0) -> "tsp" STD_UK STD_RIGHT_ARROW "ml" | G35: =MID(F35,1,SEARCH("STD_RIGHT_ARROW",F35)-2)&" STD_RIGHT_ARROW" -> "tsp" STD_UK STD_RIGHT_ARROW | H35: ="/* NNNN */ UNIT_CONV("&D35&","&REPT(CHAR(32),21-LEN(D35))&" "&E35&", "&F35&","&REPT(CHAR(32),60-LEN(F35))&G35&REPT(CHAR(32),60-LEN(G35))&")," -> /* NNNN */ UNIT_CONV(constFactorTspukMl, multiply, "tsp" STD_UK STD_RIGHT_ARROW "ml", "tsp" STD_UK STD_RIGHT_ARROW ), | I35: =VLOOKUP(A35,Factors!D:G,4,0) -> 5.919388 | J35: =SUBSTITUTE(TEXT(I35,"0.000000000000000000000000000000000000000000000000000000E+00"),"E","e") -> 5.919388020833300000000000000000000000000000000000000000e+00 | K35: =VLOOKUP(A35,Factors!D:N,11,0) -> TspukMl | L35: =IF(E35="multiply"," generateConstantArray("&CHAR(34)&K35&CHAR(34)&","&REPT(CHAR(32),14-LEN(K35))&CHAR(34)&"+"&J35&CHAR(34)&");","") -> generateConstantArray("TspukMl", "+5.919388020833300000000000000000000000000000000000000000e+00"); | N35: =" ["&D35&"] = "&CHAR(38)&"const_"&K35&"," -> [constFactorTspukMl] = &const_TspukMl,
A37: ITM_LtoQT | B37: l→qt.␭ | C37: label updated
A38: ITM_QTtoL | B38: qt.␭→l | C38: label updated

Sheet Factors
F2: milliliter
C3: PINTLQ | D3: pint⒧⒤⒬ | E3: US liquid pint | F3: 473.17647 | J3: =F3/F5 -> 2 | K3: cup US
C4: QTUS | D4: qt.␮ | E4: US quart | F4: =2 * F3 -> 946.35295 | J4: =F4/F3 -> 2 | K4: pint US | L4: liquid | M4: =F4/F5 -> 4 | N4: =F4/F15 -> 32.000032
C5: CUPC | D5: cup␮⒞ | E5: US customary cup | F5: 236.58824 | J5: =F5/F15 -> 8.000008 | K5: floz US
C6: TBSPC | D6: tbsp␮⒞ | E6: US customary tablespoon | F6: 14.786765 | G6: ="1/16" -> 1/16 | H6: =E5 -> US customary cup
C7: TSPC | D7: tsp␮⒞ | E7: US customary teaspoon | F7: 4.9289216 | G7: ="1/48" -> 1/48 | H7: =E5 -> US customary cup
C9: PINTUK | D9: pint␭ | E9: UK pint | F9: 568.26125 | H9: 568.26125 | J9: =F9/F11 -> 2 | K9: cup UK
C10: QT | D10: qt.␮ | E10: UK quart | F10: 1136.5225 | G10: 1136,523? | H10: =2*H9 -> 1136.5225 | J10: =F10/F9 -> 2 | K10: pint UK
C11: CUPUK | D11: cup␭ | E11: UK cup | F11: 284.13063 | H11: 284.13063 | J11: =F11/F16 -> 9.9999868 | K11: floz UK
C12: TBSPUK | D12: tbsp␭ | E12: UK tablespoon | F12: 17.758164 | G12: Ben: 15? | H12: 177.58164
C13: TSPUK | D13: tsp␭ | E13: UK teaspoon | F13: 5.919388 | H13: 5.919388
C14: ML | D14: ml | E14: milliliter | F14: 1
C15: FZUS | E15: US fluid ounce | F15: 29.5735 | N15: ml = pintuk × 568.26125
C16: FZUK | E16: UK fluid ounce | F16: 28.4131 | N16: ml = cupuk × 284.130625
C17: GLUS | E17: US gallon | F17: 3785.51 | J17: =F17/F4 -> 4.0001038 | K17: quart US | N17: ml = tbspuk × 17.7581640625
C18: GLUK | E18: UK gallon | F18: 4545.09 | J18: =F18/F10 -> 3.9991201 | K18: quart UK | N18: ml = tspuk × 5.9193880208333...
F21: Factor | H21: From | I21: To
A22: PINTLQtoML | B22: PINTLQ | C22: ML | D22: ITM_PINTLQtoML | E22: pint⒧⒤⒬→ml | F22: =H22/I22 -> 473.17647 | G22: =IF(M22="multiply",F22,F23) -> 473.17647 | H22: =VLOOKUP(B22,units,4,0) -> 473.17647 | I22: =VLOOKUP(C22,units,4,0) -> 1 | J22: =PROPER(B22)&PROPER(C22) -> PintlqMl | K22: ="constFactor"&J22 -> constFactorPintlqMl | M22: =IF(H22>I22,"multiply"," divide") -> multiply | N22: =IF(M22="multiply",PROPER(B22)&PROPER(C22),J23) -> PintlqMl
A23: MLtoPINTLQ | B23: ML | C23: PINTLQ | D23: ITM_MLtoPINTLQ | E23: ml→pint⒧⒤⒬ | F23: =H23/I23 -> 0.0021133764 | G23: =IF(M23="multiply",F23,F22) -> 473.17647 | H23: =VLOOKUP(B23,units,4,0) -> 1 | I23: =VLOOKUP(C23,units,4,0) -> 473.17647 | J23: =PROPER(B23)&PROPER(C23) -> MlPintlq | K23: ="constFactor"&J23 -> constFactorMlPintlq | M23: =IF(M22="multiply"," divide","multiply") -> divide | N23: =IF(M23="multiply",PROPER(B23)&PROPER(C23),J22) -> PintlqMl
A24: QTUStoML | B24: QTUS | C24: ML | D24: ITM_QTUStoML | E24: qt.␮→ml | F24: =H24/I24 -> 946.35295 | G24: =IF(M24="multiply",F24,F25) -> 946.35295 | H24: =VLOOKUP(B24,units,4,0) -> 946.35295 | I24: =VLOOKUP(C24,units,4,0) -> 1 | J24: =PROPER(B24)&PROPER(C24) -> QtusMl | K24: ="constFactor"&J24 -> constFactorQtusMl | M24: =IF(H24>I24,"multiply"," divide") -> multiply | N24: =IF(M24="multiply",PROPER(B24)&PROPER(C24),J25) -> QtusMl
A25: MLtoQTUS | B25: ML | C25: QTUS | D25: ITM_MLtoQTUS | E25: ml→qt.␮ | F25: =H25/I25 -> 0.0010566882 | G25: =IF(M25="multiply",F25,F24) -> 946.35295 | H25: =VLOOKUP(B25,units,4,0) -> 1 | I25: =VLOOKUP(C25,units,4,0) -> 946.35295 | J25: =PROPER(B25)&PROPER(C25) -> MlQtus | K25: ="constFactor"&J25 -> constFactorMlQtus | M25: =IF(M24="multiply"," divide","multiply") -> divide | N25: =IF(M25="multiply",PROPER(B25)&PROPER(C25),J24) -> QtusMl
A26: FZUStoCUPC | B26: FZUS | C26: CUPC | D26: ITM_FZUStoCUPC | E26: floz␮→cup␮⒞ | F26: =H26/I26 -> 0.12499988 | G26: =IF(M26="multiply",F26,F27) -> 8.000008 | H26: =VLOOKUP(B26,units,4,0) -> 29.5735 | I26: =VLOOKUP(C26,units,4,0) -> 236.58824 | J26: =PROPER(B26)&PROPER(C26) -> FzusCupc | K26: ="constFactor"&J26 -> constFactorFzusCupc | M26: =IF(H26>I26,"multiply"," divide") -> divide | N26: =IF(M26="multiply",PROPER(B26)&PROPER(C26),J27) -> CupcFzus
A27: CUPCtoFZUS | B27: CUPC | C27: FZUS | D27: ITM_CUPCtoFZUS | E27: cup␮⒞→floz␮ | F27: =H27/I27 -> 8.000008 | G27: =IF(M27="multiply",F27,F26) -> 8.000008 | H27: =VLOOKUP(B27,units,4,0) -> 236.58824 | I27: =VLOOKUP(C27,units,4,0) -> 29.5735 | J27: =PROPER(B27)&PROPER(C27) -> CupcFzus | K27: ="constFactor"&J27 -> constFactorCupcFzus | M27: =IF(M26="multiply"," divide","multiply") -> multiply | N27: =IF(M27="multiply",PROPER(B27)&PROPER(C27),J26) -> CupcFzus
A28: FZUStoTBSPC | B28: FZUS | C28: TBSPC | D28: ITM_FZUStoTBSPC | E28: floz␮→tbsp␮⒞ | F28: =H28/I28 -> 1.999998 | G28: =IF(M28="multiply",F28,F29) -> 1.999998 | H28: =VLOOKUP(B28,units,4,0) -> 29.5735 | I28: =VLOOKUP(C28,units,4,0) -> 14.786765 | J28: =PROPER(B28)&PROPER(C28) -> FzusTbspc | K28: ="constFactor"&J28 -> constFactorFzusTbspc | M28: =IF(H28>I28,"multiply"," divide") -> multiply | N28: =IF(M28="multiply",PROPER(B28)&PROPER(C28),J29) -> FzusTbspc
A29: TBSPCtoFZUS | B29: TBSPC | C29: FZUS | D29: ITM_TBSPCtoFZUS | E29: tbsp␮⒞→floz␮ | F29: =H29/I29 -> 0.5000005 | G29: =IF(M29="multiply",F29,F28) -> 1.999998 | H29: =VLOOKUP(B29,units,4,0) -> 14.786765 | I29: =VLOOKUP(C29,units,4,0) -> 29.5735 | J29: =PROPER(B29)&PROPER(C29) -> TbspcFzus | K29: ="constFactor"&J29 -> constFactorTbspcFzus | M29: =IF(M28="multiply"," divide","multiply") -> divide | N29: =IF(M29="multiply",PROPER(B29)&PROPER(C29),J28) -> FzusTbspc
A30: MLtoCUPC | B30: ML | C30: CUPC | D30: ITM_MLtoCUPC | E30: ml→cup␮⒞ | F30: =H30/I30 -> 0.0042267528 | G30: =IF(M30="multiply",F30,F31) -> 236.58824 | H30: =VLOOKUP(B30,units,4,0) -> 1 | I30: =VLOOKUP(C30,units,4,0) -> 236.58824 | J30: =PROPER(B30)&PROPER(C30) -> MlCupc | K30: ="constFactor"&J30 -> constFactorMlCupc | M30: =IF(H30>I30,"multiply"," divide") -> divide | N30: =IF(M30="multiply",PROPER(B30)&PROPER(C30),J31) -> CupcMl
A31: CUPCtoML | B31: CUPC | C31: ML | D31: ITM_CUPCtoML | E31: cup␮⒞→ml | F31: =H31/I31 -> 236.58824 | G31: =IF(M31="multiply",F31,F30) -> 236.58824 | H31: =VLOOKUP(B31,units,4,0) -> 236.58824 | I31: =VLOOKUP(C31,units,4,0) -> 1 | J31: =PROPER(B31)&PROPER(C31) -> CupcMl | K31: ="constFactor"&J31 -> constFactorCupcMl | M31: =IF(M30="multiply"," divide","multiply") -> multiply | N31: =IF(M31="multiply",PROPER(B31)&PROPER(C31),J30) -> CupcMl
A32: MLtoTBSPC | B32: ML | C32: TBSPC | D32: ITM_MLtoTBSPC | E32: ml→tbsp␮⒞ | F32: =H32/I32 -> 0.067628045 | G32: =IF(M32="multiply",F32,F33) -> 14.786765 | H32: =VLOOKUP(B32,units,4,0) -> 1 | I32: =VLOOKUP(C32,units,4,0) -> 14.786765 | J32: =PROPER(B32)&PROPER(C32) -> MlTbspc | K32: ="constFactor"&J32 -> constFactorMlTbspc | M32: =IF(H32>I32,"multiply"," divide") -> divide | N32: =IF(M32="multiply",PROPER(B32)&PROPER(C32),J33) -> TbspcMl
A33: TBSPCtoML | B33: TBSPC | C33: ML | D33: ITM_TBSPCtoML | E33: tbsp␮⒞→ml | F33: =H33/I33 -> 14.786765 | G33: =IF(M33="multiply",F33,F32) -> 14.786765 | H33: =VLOOKUP(B33,units,4,0) -> 14.786765 | I33: =VLOOKUP(C33,units,4,0) -> 1 | J33: =PROPER(B33)&PROPER(C33) -> TbspcMl | K33: ="constFactor"&J33 -> constFactorTbspcMl | M33: =IF(M32="multiply"," divide","multiply") -> multiply | N33: =IF(M33="multiply",PROPER(B33)&PROPER(C33),J32) -> TbspcMl
A34: MLtoTSPC | B34: ML | C34: TSPC | D34: ITM_MLtoTSPC | E34: ml→tsp␮⒞ | F34: =H34/I34 -> 0.20288414 | G34: =IF(M34="multiply",F34,F35) -> 4.9289216 | H34: =VLOOKUP(B34,units,4,0) -> 1 | I34: =VLOOKUP(C34,units,4,0) -> 4.9289216 | J34: =PROPER(B34)&PROPER(C34) -> MlTspc | K34: ="constFactor"&J34 -> constFactorMlTspc | M34: =IF(H34>I34,"multiply"," divide") -> divide | N34: =IF(M34="multiply",PROPER(B34)&PROPER(C34),J35) -> TspcMl
A35: TSPCtoML | B35: TSPC | C35: ML | D35: ITM_TSPCtoML | E35: tsp␮⒞→ml | F35: =H35/I35 -> 4.9289216 | G35: =IF(M35="multiply",F35,F34) -> 4.9289216 | H35: =VLOOKUP(B35,units,4,0) -> 4.9289216 | I35: =VLOOKUP(C35,units,4,0) -> 1 | J35: =PROPER(B35)&PROPER(C35) -> TspcMl | K35: ="constFactor"&J35 -> constFactorTspcMl | M35: =IF(M34="multiply"," divide","multiply") -> multiply | N35: =IF(M35="multiply",PROPER(B35)&PROPER(C35),J34) -> TspcMl
A36: FZUStoTSPC | B36: FZUS | C36: TSPC | D36: ITM_FZUStoTSPC | E36: floz␮→tsp␮⒞ | F36: =H36/I36 -> 5.999994 | G36: =IF(M36="multiply",F36,F37) -> 5.999994 | H36: =VLOOKUP(B36,units,4,0) -> 29.5735 | I36: =VLOOKUP(C36,units,4,0) -> 4.9289216 | J36: =PROPER(B36)&PROPER(C36) -> FzusTspc | K36: ="constFactor"&J36 -> constFactorFzusTspc | M36: =IF(H36>I36,"multiply"," divide") -> multiply | N36: =IF(M36="multiply",PROPER(B36)&PROPER(C36),J37) -> FzusTspc
A37: TSPCtoFZUS | B37: TSPC | C37: FZUS | D37: ITM_TSPCtoFZUS | E37: tsp␮⒞→floz␮ | F37: =H37/I37 -> 0.16666683 | G37: =IF(M37="multiply",F37,F36) -> 5.999994 | H37: =VLOOKUP(B37,units,4,0) -> 4.9289216 | I37: =VLOOKUP(C37,units,4,0) -> 29.5735 | J37: =PROPER(B37)&PROPER(C37) -> TspcFzus | K37: ="constFactor"&J37 -> constFactorTspcFzus | M37: =IF(M36="multiply"," divide","multiply") -> divide | N37: =IF(M37="multiply",PROPER(B37)&PROPER(C37),J36) -> FzusTspc
J38: =PROPER(B38)&PROPER(C38)
A39: PINTUKtoML | B39: PINTUK | C39: ML | D39: ITM_PINTUKtoML | E39: pint␭→ml | F39: =H39/I39 -> 568.26125 | G39: =IF(M39="multiply",F39,F40) -> 568.26125 | H39: =VLOOKUP(B39,units,4,0) -> 568.26125 | I39: =VLOOKUP(C39,units,4,0) -> 1 | J39: =PROPER(B39)&PROPER(C39) -> PintukMl | K39: ="constFactor"&J39 -> constFactorPintukMl | M39: =IF(H39>I39,"multiply"," divide") -> multiply | N39: =IF(M39="multiply",PROPER(B39)&PROPER(C39),J40) -> PintukMl
A40: MLtoPINTUK | B40: ML | C40: PINTUK | D40: ITM_MLtoPINTUK | E40: ml→pint␭ | F40: =H40/I40 -> 0.001759754 | G40: =IF(M40="multiply",F40,F39) -> 568.26125 | H40: =VLOOKUP(B40,units,4,0) -> 1 | I40: =VLOOKUP(C40,units,4,0) -> 568.26125 | J40: =PROPER(B40)&PROPER(C40) -> MlPintuk | K40: ="constFactor"&J40 -> constFactorMlPintuk | M40: =IF(M39="multiply"," divide","multiply") -> divide | N40: =IF(M40="multiply",PROPER(B40)&PROPER(C40),J39) -> PintukMl
A41: QTtoML | B41: QT | C41: ML | D41: ITM_QTtoML | E41: qt.␭→ml | F41: =H41/I41 -> 1136.5225 | G41: =IF(M41="multiply",F41,F42) -> 1136.5225 | H41: =VLOOKUP(B41,units,4,0) -> 1136.5225 | I41: =VLOOKUP(C41,units,4,0) -> 1 | J41: =PROPER(B41)&PROPER(C41) -> QtMl | K41: ="constFactor"&J41 -> constFactorQtMl | M41: =IF(H41>I41,"multiply"," divide") -> multiply | N41: =IF(M41="multiply",PROPER(B41)&PROPER(C41),J42) -> QtMl
A42: MLtoQT | B42: ML | C42: QT | D42: ITM_MLtoQT | E42: ml→qt.␭ | F42: =H42/I42 -> 0.00087987699 | G42: =IF(M42="multiply",F42,F41) -> 1136.5225 | H42: =VLOOKUP(B42,units,4,0) -> 1 | I42: =VLOOKUP(C42,units,4,0) -> 1136.5225 | J42: =PROPER(B42)&PROPER(C42) -> MlQt | K42: ="constFactor"&J42 -> constFactorMlQt | M42: =IF(M41="multiply"," divide","multiply") -> divide | N42: =IF(M42="multiply",PROPER(B42)&PROPER(C42),J41) -> QtMl
A43: FZUKtoCUPUK | B43: FZUK | C43: CUPUK | D43: ITM_FZUKtoCUPUK | E43: floz␭→cup␭ | F43: =H43/I43 -> 0.10000013 | G43: =IF(M43="multiply",F43,F44) -> 9.9999868 | H43: =VLOOKUP(B43,units,4,0) -> 28.4131 | I43: =VLOOKUP(C43,units,4,0) -> 284.13063 | J43: =PROPER(B43)&PROPER(C43) -> FzukCupuk | K43: ="constFactor"&J43 -> constFactorFzukCupuk | M43: =IF(H43>I43,"multiply"," divide") -> divide | N43: =IF(M43="multiply",PROPER(B43)&PROPER(C43),J44) -> CupukFzuk
A44: CUPUKtoFZUK | B44: CUPUK | C44: FZUK | D44: ITM_CUPUKtoFZUK | E44: cup␭→floz␭ | F44: =H44/I44 -> 9.9999868 | G44: =IF(M44="multiply",F44,F43) -> 9.9999868 | H44: =VLOOKUP(B44,units,4,0) -> 284.13063 | I44: =VLOOKUP(C44,units,4,0) -> 28.4131 | J44: =PROPER(B44)&PROPER(C44) -> CupukFzuk | K44: ="constFactor"&J44 -> constFactorCupukFzuk | M44: =IF(M43="multiply"," divide","multiply") -> multiply | N44: =IF(M44="multiply",PROPER(B44)&PROPER(C44),J43) -> CupukFzuk
...

Sheet STD
A1: ITM_PINTLQtoML | B1: "pint" STD_SUB_l STD_SUB_i STD_SUB_q STD_RIGHT_ARROW "ml"
A2: ITM_MLtoPINTLQ | B2: "ml" STD_RIGHT_ARROW "pint" STD_SUB_l STD_SUB_i STD_SUB_q
A3: ITM_QTUStoML | B3: "qt." STD_US STD_RIGHT_ARROW "ml"
A4: ITM_MLtoQTUS | B4: "ml" STD_RIGHT_ARROW "qt." STD_US
A5: ITM_FZUStoCUPC | B5: "floz" STD_US STD_RIGHT_ARROW "cup" STD_US STD_SUB_c
A6: ITM_CUPCtoFZUS | B6: "cup" STD_US STD_SUB_c STD_RIGHT_ARROW "floz" STD_US
A7: ITM_FZUStoTBSPC | B7: "floz" STD_US STD_RIGHT_ARROW "Tbsp" STD_US STD_SUB_c
A8: ITM_TBSPCtoFZUS | B8: "Tbsp" STD_US STD_SUB_c STD_RIGHT_ARROW "floz" STD_US
A9: ITM_MLtoCUPC | B9: "ml" STD_RIGHT_ARROW "cup" STD_US STD_SUB_c
A10: ITM_CUPCtoML | B10: "cup" STD_US STD_SUB_c STD_RIGHT_ARROW "ml"
A11: ITM_MLtoTBSPC | B11: "ml" STD_RIGHT_ARROW "Tbsp" STD_US STD_SUB_c
A12: ITM_TBSPCtoML | B12: "Tbsp" STD_US STD_SUB_c STD_RIGHT_ARROW "ml"
... A34: ITM_TSPUKtoFZUK | B34: "tsp" STD_UK STD_RIGHT_ARROW "floz" STD_UK
